[2022-12-26T10:02:17.928+0000] {taskinstance.py:1087} INFO - Dependencies all met for <TaskInstance: Can_I_change_name_to_this.counter_data_cleansing scheduled__2022-12-25T10:00:00+00:00 [queued]>
[2022-12-26T10:02:18.013+0000] {taskinstance.py:1087} INFO - Dependencies all met for <TaskInstance: Can_I_change_name_to_this.counter_data_cleansing scheduled__2022-12-25T10:00:00+00:00 [queued]>
[2022-12-26T10:02:18.015+0000] {taskinstance.py:1283} INFO - 
--------------------------------------------------------------------------------
[2022-12-26T10:02:18.020+0000] {taskinstance.py:1284} INFO - Starting attempt 1 of 1
[2022-12-26T10:02:18.023+0000] {taskinstance.py:1285} INFO - 
--------------------------------------------------------------------------------
[2022-12-26T10:02:18.067+0000] {taskinstance.py:1304} INFO - Executing <Task(BashOperator): counter_data_cleansing> on 2022-12-25 10:00:00+00:00
[2022-12-26T10:02:18.094+0000] {standard_task_runner.py:55} INFO - Started process 165 to run task
[2022-12-26T10:02:18.138+0000] {standard_task_runner.py:82} INFO - Running: ['***', 'tasks', 'run', 'Can_I_change_name_to_this', 'counter_data_cleansing', 'scheduled__2022-12-25T10:00:00+00:00', '--job-id', '269', '--raw', '--subdir', 'DAGS_FOLDER/dags.py', '--cfg-path', '/tmp/tmp52zfemmu']
[2022-12-26T10:02:18.149+0000] {standard_task_runner.py:83} INFO - Job 269: Subtask counter_data_cleansing
[2022-12-26T10:02:18.489+0000] {task_command.py:389} INFO - Running <TaskInstance: Can_I_change_name_to_this.counter_data_cleansing scheduled__2022-12-25T10:00:00+00:00 [running]> on host 502390ac5559
[2022-12-26T10:02:18.960+0000] {taskinstance.py:1513} INFO - Exporting the following env vars:
AIRFLOW_CTX_DAG_OWNER=***
AIRFLOW_CTX_DAG_ID=Can_I_change_name_to_this
AIRFLOW_CTX_TASK_ID=counter_data_cleansing
AIRFLOW_CTX_EXECUTION_DATE=2022-12-25T10:00:00+00:00
AIRFLOW_CTX_TRY_NUMBER=1
AIRFLOW_CTX_DAG_RUN_ID=scheduled__2022-12-25T10:00:00+00:00
[2022-12-26T10:02:18.975+0000] {subprocess.py:63} INFO - Tmp dir root location: 
 /tmp
[2022-12-26T10:02:18.981+0000] {subprocess.py:75} INFO - Running command: ['/bin/bash', '-c', 'python /opt/***/tasks/data_cleansing_counter_stat.py']
[2022-12-26T10:02:19.074+0000] {subprocess.py:86} INFO - Output:
[2022-12-26T10:02:24.811+0000] {subprocess.py:93} INFO - 2022-12-26 10:02:24 +0000 - dagster - DEBUG - counter_stat_job - dc1af77d-3ad6-4225-a961-4ab5b225b04f - 166 - RUN_START - Started execution of run for "counter_stat_job".
[2022-12-26T10:02:24.848+0000] {subprocess.py:93} INFO - 2022-12-26 10:02:24 +0000 - dagster - DEBUG - counter_stat_job - dc1af77d-3ad6-4225-a961-4ab5b225b04f - 166 - ENGINE_EVENT - Executing steps in process (pid: 166)
[2022-12-26T10:02:24.856+0000] {subprocess.py:93} INFO - 2022-12-26 10:02:24 +0000 - dagster - DEBUG - counter_stat_job - dc1af77d-3ad6-4225-a961-4ab5b225b04f - 166 - RESOURCE_INIT_STARTED - Starting initialization of resources [io_manager].
[2022-12-26T10:02:25.100+0000] {subprocess.py:93} INFO - 2022-12-26 10:02:25 +0000 - dagster - DEBUG - counter_stat_job - dc1af77d-3ad6-4225-a961-4ab5b225b04f - 166 - RESOURCE_INIT_SUCCESS - Finished initialization of resources [io_manager].
[2022-12-26T10:02:25.107+0000] {subprocess.py:93} INFO - 2022-12-26 10:02:25 +0000 - dagster - DEBUG - counter_stat_job - dc1af77d-3ad6-4225-a961-4ab5b225b04f - 166 - LOGS_CAPTURED - Started capturing logs in process (pid: 166).
[2022-12-26T10:02:25.108+0000] {subprocess.py:93} INFO - 2022-12-26 10:02:25 +0000 - dagster - DEBUG - counter_stat_job - dc1af77d-3ad6-4225-a961-4ab5b225b04f - 166 - read_json - STEP_START - Started execution of step "read_json".
[2022-12-26T10:02:25.133+0000] {subprocess.py:93} INFO - 2022-12-26 10:02:25 +0000 - dagster - ERROR - counter_stat_job - dc1af77d-3ad6-4225-a961-4ab5b225b04f - 166 - read_json - STEP_FAILURE - Execution of step "read_json" failed.
[2022-12-26T10:02:25.137+0000] {subprocess.py:93} INFO - 
[2022-12-26T10:02:25.141+0000] {subprocess.py:93} INFO - dagster._core.errors.DagsterExecutionStepExecutionError: Error occurred while executing op "read_json"::
[2022-12-26T10:02:25.144+0000] {subprocess.py:93} INFO - 
[2022-12-26T10:02:25.148+0000] {subprocess.py:93} INFO - ValueError: Expected object or value
[2022-12-26T10:02:25.151+0000] {subprocess.py:93} INFO - 
[2022-12-26T10:02:25.156+0000] {subprocess.py:93} INFO - Stack Trace:
[2022-12-26T10:02:25.160+0000] {subprocess.py:93} INFO -   File "/home/***/.local/lib/python3.7/site-packages/dagster/_core/execution/plan/utils.py", line 56, in op_execution_error_boundary
[2022-12-26T10:02:25.167+0000] {subprocess.py:93} INFO -     yield
[2022-12-26T10:02:25.183+0000] {subprocess.py:93} INFO -   File "/home/***/.local/lib/python3.7/site-packages/dagster/_utils/__init__.py", line 458, in iterate_with_context
[2022-12-26T10:02:25.187+0000] {subprocess.py:93} INFO -     next_output = next(iterator)
[2022-12-26T10:02:25.188+0000] {subprocess.py:93} INFO -   File "/home/***/.local/lib/python3.7/site-packages/dagster/_core/execution/plan/compute_generator.py", line 75, in _coerce_solid_compute_fn_to_iterator
[2022-12-26T10:02:25.189+0000] {subprocess.py:93} INFO -     result = fn(context, **kwargs) if context_arg_provided else fn(**kwargs)
[2022-12-26T10:02:25.192+0000] {subprocess.py:93} INFO -   File "/opt/***/tasks/data_cleansing_counter_stat.py", line 20, in read_json
[2022-12-26T10:02:25.193+0000] {subprocess.py:93} INFO -     df = pd.read_json("/opt/***/zone1/lol_counter_stat.json",lines=True)
[2022-12-26T10:02:25.194+0000] {subprocess.py:93} INFO -   File "/home/***/.local/lib/python3.7/site-packages/pandas/util/_decorators.py", line 207, in wrapper
[2022-12-26T10:02:25.195+0000] {subprocess.py:93} INFO -     return func(*args, **kwargs)
[2022-12-26T10:02:25.195+0000] {subprocess.py:93} INFO -   File "/home/***/.local/lib/python3.7/site-packages/pandas/util/_decorators.py", line 311, in wrapper
[2022-12-26T10:02:25.196+0000] {subprocess.py:93} INFO -     return func(*args, **kwargs)
[2022-12-26T10:02:25.197+0000] {subprocess.py:93} INFO -   File "/home/***/.local/lib/python3.7/site-packages/pandas/io/json/_json.py", line 614, in read_json
[2022-12-26T10:02:25.199+0000] {subprocess.py:93} INFO -     return json_reader.read()
[2022-12-26T10:02:25.200+0000] {subprocess.py:93} INFO -   File "/home/***/.local/lib/python3.7/site-packages/pandas/io/json/_json.py", line 746, in read
[2022-12-26T10:02:25.200+0000] {subprocess.py:93} INFO -     obj = self._get_object_parser(self._combine_lines(data_lines))
[2022-12-26T10:02:25.201+0000] {subprocess.py:93} INFO -   File "/home/***/.local/lib/python3.7/site-packages/pandas/io/json/_json.py", line 770, in _get_object_parser
[2022-12-26T10:02:25.203+0000] {subprocess.py:93} INFO -     obj = FrameParser(json, **kwargs).parse()
[2022-12-26T10:02:25.204+0000] {subprocess.py:93} INFO -   File "/home/***/.local/lib/python3.7/site-packages/pandas/io/json/_json.py", line 885, in parse
[2022-12-26T10:02:25.205+0000] {subprocess.py:93} INFO -     self._parse_no_numpy()
[2022-12-26T10:02:25.206+0000] {subprocess.py:93} INFO -   File "/home/***/.local/lib/python3.7/site-packages/pandas/io/json/_json.py", line 1140, in _parse_no_numpy
[2022-12-26T10:02:25.207+0000] {subprocess.py:93} INFO -     loads(json, precise_float=self.precise_float), dtype=None
[2022-12-26T10:02:25.209+0000] {subprocess.py:93} INFO - 
[2022-12-26T10:02:25.213+0000] {subprocess.py:93} INFO - 2022-12-26 10:02:25 +0000 - dagster - ERROR - counter_stat_job - dc1af77d-3ad6-4225-a961-4ab5b225b04f - 166 - RUN_FAILURE - Execution of run for "counter_stat_job" failed. An exception was thrown during execution.
[2022-12-26T10:02:25.215+0000] {subprocess.py:93} INFO - 
[2022-12-26T10:02:25.217+0000] {subprocess.py:93} INFO - ValueError: Expected object or value
[2022-12-26T10:02:25.220+0000] {subprocess.py:93} INFO - 
[2022-12-26T10:02:25.222+0000] {subprocess.py:93} INFO - Stack Trace:
[2022-12-26T10:02:25.223+0000] {subprocess.py:93} INFO -   File "/home/***/.local/lib/python3.7/site-packages/dagster/_core/execution/api.py", line 1089, in pipeline_execution_iterator
[2022-12-26T10:02:25.224+0000] {subprocess.py:93} INFO -     for event in pipeline_context.executor.execute(pipeline_context, execution_plan):
[2022-12-26T10:02:25.232+0000] {subprocess.py:93} INFO -   File "/home/***/.local/lib/python3.7/site-packages/dagster/_core/executor/in_process.py", line 50, in execute
[2022-12-26T10:02:25.237+0000] {subprocess.py:93} INFO -     output_capture=plan_context.output_capture,
[2022-12-26T10:02:25.240+0000] {subprocess.py:93} INFO -   File "/home/***/.local/lib/python3.7/site-packages/dagster/_core/execution/api.py", line 1192, in __iter__
[2022-12-26T10:02:25.242+0000] {subprocess.py:93} INFO -     pipeline_context=self.pipeline_context,
[2022-12-26T10:02:25.247+0000] {subprocess.py:93} INFO -   File "/home/***/.local/lib/python3.7/site-packages/dagster/_core/execution/plan/execute_plan.py", line 115, in inner_plan_execution_iterator
[2022-12-26T10:02:25.250+0000] {subprocess.py:93} INFO -     dagster_event_sequence_for_step(step_context)
[2022-12-26T10:02:25.280+0000] {subprocess.py:93} INFO -   File "/home/***/.local/lib/python3.7/site-packages/dagster/_core/execution/plan/execute_plan.py", line 340, in dagster_event_sequence_for_step
[2022-12-26T10:02:25.291+0000] {subprocess.py:93} INFO -     raise dagster_user_error.user_exception
[2022-12-26T10:02:25.298+0000] {subprocess.py:93} INFO -   File "/home/***/.local/lib/python3.7/site-packages/dagster/_core/execution/plan/utils.py", line 56, in op_execution_error_boundary
[2022-12-26T10:02:25.303+0000] {subprocess.py:93} INFO -     yield
[2022-12-26T10:02:25.304+0000] {subprocess.py:93} INFO -   File "/home/***/.local/lib/python3.7/site-packages/dagster/_utils/__init__.py", line 458, in iterate_with_context
[2022-12-26T10:02:25.306+0000] {subprocess.py:93} INFO -     next_output = next(iterator)
[2022-12-26T10:02:25.309+0000] {subprocess.py:93} INFO -   File "/home/***/.local/lib/python3.7/site-packages/dagster/_core/execution/plan/compute_generator.py", line 75, in _coerce_solid_compute_fn_to_iterator
[2022-12-26T10:02:25.313+0000] {subprocess.py:93} INFO -     result = fn(context, **kwargs) if context_arg_provided else fn(**kwargs)
[2022-12-26T10:02:25.330+0000] {subprocess.py:93} INFO -   File "/opt/***/tasks/data_cleansing_counter_stat.py", line 20, in read_json
[2022-12-26T10:02:25.335+0000] {subprocess.py:93} INFO -     df = pd.read_json("/opt/***/zone1/lol_counter_stat.json",lines=True)
[2022-12-26T10:02:25.340+0000] {subprocess.py:93} INFO -   File "/home/***/.local/lib/python3.7/site-packages/pandas/util/_decorators.py", line 207, in wrapper
[2022-12-26T10:02:25.343+0000] {subprocess.py:93} INFO -     return func(*args, **kwargs)
[2022-12-26T10:02:25.367+0000] {subprocess.py:93} INFO -   File "/home/***/.local/lib/python3.7/site-packages/pandas/util/_decorators.py", line 311, in wrapper
[2022-12-26T10:02:25.371+0000] {subprocess.py:93} INFO -     return func(*args, **kwargs)
[2022-12-26T10:02:25.380+0000] {subprocess.py:93} INFO -   File "/home/***/.local/lib/python3.7/site-packages/pandas/io/json/_json.py", line 614, in read_json
[2022-12-26T10:02:25.391+0000] {subprocess.py:93} INFO -     return json_reader.read()
[2022-12-26T10:02:25.394+0000] {subprocess.py:93} INFO -   File "/home/***/.local/lib/python3.7/site-packages/pandas/io/json/_json.py", line 746, in read
[2022-12-26T10:02:25.399+0000] {subprocess.py:93} INFO -     obj = self._get_object_parser(self._combine_lines(data_lines))
[2022-12-26T10:02:25.403+0000] {subprocess.py:93} INFO -   File "/home/***/.local/lib/python3.7/site-packages/pandas/io/json/_json.py", line 770, in _get_object_parser
[2022-12-26T10:02:25.408+0000] {subprocess.py:93} INFO -     obj = FrameParser(json, **kwargs).parse()
[2022-12-26T10:02:25.416+0000] {subprocess.py:93} INFO -   File "/home/***/.local/lib/python3.7/site-packages/pandas/io/json/_json.py", line 885, in parse
[2022-12-26T10:02:25.424+0000] {subprocess.py:93} INFO -     self._parse_no_numpy()
[2022-12-26T10:02:25.428+0000] {subprocess.py:93} INFO -   File "/home/***/.local/lib/python3.7/site-packages/pandas/io/json/_json.py", line 1140, in _parse_no_numpy
[2022-12-26T10:02:25.431+0000] {subprocess.py:93} INFO -     loads(json, precise_float=self.precise_float), dtype=None
[2022-12-26T10:02:25.444+0000] {subprocess.py:93} INFO - 
[2022-12-26T10:02:25.447+0000] {subprocess.py:93} INFO - Traceback (most recent call last):
[2022-12-26T10:02:25.449+0000] {subprocess.py:93} INFO -   File "/home/***/.local/lib/python3.7/site-packages/dagster/_core/execution/plan/execute_plan.py", line 266, in dagster_event_sequence_for_step
[2022-12-26T10:02:25.451+0000] {subprocess.py:93} INFO -     for step_event in check.generator(step_events):
[2022-12-26T10:02:25.454+0000] {subprocess.py:93} INFO -   File "/home/***/.local/lib/python3.7/site-packages/dagster/_core/execution/plan/execute_step.py", line 389, in core_dagster_event_sequence_for_step
[2022-12-26T10:02:25.455+0000] {subprocess.py:93} INFO -     _step_output_error_checked_user_event_sequence(step_context, user_event_sequence)
[2022-12-26T10:02:25.457+0000] {subprocess.py:93} INFO -   File "/home/***/.local/lib/python3.7/site-packages/dagster/_core/execution/plan/execute_step.py", line 94, in _step_output_error_checked_user_event_sequence
[2022-12-26T10:02:25.459+0000] {subprocess.py:93} INFO -     for user_event in user_event_sequence:
[2022-12-26T10:02:25.464+0000] {subprocess.py:93} INFO -   File "/home/***/.local/lib/python3.7/site-packages/dagster/_core/execution/plan/compute.py", line 177, in execute_core_compute
[2022-12-26T10:02:25.466+0000] {subprocess.py:93} INFO -     for step_output in _yield_compute_results(step_context, inputs, compute_fn):
[2022-12-26T10:02:25.472+0000] {subprocess.py:93} INFO -   File "/home/***/.local/lib/python3.7/site-packages/dagster/_core/execution/plan/compute.py", line 154, in _yield_compute_results
[2022-12-26T10:02:25.475+0000] {subprocess.py:93} INFO -     user_event_generator,
[2022-12-26T10:02:25.477+0000] {subprocess.py:93} INFO -   File "/home/***/.local/lib/python3.7/site-packages/dagster/_utils/__init__.py", line 460, in iterate_with_context
[2022-12-26T10:02:25.480+0000] {subprocess.py:93} INFO -     return
[2022-12-26T10:02:25.486+0000] {subprocess.py:93} INFO -   File "/usr/local/lib/python3.7/contextlib.py", line 130, in __exit__
[2022-12-26T10:02:25.490+0000] {subprocess.py:93} INFO -     self.gen.throw(type, value, traceback)
[2022-12-26T10:02:25.494+0000] {subprocess.py:93} INFO -   File "/home/***/.local/lib/python3.7/site-packages/dagster/_core/execution/plan/utils.py", line 91, in op_execution_error_boundary
[2022-12-26T10:02:25.499+0000] {subprocess.py:93} INFO -     ) from e
[2022-12-26T10:02:25.529+0000] {subprocess.py:93} INFO - dagster._core.errors.DagsterExecutionStepExecutionError: Error occurred while executing op "read_json":
[2022-12-26T10:02:25.535+0000] {subprocess.py:93} INFO - 
[2022-12-26T10:02:25.546+0000] {subprocess.py:93} INFO - During handling of the above exception, another exception occurred:
[2022-12-26T10:02:25.548+0000] {subprocess.py:93} INFO - 
[2022-12-26T10:02:25.552+0000] {subprocess.py:93} INFO - Traceback (most recent call last):
[2022-12-26T10:02:25.557+0000] {subprocess.py:93} INFO -   File "/opt/***/tasks/data_cleansing_counter_stat.py", line 75, in <module>
[2022-12-26T10:02:25.560+0000] {subprocess.py:93} INFO -     result = counter_stat_job.execute_in_process()
[2022-12-26T10:02:25.562+0000] {subprocess.py:93} INFO -   File "/home/***/.local/lib/python3.7/site-packages/dagster/_core/definitions/job_definition.py", line 394, in execute_in_process
[2022-12-26T10:02:25.564+0000] {subprocess.py:93} INFO -     asset_selection=frozenset(asset_selection),
[2022-12-26T10:02:25.566+0000] {subprocess.py:93} INFO -   File "/home/***/.local/lib/python3.7/site-packages/dagster/_core/execution/execute_in_process.py", line 77, in core_execute_in_process
[2022-12-26T10:02:25.571+0000] {subprocess.py:93} INFO -     event_list = list(execute_run_iterable)
[2022-12-26T10:02:25.573+0000] {subprocess.py:93} INFO -   File "/home/***/.local/lib/python3.7/site-packages/dagster/_core/execution/api.py", line 1192, in __iter__
[2022-12-26T10:02:25.579+0000] {subprocess.py:93} INFO -     pipeline_context=self.pipeline_context,
[2022-12-26T10:02:25.583+0000] {subprocess.py:93} INFO -   File "/home/***/.local/lib/python3.7/site-packages/dagster/_core/execution/api.py", line 1089, in pipeline_execution_iterator
[2022-12-26T10:02:25.587+0000] {subprocess.py:93} INFO -     for event in pipeline_context.executor.execute(pipeline_context, execution_plan):
[2022-12-26T10:02:25.590+0000] {subprocess.py:93} INFO -   File "/home/***/.local/lib/python3.7/site-packages/dagster/_core/executor/in_process.py", line 50, in execute
[2022-12-26T10:02:25.591+0000] {subprocess.py:93} INFO -     output_capture=plan_context.output_capture,
[2022-12-26T10:02:25.593+0000] {subprocess.py:93} INFO -   File "/home/***/.local/lib/python3.7/site-packages/dagster/_core/execution/api.py", line 1192, in __iter__
[2022-12-26T10:02:25.593+0000] {subprocess.py:93} INFO -     pipeline_context=self.pipeline_context,
[2022-12-26T10:02:25.595+0000] {subprocess.py:93} INFO -   File "/home/***/.local/lib/python3.7/site-packages/dagster/_core/execution/plan/execute_plan.py", line 115, in inner_plan_execution_iterator
[2022-12-26T10:02:25.596+0000] {subprocess.py:93} INFO -     dagster_event_sequence_for_step(step_context)
[2022-12-26T10:02:25.597+0000] {subprocess.py:93} INFO -   File "/home/***/.local/lib/python3.7/site-packages/dagster/_core/execution/plan/execute_plan.py", line 340, in dagster_event_sequence_for_step
[2022-12-26T10:02:25.599+0000] {subprocess.py:93} INFO -     raise dagster_user_error.user_exception
[2022-12-26T10:02:25.602+0000] {subprocess.py:93} INFO -   File "/home/***/.local/lib/python3.7/site-packages/dagster/_core/execution/plan/utils.py", line 56, in op_execution_error_boundary
[2022-12-26T10:02:25.604+0000] {subprocess.py:93} INFO -     yield
[2022-12-26T10:02:25.605+0000] {subprocess.py:93} INFO -   File "/home/***/.local/lib/python3.7/site-packages/dagster/_utils/__init__.py", line 458, in iterate_with_context
[2022-12-26T10:02:25.606+0000] {subprocess.py:93} INFO -     next_output = next(iterator)
[2022-12-26T10:02:25.607+0000] {subprocess.py:93} INFO -   File "/home/***/.local/lib/python3.7/site-packages/dagster/_core/execution/plan/compute_generator.py", line 75, in _coerce_solid_compute_fn_to_iterator
[2022-12-26T10:02:25.609+0000] {subprocess.py:93} INFO -     result = fn(context, **kwargs) if context_arg_provided else fn(**kwargs)
[2022-12-26T10:02:25.611+0000] {subprocess.py:93} INFO -   File "/opt/***/tasks/data_cleansing_counter_stat.py", line 20, in read_json
[2022-12-26T10:02:25.612+0000] {subprocess.py:93} INFO -     df = pd.read_json("/opt/***/zone1/lol_counter_stat.json",lines=True)
[2022-12-26T10:02:25.613+0000] {subprocess.py:93} INFO -   File "/home/***/.local/lib/python3.7/site-packages/pandas/util/_decorators.py", line 207, in wrapper
[2022-12-26T10:02:25.613+0000] {subprocess.py:93} INFO -     return func(*args, **kwargs)
[2022-12-26T10:02:25.615+0000] {subprocess.py:93} INFO -   File "/home/***/.local/lib/python3.7/site-packages/pandas/util/_decorators.py", line 311, in wrapper
[2022-12-26T10:02:25.616+0000] {subprocess.py:93} INFO -     return func(*args, **kwargs)
[2022-12-26T10:02:25.616+0000] {subprocess.py:93} INFO -   File "/home/***/.local/lib/python3.7/site-packages/pandas/io/json/_json.py", line 614, in read_json
[2022-12-26T10:02:25.617+0000] {subprocess.py:93} INFO -     return json_reader.read()
[2022-12-26T10:02:25.618+0000] {subprocess.py:93} INFO -   File "/home/***/.local/lib/python3.7/site-packages/pandas/io/json/_json.py", line 746, in read
[2022-12-26T10:02:25.620+0000] {subprocess.py:93} INFO -     obj = self._get_object_parser(self._combine_lines(data_lines))
[2022-12-26T10:02:25.621+0000] {subprocess.py:93} INFO -   File "/home/***/.local/lib/python3.7/site-packages/pandas/io/json/_json.py", line 770, in _get_object_parser
[2022-12-26T10:02:25.622+0000] {subprocess.py:93} INFO -     obj = FrameParser(json, **kwargs).parse()
[2022-12-26T10:02:25.624+0000] {subprocess.py:93} INFO -   File "/home/***/.local/lib/python3.7/site-packages/pandas/io/json/_json.py", line 885, in parse
[2022-12-26T10:02:25.624+0000] {subprocess.py:93} INFO -     self._parse_no_numpy()
[2022-12-26T10:02:25.632+0000] {subprocess.py:93} INFO -   File "/home/***/.local/lib/python3.7/site-packages/pandas/io/json/_json.py", line 1140, in _parse_no_numpy
[2022-12-26T10:02:25.633+0000] {subprocess.py:93} INFO -     loads(json, precise_float=self.precise_float), dtype=None
[2022-12-26T10:02:25.634+0000] {subprocess.py:93} INFO - ValueError: Expected object or value
[2022-12-26T10:02:26.415+0000] {subprocess.py:97} INFO - Command exited with return code 1
[2022-12-26T10:02:26.536+0000] {taskinstance.py:1772} ERROR - Task failed with exception
Traceback (most recent call last):
  File "/home/airflow/.local/lib/python3.7/site-packages/airflow/operators/bash.py", line 197, in execute
    f"Bash command failed. The command returned a non-zero exit code {result.exit_code}."
airflow.exceptions.AirflowException: Bash command failed. The command returned a non-zero exit code 1.
[2022-12-26T10:02:26.565+0000] {taskinstance.py:1327} INFO - Marking task as FAILED. dag_id=Can_I_change_name_to_this, task_id=counter_data_cleansing, execution_date=20221225T100000, start_date=20221226T100217, end_date=20221226T100226
[2022-12-26T10:02:26.639+0000] {standard_task_runner.py:105} ERROR - Failed to execute job 269 for task counter_data_cleansing (Bash command failed. The command returned a non-zero exit code 1.; 165)
[2022-12-26T10:02:26.738+0000] {local_task_job.py:159} INFO - Task exited with return code 1
[2022-12-26T10:02:26.829+0000] {taskinstance.py:2582} INFO - 0 downstream tasks scheduled from follow-on schedule check
