[2022-12-17T03:05:34.534+0000] {taskinstance.py:1165} INFO - Dependencies all met for <TaskInstance: Can_I_change_name_to_this.task_6 manual__2022-12-17T03:04:45.117451+00:00 [queued]>
[2022-12-17T03:05:34.550+0000] {taskinstance.py:1165} INFO - Dependencies all met for <TaskInstance: Can_I_change_name_to_this.task_6 manual__2022-12-17T03:04:45.117451+00:00 [queued]>
[2022-12-17T03:05:34.551+0000] {taskinstance.py:1362} INFO - 
--------------------------------------------------------------------------------
[2022-12-17T03:05:34.552+0000] {taskinstance.py:1363} INFO - Starting attempt 1 of 1
[2022-12-17T03:05:34.554+0000] {taskinstance.py:1364} INFO - 
--------------------------------------------------------------------------------
[2022-12-17T03:05:34.575+0000] {taskinstance.py:1383} INFO - Executing <Task(BashOperator): task_6> on 2022-12-17 03:04:45.117451+00:00
[2022-12-17T03:05:34.596+0000] {standard_task_runner.py:55} INFO - Started process 284 to run task
[2022-12-17T03:05:34.614+0000] {standard_task_runner.py:82} INFO - Running: ['***', 'tasks', 'run', 'Can_I_change_name_to_this', 'task_6', 'manual__2022-12-17T03:04:45.117451+00:00', '--job-id', '83', '--raw', '--subdir', 'DAGS_FOLDER/dags.py', '--cfg-path', '/tmp/tmpu6j6utc4']
[2022-12-17T03:05:34.617+0000] {standard_task_runner.py:83} INFO - Job 83: Subtask task_6
[2022-12-17T03:05:34.733+0000] {task_command.py:376} INFO - Running <TaskInstance: Can_I_change_name_to_this.task_6 manual__2022-12-17T03:04:45.117451+00:00 [running]> on host c8f80f7eb8b2
[2022-12-17T03:05:34.843+0000] {taskinstance.py:1592} INFO - Exporting the following env vars:
AIRFLOW_CTX_DAG_OWNER=***
AIRFLOW_CTX_DAG_ID=Can_I_change_name_to_this
AIRFLOW_CTX_TASK_ID=task_6
AIRFLOW_CTX_EXECUTION_DATE=2022-12-17T03:04:45.117451+00:00
AIRFLOW_CTX_TRY_NUMBER=1
AIRFLOW_CTX_DAG_RUN_ID=manual__2022-12-17T03:04:45.117451+00:00
[2022-12-17T03:05:34.860+0000] {subprocess.py:63} INFO - Tmp dir root location: 
 /tmp
[2022-12-17T03:05:34.864+0000] {subprocess.py:75} INFO - Running command: ['/bin/bash', '-c', 'python /opt/***/tasks/data_cleansing_basic_stat.py']
[2022-12-17T03:05:34.944+0000] {subprocess.py:86} INFO - Output:
[2022-12-17T03:05:44.236+0000] {subprocess.py:93} INFO - 2022-12-17 03:05:44 +0000 - dagster - DEBUG - data_cleansing_whole_job - 4c55c977-0d51-4945-a789-c24352529a85 - 286 - RUN_START - Started execution of run for "data_cleansing_whole_job".
[2022-12-17T03:05:44.285+0000] {subprocess.py:93} INFO - 2022-12-17 03:05:44 +0000 - dagster - DEBUG - data_cleansing_whole_job - 4c55c977-0d51-4945-a789-c24352529a85 - 286 - ENGINE_EVENT - Executing steps in process (pid: 286)
[2022-12-17T03:05:44.291+0000] {subprocess.py:93} INFO - 2022-12-17 03:05:44 +0000 - dagster - DEBUG - data_cleansing_whole_job - 4c55c977-0d51-4945-a789-c24352529a85 - 286 - RESOURCE_INIT_STARTED - Starting initialization of resources [io_manager].
[2022-12-17T03:05:44.295+0000] {subprocess.py:93} INFO - 2022-12-17 03:05:44 +0000 - dagster - DEBUG - data_cleansing_whole_job - 4c55c977-0d51-4945-a789-c24352529a85 - 286 - RESOURCE_INIT_SUCCESS - Finished initialization of resources [io_manager].
[2022-12-17T03:05:44.297+0000] {subprocess.py:93} INFO - 2022-12-17 03:05:44 +0000 - dagster - DEBUG - data_cleansing_whole_job - 4c55c977-0d51-4945-a789-c24352529a85 - 286 - LOGS_CAPTURED - Started capturing logs in process (pid: 286).
[2022-12-17T03:05:44.326+0000] {subprocess.py:93} INFO - 2022-12-17 03:05:44 +0000 - dagster - DEBUG - data_cleansing_whole_job - 4c55c977-0d51-4945-a789-c24352529a85 - 286 - reading_json - STEP_START - Started execution of step "reading_json".
[2022-12-17T03:05:44.606+0000] {subprocess.py:93} INFO - 2022-12-17 03:05:44 +0000 - dagster - DEBUG - data_cleansing_whole_job - 4c55c977-0d51-4945-a789-c24352529a85 - 286 - reading_json - STEP_OUTPUT - Yielded output "result" of type "DataFrame". (Type check passed).
[2022-12-17T03:05:44.608+0000] {subprocess.py:93} INFO - 2022-12-17 03:05:44 +0000 - dagster - DEBUG - data_cleansing_whole_job - 4c55c977-0d51-4945-a789-c24352529a85 - 286 - reading_json - HANDLED_OUTPUT - Handled output "result" using IO manager "io_manager"
[2022-12-17T03:05:44.611+0000] {subprocess.py:93} INFO - 2022-12-17 03:05:44 +0000 - dagster - DEBUG - data_cleansing_whole_job - 4c55c977-0d51-4945-a789-c24352529a85 - 286 - reading_json - STEP_SUCCESS - Finished execution of step "reading_json" in 362ms.
[2022-12-17T03:05:44.613+0000] {subprocess.py:93} INFO - 2022-12-17 03:05:44 +0000 - dagster - DEBUG - data_cleansing_whole_job - 4c55c977-0d51-4945-a789-c24352529a85 - 286 - data_validation - STEP_START - Started execution of step "data_validation".
[2022-12-17T03:05:44.616+0000] {subprocess.py:93} INFO - 2022-12-17 03:05:44 +0000 - dagster - DEBUG - data_cleansing_whole_job - 4c55c977-0d51-4945-a789-c24352529a85 - 286 - data_validation - LOADED_INPUT - Loaded input "df" using input manager "io_manager", from output "result" of step "reading_json"
[2022-12-17T03:05:44.617+0000] {subprocess.py:93} INFO - 2022-12-17 03:05:44 +0000 - dagster - DEBUG - data_cleansing_whole_job - 4c55c977-0d51-4945-a789-c24352529a85 - 286 - data_validation - STEP_INPUT - Got input "df" of type "DataFrame". (Type check passed).
[2022-12-17T03:05:44.649+0000] {subprocess.py:93} INFO - 2022-12-17 03:05:44 +0000 - dagster - DEBUG - data_cleansing_whole_job - 4c55c977-0d51-4945-a789-c24352529a85 - 286 - data_validation - STEP_OUTPUT - Yielded output "result" of type "DataFrame". (Type check passed).
[2022-12-17T03:05:44.651+0000] {subprocess.py:93} INFO - 2022-12-17 03:05:44 +0000 - dagster - DEBUG - data_cleansing_whole_job - 4c55c977-0d51-4945-a789-c24352529a85 - 286 - data_validation - HANDLED_OUTPUT - Handled output "result" using IO manager "io_manager"
[2022-12-17T03:05:44.652+0000] {subprocess.py:93} INFO - 2022-12-17 03:05:44 +0000 - dagster - DEBUG - data_cleansing_whole_job - 4c55c977-0d51-4945-a789-c24352529a85 - 286 - data_validation - STEP_SUCCESS - Finished execution of step "data_validation" in 26ms.
[2022-12-17T03:05:44.653+0000] {subprocess.py:93} INFO - 2022-12-17 03:05:44 +0000 - dagster - DEBUG - data_cleansing_whole_job - 4c55c977-0d51-4945-a789-c24352529a85 - 286 - data_cleaning - STEP_START - Started execution of step "data_cleaning".
[2022-12-17T03:05:44.655+0000] {subprocess.py:93} INFO - 2022-12-17 03:05:44 +0000 - dagster - DEBUG - data_cleansing_whole_job - 4c55c977-0d51-4945-a789-c24352529a85 - 286 - data_cleaning - LOADED_INPUT - Loaded input "df" using input manager "io_manager", from output "result" of step "data_validation"
[2022-12-17T03:05:44.657+0000] {subprocess.py:93} INFO - 2022-12-17 03:05:44 +0000 - dagster - DEBUG - data_cleansing_whole_job - 4c55c977-0d51-4945-a789-c24352529a85 - 286 - data_cleaning - STEP_INPUT - Got input "df" of type "DataFrame". (Type check passed).
[2022-12-17T03:05:44.658+0000] {subprocess.py:93} INFO - {"message": "now perform data cleansing on lol_basic_stat", "time": "2022-12-17T03:05:44.658159"}
[2022-12-17T03:05:44.664+0000] {subprocess.py:93} INFO - {"message": "successfully perform data cleansing on lol_basic_stat", "time": "2022-12-17T03:05:44.663966"}
[2022-12-17T03:05:44.665+0000] {subprocess.py:93} INFO - {"message": "Now putting dataframe into pg and redshift", "time": "2022-12-17T03:05:44.665338"}
[2022-12-17T03:05:44.670+0000] {subprocess.py:93} INFO - 2022-12-17 03:05:44 +0000 - dagster - DEBUG - data_cleansing_whole_job - 4c55c977-0d51-4945-a789-c24352529a85 - 286 - data_cleaning - STEP_OUTPUT - Yielded output "result" of type "DataFrame". (Type check passed).
[2022-12-17T03:05:44.710+0000] {subprocess.py:93} INFO - 2022-12-17 03:05:44 +0000 - dagster - DEBUG - data_cleansing_whole_job - 4c55c977-0d51-4945-a789-c24352529a85 - 286 - data_cleaning - HANDLED_OUTPUT - Handled output "result" using IO manager "io_manager"
[2022-12-17T03:05:44.715+0000] {subprocess.py:93} INFO - 2022-12-17 03:05:44 +0000 - dagster - DEBUG - data_cleansing_whole_job - 4c55c977-0d51-4945-a789-c24352529a85 - 286 - data_cleaning - STEP_SUCCESS - Finished execution of step "data_cleaning" in 53ms.
[2022-12-17T03:05:44.724+0000] {subprocess.py:93} INFO - 2022-12-17 03:05:44 +0000 - dagster - DEBUG - data_cleansing_whole_job - 4c55c977-0d51-4945-a789-c24352529a85 - 286 - df_to_file - STEP_START - Started execution of step "df_to_file".
[2022-12-17T03:05:44.734+0000] {subprocess.py:93} INFO - 2022-12-17 03:05:44 +0000 - dagster - DEBUG - data_cleansing_whole_job - 4c55c977-0d51-4945-a789-c24352529a85 - 286 - df_to_file - LOADED_INPUT - Loaded input "df" using input manager "io_manager", from output "result" of step "data_cleaning"
[2022-12-17T03:05:44.737+0000] {subprocess.py:93} INFO - 2022-12-17 03:05:44 +0000 - dagster - DEBUG - data_cleansing_whole_job - 4c55c977-0d51-4945-a789-c24352529a85 - 286 - df_to_file - STEP_INPUT - Got input "df" of type "DataFrame". (Type check passed).
[2022-12-17T03:05:44.763+0000] {subprocess.py:93} INFO - 2022-12-17 03:05:44 +0000 - dagster - DEBUG - data_cleansing_whole_job - 4c55c977-0d51-4945-a789-c24352529a85 - 286 - df_to_file - STEP_OUTPUT - Yielded output "result" of type "Any". (Type check passed).
[2022-12-17T03:05:44.801+0000] {subprocess.py:93} INFO - 2022-12-17 03:05:44 +0000 - dagster - DEBUG - data_cleansing_whole_job - 4c55c977-0d51-4945-a789-c24352529a85 - 286 - df_to_file - HANDLED_OUTPUT - Handled output "result" using IO manager "io_manager"
[2022-12-17T03:05:44.805+0000] {subprocess.py:93} INFO - 2022-12-17 03:05:44 +0000 - dagster - DEBUG - data_cleansing_whole_job - 4c55c977-0d51-4945-a789-c24352529a85 - 286 - df_to_file - STEP_SUCCESS - Finished execution of step "df_to_file" in 34ms.
[2022-12-17T03:05:44.831+0000] {subprocess.py:93} INFO - 2022-12-17 03:05:44 +0000 - dagster - DEBUG - data_cleansing_whole_job - 4c55c977-0d51-4945-a789-c24352529a85 - 286 - sending_to_pg - STEP_START - Started execution of step "sending_to_pg".
[2022-12-17T03:05:44.833+0000] {subprocess.py:93} INFO - 2022-12-17 03:05:44 +0000 - dagster - DEBUG - data_cleansing_whole_job - 4c55c977-0d51-4945-a789-c24352529a85 - 286 - sending_to_pg - LOADED_INPUT - Loaded input "df" using input manager "io_manager", from output "result" of step "data_cleaning"
[2022-12-17T03:05:44.839+0000] {subprocess.py:93} INFO - 2022-12-17 03:05:44 +0000 - dagster - DEBUG - data_cleansing_whole_job - 4c55c977-0d51-4945-a789-c24352529a85 - 286 - sending_to_pg - STEP_INPUT - Got input "df" of type "DataFrame". (Type check passed).
[2022-12-17T03:05:44.997+0000] {subprocess.py:93} INFO - 2022-12-17 03:05:44 +0000 - dagster - ERROR - data_cleansing_whole_job - 4c55c977-0d51-4945-a789-c24352529a85 - 286 - sending_to_pg - STEP_FAILURE - Execution of step "sending_to_pg" failed.
[2022-12-17T03:05:45.001+0000] {subprocess.py:93} INFO - 
[2022-12-17T03:05:45.003+0000] {subprocess.py:93} INFO - dagster._core.errors.DagsterExecutionStepExecutionError: Error occurred while executing op "sending_to_pg"::
[2022-12-17T03:05:45.007+0000] {subprocess.py:93} INFO - 
[2022-12-17T03:05:45.009+0000] {subprocess.py:93} INFO - sqlalchemy.exc.OperationalError: (psycopg2.OperationalError) connection to server at "localhost" (127.0.0.1), port 5432 failed: Connection refused
[2022-12-17T03:05:45.016+0000] {subprocess.py:93} INFO - 	Is the server running on that host and accepting TCP/IP connections?
[2022-12-17T03:05:45.095+0000] {subprocess.py:93} INFO - connection to server at "localhost" (::1), port 5432 failed: Cannot assign requested address
[2022-12-17T03:05:45.097+0000] {subprocess.py:93} INFO - 	Is the server running on that host and accepting TCP/IP connections?
[2022-12-17T03:05:45.098+0000] {subprocess.py:93} INFO - 
[2022-12-17T03:05:45.103+0000] {subprocess.py:93} INFO - (Background on this error at: https://sqlalche.me/e/14/e3q8)
[2022-12-17T03:05:45.104+0000] {subprocess.py:93} INFO - 
[2022-12-17T03:05:45.105+0000] {subprocess.py:93} INFO - Stack Trace:
[2022-12-17T03:05:45.108+0000] {subprocess.py:93} INFO -   File "/home/***/.local/lib/python3.7/site-packages/dagster/_core/execution/plan/utils.py", line 47, in solid_execution_error_boundary
[2022-12-17T03:05:45.138+0000] {subprocess.py:93} INFO -     yield
[2022-12-17T03:05:45.146+0000] {subprocess.py:93} INFO -   File "/home/***/.local/lib/python3.7/site-packages/dagster/_utils/__init__.py", line 447, in iterate_with_context
[2022-12-17T03:05:45.161+0000] {subprocess.py:93} INFO -     next_output = next(iterator)
[2022-12-17T03:05:45.165+0000] {subprocess.py:93} INFO -   File "/home/***/.local/lib/python3.7/site-packages/dagster/_core/execution/plan/compute_generator.py", line 74, in _coerce_solid_compute_fn_to_iterator
[2022-12-17T03:05:45.167+0000] {subprocess.py:93} INFO -     result = fn(context, **kwargs) if context_arg_provided else fn(**kwargs)
[2022-12-17T03:05:45.172+0000] {subprocess.py:93} INFO -   File "/opt/***/tasks/data_cleansing_basic_stat.py", line 77, in sending_to_pg
[2022-12-17T03:05:45.184+0000] {subprocess.py:93} INFO -     df.to_sql('lol_basic_stat',con=pg_engine,if_exists="append",index=False)
[2022-12-17T03:05:45.193+0000] {subprocess.py:93} INFO -   File "/home/***/.local/lib/python3.7/site-packages/pandas/core/generic.py", line 2882, in to_sql
[2022-12-17T03:05:45.194+0000] {subprocess.py:93} INFO -     method=method,
[2022-12-17T03:05:45.200+0000] {subprocess.py:93} INFO -   File "/home/***/.local/lib/python3.7/site-packages/pandas/io/sql.py", line 728, in to_sql
[2022-12-17T03:05:45.208+0000] {subprocess.py:93} INFO -     **engine_kwargs,
[2022-12-17T03:05:45.211+0000] {subprocess.py:93} INFO -   File "/home/***/.local/lib/python3.7/site-packages/pandas/io/sql.py", line 1758, in to_sql
[2022-12-17T03:05:45.216+0000] {subprocess.py:93} INFO -     dtype=dtype,
[2022-12-17T03:05:45.224+0000] {subprocess.py:93} INFO -   File "/home/***/.local/lib/python3.7/site-packages/pandas/io/sql.py", line 1650, in prep_table
[2022-12-17T03:05:45.228+0000] {subprocess.py:93} INFO -     table.create()
[2022-12-17T03:05:45.231+0000] {subprocess.py:93} INFO -   File "/home/***/.local/lib/python3.7/site-packages/pandas/io/sql.py", line 856, in create
[2022-12-17T03:05:45.236+0000] {subprocess.py:93} INFO -     if self.exists():
[2022-12-17T03:05:45.248+0000] {subprocess.py:93} INFO -   File "/home/***/.local/lib/python3.7/site-packages/pandas/io/sql.py", line 840, in exists
[2022-12-17T03:05:45.249+0000] {subprocess.py:93} INFO -     return self.pd_sql.has_table(self.name, self.schema)
[2022-12-17T03:05:45.251+0000] {subprocess.py:93} INFO -   File "/home/***/.local/lib/python3.7/site-packages/pandas/io/sql.py", line 1783, in has_table
[2022-12-17T03:05:45.257+0000] {subprocess.py:93} INFO -     insp = sa.inspect(self.connectable)
[2022-12-17T03:05:45.259+0000] {subprocess.py:93} INFO -   File "/home/***/.local/lib/python3.7/site-packages/sqlalchemy/inspection.py", line 64, in inspect
[2022-12-17T03:05:45.267+0000] {subprocess.py:93} INFO -     ret = reg(subject)
[2022-12-17T03:05:45.275+0000] {subprocess.py:93} INFO -   File "/home/***/.local/lib/python3.7/site-packages/sqlalchemy/engine/reflection.py", line 182, in _engine_insp
[2022-12-17T03:05:45.283+0000] {subprocess.py:93} INFO -     return Inspector._construct(Inspector._init_engine, bind)
[2022-12-17T03:05:45.292+0000] {subprocess.py:93} INFO -   File "/home/***/.local/lib/python3.7/site-packages/sqlalchemy/engine/reflection.py", line 117, in _construct
[2022-12-17T03:05:45.304+0000] {subprocess.py:93} INFO -     init(self, bind)
[2022-12-17T03:05:45.307+0000] {subprocess.py:93} INFO -   File "/home/***/.local/lib/python3.7/site-packages/sqlalchemy/engine/reflection.py", line 128, in _init_engine
[2022-12-17T03:05:45.312+0000] {subprocess.py:93} INFO -     engine.connect().close()
[2022-12-17T03:05:45.315+0000] {subprocess.py:93} INFO -   File "/home/***/.local/lib/python3.7/site-packages/sqlalchemy/engine/base.py", line 3197, in connect
[2022-12-17T03:05:45.330+0000] {subprocess.py:93} INFO -     return self._connection_cls(self, close_with_result=close_with_result)
[2022-12-17T03:05:45.334+0000] {subprocess.py:93} INFO -   File "/home/***/.local/lib/python3.7/site-packages/sqlalchemy/engine/base.py", line 96, in __init__
[2022-12-17T03:05:45.337+0000] {subprocess.py:93} INFO -     else engine.raw_connection()
[2022-12-17T03:05:45.341+0000] {subprocess.py:93} INFO -   File "/home/***/.local/lib/python3.7/site-packages/sqlalchemy/engine/base.py", line 3276, in raw_connection
[2022-12-17T03:05:45.351+0000] {subprocess.py:93} INFO -     return self._wrap_pool_connect(self.pool.connect, _connection)
[2022-12-17T03:05:45.360+0000] {subprocess.py:93} INFO -   File "/home/***/.local/lib/python3.7/site-packages/sqlalchemy/engine/base.py", line 3247, in _wrap_pool_connect
[2022-12-17T03:05:45.366+0000] {subprocess.py:93} INFO -     e, dialect, self
[2022-12-17T03:05:45.376+0000] {subprocess.py:93} INFO -   File "/home/***/.local/lib/python3.7/site-packages/sqlalchemy/engine/base.py", line 2101, in _handle_dbapi_exception_noconnection
[2022-12-17T03:05:45.379+0000] {subprocess.py:93} INFO -     sqlalchemy_exception, with_traceback=exc_info[2], from_=e
[2022-12-17T03:05:45.384+0000] {subprocess.py:93} INFO -   File "/home/***/.local/lib/python3.7/site-packages/sqlalchemy/util/compat.py", line 207, in raise_
[2022-12-17T03:05:45.387+0000] {subprocess.py:93} INFO -     raise exception
[2022-12-17T03:05:45.388+0000] {subprocess.py:93} INFO -   File "/home/***/.local/lib/python3.7/site-packages/sqlalchemy/engine/base.py", line 3243, in _wrap_pool_connect
[2022-12-17T03:05:45.389+0000] {subprocess.py:93} INFO -     return fn()
[2022-12-17T03:05:45.391+0000] {subprocess.py:93} INFO -   File "/home/***/.local/lib/python3.7/site-packages/sqlalchemy/pool/base.py", line 310, in connect
[2022-12-17T03:05:45.392+0000] {subprocess.py:93} INFO -     return _ConnectionFairy._checkout(self)
[2022-12-17T03:05:45.393+0000] {subprocess.py:93} INFO -   File "/home/***/.local/lib/python3.7/site-packages/sqlalchemy/pool/base.py", line 868, in _checkout
[2022-12-17T03:05:45.395+0000] {subprocess.py:93} INFO -     fairy = _ConnectionRecord.checkout(pool)
[2022-12-17T03:05:45.399+0000] {subprocess.py:93} INFO -   File "/home/***/.local/lib/python3.7/site-packages/sqlalchemy/pool/base.py", line 476, in checkout
[2022-12-17T03:05:45.400+0000] {subprocess.py:93} INFO -     rec = pool._do_get()
[2022-12-17T03:05:45.401+0000] {subprocess.py:93} INFO -   File "/home/***/.local/lib/python3.7/site-packages/sqlalchemy/pool/impl.py", line 146, in _do_get
[2022-12-17T03:05:45.402+0000] {subprocess.py:93} INFO -     self._dec_overflow()
[2022-12-17T03:05:45.404+0000] {subprocess.py:93} INFO -   File "/home/***/.local/lib/python3.7/site-packages/sqlalchemy/util/langhelpers.py", line 72, in __exit__
[2022-12-17T03:05:45.407+0000] {subprocess.py:93} INFO -     with_traceback=exc_tb,
[2022-12-17T03:05:45.408+0000] {subprocess.py:93} INFO -   File "/home/***/.local/lib/python3.7/site-packages/sqlalchemy/util/compat.py", line 207, in raise_
[2022-12-17T03:05:45.409+0000] {subprocess.py:93} INFO -     raise exception
[2022-12-17T03:05:45.415+0000] {subprocess.py:93} INFO -   File "/home/***/.local/lib/python3.7/site-packages/sqlalchemy/pool/impl.py", line 143, in _do_get
[2022-12-17T03:05:45.417+0000] {subprocess.py:93} INFO -     return self._create_connection()
[2022-12-17T03:05:45.419+0000] {subprocess.py:93} INFO -   File "/home/***/.local/lib/python3.7/site-packages/sqlalchemy/pool/base.py", line 256, in _create_connection
[2022-12-17T03:05:45.422+0000] {subprocess.py:93} INFO -     return _ConnectionRecord(self)
[2022-12-17T03:05:45.425+0000] {subprocess.py:93} INFO -   File "/home/***/.local/lib/python3.7/site-packages/sqlalchemy/pool/base.py", line 371, in __init__
[2022-12-17T03:05:45.430+0000] {subprocess.py:93} INFO -     self.__connect()
[2022-12-17T03:05:45.447+0000] {subprocess.py:93} INFO -   File "/home/***/.local/lib/python3.7/site-packages/sqlalchemy/pool/base.py", line 666, in __connect
[2022-12-17T03:05:45.460+0000] {subprocess.py:93} INFO -     pool.logger.debug("Error on connect(): %s", e)
[2022-12-17T03:05:45.461+0000] {subprocess.py:93} INFO -   File "/home/***/.local/lib/python3.7/site-packages/sqlalchemy/util/langhelpers.py", line 72, in __exit__
[2022-12-17T03:05:45.469+0000] {subprocess.py:93} INFO -     with_traceback=exc_tb,
[2022-12-17T03:05:45.473+0000] {subprocess.py:93} INFO -   File "/home/***/.local/lib/python3.7/site-packages/sqlalchemy/util/compat.py", line 207, in raise_
[2022-12-17T03:05:45.481+0000] {subprocess.py:93} INFO -     raise exception
[2022-12-17T03:05:45.482+0000] {subprocess.py:93} INFO -   File "/home/***/.local/lib/python3.7/site-packages/sqlalchemy/pool/base.py", line 661, in __connect
[2022-12-17T03:05:45.485+0000] {subprocess.py:93} INFO -     self.dbapi_connection = connection = pool._invoke_creator(self)
[2022-12-17T03:05:45.489+0000] {subprocess.py:93} INFO -   File "/home/***/.local/lib/python3.7/site-packages/sqlalchemy/engine/create.py", line 590, in connect
[2022-12-17T03:05:45.491+0000] {subprocess.py:93} INFO -     return dialect.connect(*cargs, **cparams)
[2022-12-17T03:05:45.494+0000] {subprocess.py:93} INFO -   File "/home/***/.local/lib/python3.7/site-packages/sqlalchemy/engine/default.py", line 584, in connect
[2022-12-17T03:05:45.505+0000] {subprocess.py:93} INFO -     return self.dbapi.connect(*cargs, **cparams)
[2022-12-17T03:05:45.505+0000] {subprocess.py:93} INFO -   File "/home/***/.local/lib/python3.7/site-packages/psycopg2/__init__.py", line 122, in connect
[2022-12-17T03:05:45.510+0000] {subprocess.py:93} INFO -     conn = _connect(dsn, connection_factory=connection_factory, **kwasync)
[2022-12-17T03:05:45.524+0000] {subprocess.py:93} INFO - 
[2022-12-17T03:05:45.527+0000] {subprocess.py:93} INFO - The above exception was caused by the following exception:
[2022-12-17T03:05:45.539+0000] {subprocess.py:93} INFO - psycopg2.OperationalError: connection to server at "localhost" (127.0.0.1), port 5432 failed: Connection refused
[2022-12-17T03:05:45.550+0000] {subprocess.py:93} INFO - 	Is the server running on that host and accepting TCP/IP connections?
[2022-12-17T03:05:45.553+0000] {subprocess.py:93} INFO - connection to server at "localhost" (::1), port 5432 failed: Cannot assign requested address
[2022-12-17T03:05:45.554+0000] {subprocess.py:93} INFO - 	Is the server running on that host and accepting TCP/IP connections?
[2022-12-17T03:05:45.556+0000] {subprocess.py:93} INFO - 
[2022-12-17T03:05:45.558+0000] {subprocess.py:93} INFO - 
[2022-12-17T03:05:45.569+0000] {subprocess.py:93} INFO - Stack Trace:
[2022-12-17T03:05:45.571+0000] {subprocess.py:93} INFO -   File "/home/***/.local/lib/python3.7/site-packages/sqlalchemy/engine/base.py", line 3243, in _wrap_pool_connect
[2022-12-17T03:05:45.573+0000] {subprocess.py:93} INFO -     return fn()
[2022-12-17T03:05:45.575+0000] {subprocess.py:93} INFO -   File "/home/***/.local/lib/python3.7/site-packages/sqlalchemy/pool/base.py", line 310, in connect
[2022-12-17T03:05:45.577+0000] {subprocess.py:93} INFO -     return _ConnectionFairy._checkout(self)
[2022-12-17T03:05:45.580+0000] {subprocess.py:93} INFO -   File "/home/***/.local/lib/python3.7/site-packages/sqlalchemy/pool/base.py", line 868, in _checkout
[2022-12-17T03:05:45.582+0000] {subprocess.py:93} INFO -     fairy = _ConnectionRecord.checkout(pool)
[2022-12-17T03:05:45.584+0000] {subprocess.py:93} INFO -   File "/home/***/.local/lib/python3.7/site-packages/sqlalchemy/pool/base.py", line 476, in checkout
[2022-12-17T03:05:45.586+0000] {subprocess.py:93} INFO -     rec = pool._do_get()
[2022-12-17T03:05:45.587+0000] {subprocess.py:93} INFO -   File "/home/***/.local/lib/python3.7/site-packages/sqlalchemy/pool/impl.py", line 146, in _do_get
[2022-12-17T03:05:45.589+0000] {subprocess.py:93} INFO -     self._dec_overflow()
[2022-12-17T03:05:45.592+0000] {subprocess.py:93} INFO -   File "/home/***/.local/lib/python3.7/site-packages/sqlalchemy/util/langhelpers.py", line 72, in __exit__
[2022-12-17T03:05:45.594+0000] {subprocess.py:93} INFO -     with_traceback=exc_tb,
[2022-12-17T03:05:45.595+0000] {subprocess.py:93} INFO -   File "/home/***/.local/lib/python3.7/site-packages/sqlalchemy/util/compat.py", line 207, in raise_
[2022-12-17T03:05:45.597+0000] {subprocess.py:93} INFO -     raise exception
[2022-12-17T03:05:45.601+0000] {subprocess.py:93} INFO -   File "/home/***/.local/lib/python3.7/site-packages/sqlalchemy/pool/impl.py", line 143, in _do_get
[2022-12-17T03:05:45.602+0000] {subprocess.py:93} INFO -     return self._create_connection()
[2022-12-17T03:05:45.605+0000] {subprocess.py:93} INFO -   File "/home/***/.local/lib/python3.7/site-packages/sqlalchemy/pool/base.py", line 256, in _create_connection
[2022-12-17T03:05:45.608+0000] {subprocess.py:93} INFO -     return _ConnectionRecord(self)
[2022-12-17T03:05:45.609+0000] {subprocess.py:93} INFO -   File "/home/***/.local/lib/python3.7/site-packages/sqlalchemy/pool/base.py", line 371, in __init__
[2022-12-17T03:05:45.615+0000] {subprocess.py:93} INFO -     self.__connect()
[2022-12-17T03:05:45.622+0000] {subprocess.py:93} INFO -   File "/home/***/.local/lib/python3.7/site-packages/sqlalchemy/pool/base.py", line 666, in __connect
[2022-12-17T03:05:45.624+0000] {subprocess.py:93} INFO -     pool.logger.debug("Error on connect(): %s", e)
[2022-12-17T03:05:45.625+0000] {subprocess.py:93} INFO -   File "/home/***/.local/lib/python3.7/site-packages/sqlalchemy/util/langhelpers.py", line 72, in __exit__
[2022-12-17T03:05:45.626+0000] {subprocess.py:93} INFO -     with_traceback=exc_tb,
[2022-12-17T03:05:45.627+0000] {subprocess.py:93} INFO -   File "/home/***/.local/lib/python3.7/site-packages/sqlalchemy/util/compat.py", line 207, in raise_
[2022-12-17T03:05:45.627+0000] {subprocess.py:93} INFO -     raise exception
[2022-12-17T03:05:45.632+0000] {subprocess.py:93} INFO -   File "/home/***/.local/lib/python3.7/site-packages/sqlalchemy/pool/base.py", line 661, in __connect
[2022-12-17T03:05:45.633+0000] {subprocess.py:93} INFO -     self.dbapi_connection = connection = pool._invoke_creator(self)
[2022-12-17T03:05:45.634+0000] {subprocess.py:93} INFO -   File "/home/***/.local/lib/python3.7/site-packages/sqlalchemy/engine/create.py", line 590, in connect
[2022-12-17T03:05:45.644+0000] {subprocess.py:93} INFO -     return dialect.connect(*cargs, **cparams)
[2022-12-17T03:05:45.646+0000] {subprocess.py:93} INFO -   File "/home/***/.local/lib/python3.7/site-packages/sqlalchemy/engine/default.py", line 584, in connect
[2022-12-17T03:05:45.650+0000] {subprocess.py:93} INFO -     return self.dbapi.connect(*cargs, **cparams)
[2022-12-17T03:05:45.662+0000] {subprocess.py:93} INFO -   File "/home/***/.local/lib/python3.7/site-packages/psycopg2/__init__.py", line 122, in connect
[2022-12-17T03:05:45.668+0000] {subprocess.py:93} INFO -     conn = _connect(dsn, connection_factory=connection_factory, **kwasync)
[2022-12-17T03:05:45.674+0000] {subprocess.py:93} INFO - 
[2022-12-17T03:05:45.695+0000] {subprocess.py:93} INFO - 2022-12-17 03:05:45 +0000 - dagster - ERROR - data_cleansing_whole_job - 4c55c977-0d51-4945-a789-c24352529a85 - 286 - RUN_FAILURE - Execution of run for "data_cleansing_whole_job" failed. An exception was thrown during execution.
[2022-12-17T03:05:45.710+0000] {subprocess.py:93} INFO - 
[2022-12-17T03:05:45.714+0000] {subprocess.py:93} INFO - sqlalchemy.exc.OperationalError: (psycopg2.OperationalError) connection to server at "localhost" (127.0.0.1), port 5432 failed: Connection refused
[2022-12-17T03:05:45.717+0000] {subprocess.py:93} INFO - 	Is the server running on that host and accepting TCP/IP connections?
[2022-12-17T03:05:45.720+0000] {subprocess.py:93} INFO - connection to server at "localhost" (::1), port 5432 failed: Cannot assign requested address
[2022-12-17T03:05:45.722+0000] {subprocess.py:93} INFO - 	Is the server running on that host and accepting TCP/IP connections?
[2022-12-17T03:05:45.727+0000] {subprocess.py:93} INFO - 
[2022-12-17T03:05:45.728+0000] {subprocess.py:93} INFO - (Background on this error at: https://sqlalche.me/e/14/e3q8)
[2022-12-17T03:05:45.734+0000] {subprocess.py:93} INFO - 
[2022-12-17T03:05:45.740+0000] {subprocess.py:93} INFO - Stack Trace:
[2022-12-17T03:05:45.745+0000] {subprocess.py:93} INFO -   File "/home/***/.local/lib/python3.7/site-packages/dagster/_core/execution/api.py", line 1091, in pipeline_execution_iterator
[2022-12-17T03:05:45.750+0000] {subprocess.py:93} INFO -     for event in pipeline_context.executor.execute(pipeline_context, execution_plan):
[2022-12-17T03:05:45.753+0000] {subprocess.py:93} INFO -   File "/home/***/.local/lib/python3.7/site-packages/dagster/_core/executor/in_process.py", line 50, in execute
[2022-12-17T03:05:45.836+0000] {subprocess.py:93} INFO -     output_capture=plan_context.output_capture,
[2022-12-17T03:05:45.839+0000] {subprocess.py:93} INFO -   File "/home/***/.local/lib/python3.7/site-packages/dagster/_core/execution/api.py", line 1189, in __iter__
[2022-12-17T03:05:45.846+0000] {subprocess.py:93} INFO -     pipeline_context=self.pipeline_context,
[2022-12-17T03:05:45.849+0000] {subprocess.py:93} INFO -   File "/home/***/.local/lib/python3.7/site-packages/dagster/_core/execution/plan/execute_plan.py", line 121, in inner_plan_execution_iterator
[2022-12-17T03:05:45.850+0000] {subprocess.py:93} INFO -     dagster_event_sequence_for_step(step_context)
[2022-12-17T03:05:45.850+0000] {subprocess.py:93} INFO -   File "/home/***/.local/lib/python3.7/site-packages/dagster/_core/execution/plan/execute_plan.py", line 325, in dagster_event_sequence_for_step
[2022-12-17T03:05:45.851+0000] {subprocess.py:93} INFO -     raise dagster_user_error.user_exception
[2022-12-17T03:05:45.852+0000] {subprocess.py:93} INFO -   File "/home/***/.local/lib/python3.7/site-packages/dagster/_core/execution/plan/utils.py", line 47, in solid_execution_error_boundary
[2022-12-17T03:05:45.853+0000] {subprocess.py:93} INFO -     yield
[2022-12-17T03:05:45.854+0000] {subprocess.py:93} INFO -   File "/home/***/.local/lib/python3.7/site-packages/dagster/_utils/__init__.py", line 447, in iterate_with_context
[2022-12-17T03:05:45.855+0000] {subprocess.py:93} INFO -     next_output = next(iterator)
[2022-12-17T03:05:45.856+0000] {subprocess.py:93} INFO -   File "/home/***/.local/lib/python3.7/site-packages/dagster/_core/execution/plan/compute_generator.py", line 74, in _coerce_solid_compute_fn_to_iterator
[2022-12-17T03:05:45.858+0000] {subprocess.py:93} INFO -     result = fn(context, **kwargs) if context_arg_provided else fn(**kwargs)
[2022-12-17T03:05:45.859+0000] {subprocess.py:93} INFO -   File "/opt/***/tasks/data_cleansing_basic_stat.py", line 77, in sending_to_pg
[2022-12-17T03:05:45.859+0000] {subprocess.py:93} INFO -     df.to_sql('lol_basic_stat',con=pg_engine,if_exists="append",index=False)
[2022-12-17T03:05:45.860+0000] {subprocess.py:93} INFO -   File "/home/***/.local/lib/python3.7/site-packages/pandas/core/generic.py", line 2882, in to_sql
[2022-12-17T03:05:45.860+0000] {subprocess.py:93} INFO -     method=method,
[2022-12-17T03:05:45.861+0000] {subprocess.py:93} INFO -   File "/home/***/.local/lib/python3.7/site-packages/pandas/io/sql.py", line 728, in to_sql
[2022-12-17T03:05:45.864+0000] {subprocess.py:93} INFO -     **engine_kwargs,
[2022-12-17T03:05:45.864+0000] {subprocess.py:93} INFO -   File "/home/***/.local/lib/python3.7/site-packages/pandas/io/sql.py", line 1758, in to_sql
[2022-12-17T03:05:45.865+0000] {subprocess.py:93} INFO -     dtype=dtype,
[2022-12-17T03:05:45.866+0000] {subprocess.py:93} INFO -   File "/home/***/.local/lib/python3.7/site-packages/pandas/io/sql.py", line 1650, in prep_table
[2022-12-17T03:05:45.871+0000] {subprocess.py:93} INFO -     table.create()
[2022-12-17T03:05:45.873+0000] {subprocess.py:93} INFO -   File "/home/***/.local/lib/python3.7/site-packages/pandas/io/sql.py", line 856, in create
[2022-12-17T03:05:45.873+0000] {subprocess.py:93} INFO -     if self.exists():
[2022-12-17T03:05:45.874+0000] {subprocess.py:93} INFO -   File "/home/***/.local/lib/python3.7/site-packages/pandas/io/sql.py", line 840, in exists
[2022-12-17T03:05:45.875+0000] {subprocess.py:93} INFO -     return self.pd_sql.has_table(self.name, self.schema)
[2022-12-17T03:05:45.876+0000] {subprocess.py:93} INFO -   File "/home/***/.local/lib/python3.7/site-packages/pandas/io/sql.py", line 1783, in has_table
[2022-12-17T03:05:45.877+0000] {subprocess.py:93} INFO -     insp = sa.inspect(self.connectable)
[2022-12-17T03:05:45.879+0000] {subprocess.py:93} INFO -   File "/home/***/.local/lib/python3.7/site-packages/sqlalchemy/inspection.py", line 64, in inspect
[2022-12-17T03:05:45.880+0000] {subprocess.py:93} INFO -     ret = reg(subject)
[2022-12-17T03:05:45.882+0000] {subprocess.py:93} INFO -   File "/home/***/.local/lib/python3.7/site-packages/sqlalchemy/engine/reflection.py", line 182, in _engine_insp
[2022-12-17T03:05:45.883+0000] {subprocess.py:93} INFO -     return Inspector._construct(Inspector._init_engine, bind)
[2022-12-17T03:05:45.884+0000] {subprocess.py:93} INFO -   File "/home/***/.local/lib/python3.7/site-packages/sqlalchemy/engine/reflection.py", line 117, in _construct
[2022-12-17T03:05:45.885+0000] {subprocess.py:93} INFO -     init(self, bind)
[2022-12-17T03:05:45.885+0000] {subprocess.py:93} INFO -   File "/home/***/.local/lib/python3.7/site-packages/sqlalchemy/engine/reflection.py", line 128, in _init_engine
[2022-12-17T03:05:45.887+0000] {subprocess.py:93} INFO -     engine.connect().close()
[2022-12-17T03:05:45.888+0000] {subprocess.py:93} INFO -   File "/home/***/.local/lib/python3.7/site-packages/sqlalchemy/engine/base.py", line 3197, in connect
[2022-12-17T03:05:45.890+0000] {subprocess.py:93} INFO -     return self._connection_cls(self, close_with_result=close_with_result)
[2022-12-17T03:05:45.892+0000] {subprocess.py:93} INFO -   File "/home/***/.local/lib/python3.7/site-packages/sqlalchemy/engine/base.py", line 96, in __init__
[2022-12-17T03:05:45.892+0000] {subprocess.py:93} INFO -     else engine.raw_connection()
[2022-12-17T03:05:45.894+0000] {subprocess.py:93} INFO -   File "/home/***/.local/lib/python3.7/site-packages/sqlalchemy/engine/base.py", line 3276, in raw_connection
[2022-12-17T03:05:45.895+0000] {subprocess.py:93} INFO -     return self._wrap_pool_connect(self.pool.connect, _connection)
[2022-12-17T03:05:45.897+0000] {subprocess.py:93} INFO -   File "/home/***/.local/lib/python3.7/site-packages/sqlalchemy/engine/base.py", line 3247, in _wrap_pool_connect
[2022-12-17T03:05:45.898+0000] {subprocess.py:93} INFO -     e, dialect, self
[2022-12-17T03:05:45.899+0000] {subprocess.py:93} INFO -   File "/home/***/.local/lib/python3.7/site-packages/sqlalchemy/engine/base.py", line 2101, in _handle_dbapi_exception_noconnection
[2022-12-17T03:05:45.899+0000] {subprocess.py:93} INFO -     sqlalchemy_exception, with_traceback=exc_info[2], from_=e
[2022-12-17T03:05:45.900+0000] {subprocess.py:93} INFO -   File "/home/***/.local/lib/python3.7/site-packages/sqlalchemy/util/compat.py", line 207, in raise_
[2022-12-17T03:05:45.901+0000] {subprocess.py:93} INFO -     raise exception
[2022-12-17T03:05:45.903+0000] {subprocess.py:93} INFO -   File "/home/***/.local/lib/python3.7/site-packages/sqlalchemy/engine/base.py", line 3243, in _wrap_pool_connect
[2022-12-17T03:05:45.903+0000] {subprocess.py:93} INFO -     return fn()
[2022-12-17T03:05:45.904+0000] {subprocess.py:93} INFO -   File "/home/***/.local/lib/python3.7/site-packages/sqlalchemy/pool/base.py", line 310, in connect
[2022-12-17T03:05:45.905+0000] {subprocess.py:93} INFO -     return _ConnectionFairy._checkout(self)
[2022-12-17T03:05:45.905+0000] {subprocess.py:93} INFO -   File "/home/***/.local/lib/python3.7/site-packages/sqlalchemy/pool/base.py", line 868, in _checkout
[2022-12-17T03:05:45.907+0000] {subprocess.py:93} INFO -     fairy = _ConnectionRecord.checkout(pool)
[2022-12-17T03:05:45.907+0000] {subprocess.py:93} INFO -   File "/home/***/.local/lib/python3.7/site-packages/sqlalchemy/pool/base.py", line 476, in checkout
[2022-12-17T03:05:45.908+0000] {subprocess.py:93} INFO -     rec = pool._do_get()
[2022-12-17T03:05:45.910+0000] {subprocess.py:93} INFO -   File "/home/***/.local/lib/python3.7/site-packages/sqlalchemy/pool/impl.py", line 146, in _do_get
[2022-12-17T03:05:45.912+0000] {subprocess.py:93} INFO -     self._dec_overflow()
[2022-12-17T03:05:45.913+0000] {subprocess.py:93} INFO -   File "/home/***/.local/lib/python3.7/site-packages/sqlalchemy/util/langhelpers.py", line 72, in __exit__
[2022-12-17T03:05:45.914+0000] {subprocess.py:93} INFO -     with_traceback=exc_tb,
[2022-12-17T03:05:45.915+0000] {subprocess.py:93} INFO -   File "/home/***/.local/lib/python3.7/site-packages/sqlalchemy/util/compat.py", line 207, in raise_
[2022-12-17T03:05:45.916+0000] {subprocess.py:93} INFO -     raise exception
[2022-12-17T03:05:45.921+0000] {subprocess.py:93} INFO -   File "/home/***/.local/lib/python3.7/site-packages/sqlalchemy/pool/impl.py", line 143, in _do_get
[2022-12-17T03:05:45.924+0000] {subprocess.py:93} INFO -     return self._create_connection()
[2022-12-17T03:05:45.925+0000] {subprocess.py:93} INFO -   File "/home/***/.local/lib/python3.7/site-packages/sqlalchemy/pool/base.py", line 256, in _create_connection
[2022-12-17T03:05:45.929+0000] {subprocess.py:93} INFO -     return _ConnectionRecord(self)
[2022-12-17T03:05:45.930+0000] {subprocess.py:93} INFO -   File "/home/***/.local/lib/python3.7/site-packages/sqlalchemy/pool/base.py", line 371, in __init__
[2022-12-17T03:05:45.933+0000] {subprocess.py:93} INFO -     self.__connect()
[2022-12-17T03:05:45.935+0000] {subprocess.py:93} INFO -   File "/home/***/.local/lib/python3.7/site-packages/sqlalchemy/pool/base.py", line 666, in __connect
[2022-12-17T03:05:45.936+0000] {subprocess.py:93} INFO -     pool.logger.debug("Error on connect(): %s", e)
[2022-12-17T03:05:45.939+0000] {subprocess.py:93} INFO -   File "/home/***/.local/lib/python3.7/site-packages/sqlalchemy/util/langhelpers.py", line 72, in __exit__
[2022-12-17T03:05:45.940+0000] {subprocess.py:93} INFO -     with_traceback=exc_tb,
[2022-12-17T03:05:45.944+0000] {subprocess.py:93} INFO -   File "/home/***/.local/lib/python3.7/site-packages/sqlalchemy/util/compat.py", line 207, in raise_
[2022-12-17T03:05:45.950+0000] {subprocess.py:93} INFO -     raise exception
[2022-12-17T03:05:45.951+0000] {subprocess.py:93} INFO -   File "/home/***/.local/lib/python3.7/site-packages/sqlalchemy/pool/base.py", line 661, in __connect
[2022-12-17T03:05:45.953+0000] {subprocess.py:93} INFO -     self.dbapi_connection = connection = pool._invoke_creator(self)
[2022-12-17T03:05:45.955+0000] {subprocess.py:93} INFO -   File "/home/***/.local/lib/python3.7/site-packages/sqlalchemy/engine/create.py", line 590, in connect
[2022-12-17T03:05:45.958+0000] {subprocess.py:93} INFO -     return dialect.connect(*cargs, **cparams)
[2022-12-17T03:05:45.959+0000] {subprocess.py:93} INFO -   File "/home/***/.local/lib/python3.7/site-packages/sqlalchemy/engine/default.py", line 584, in connect
[2022-12-17T03:05:45.960+0000] {subprocess.py:93} INFO -     return self.dbapi.connect(*cargs, **cparams)
[2022-12-17T03:05:45.960+0000] {subprocess.py:93} INFO -   File "/home/***/.local/lib/python3.7/site-packages/psycopg2/__init__.py", line 122, in connect
[2022-12-17T03:05:45.961+0000] {subprocess.py:93} INFO -     conn = _connect(dsn, connection_factory=connection_factory, **kwasync)
[2022-12-17T03:05:45.961+0000] {subprocess.py:93} INFO - 
[2022-12-17T03:05:45.962+0000] {subprocess.py:93} INFO - The above exception was caused by the following exception:
[2022-12-17T03:05:45.962+0000] {subprocess.py:93} INFO - psycopg2.OperationalError: connection to server at "localhost" (127.0.0.1), port 5432 failed: Connection refused
[2022-12-17T03:05:45.963+0000] {subprocess.py:93} INFO - 	Is the server running on that host and accepting TCP/IP connections?
[2022-12-17T03:05:45.963+0000] {subprocess.py:93} INFO - connection to server at "localhost" (::1), port 5432 failed: Cannot assign requested address
[2022-12-17T03:05:45.964+0000] {subprocess.py:93} INFO - 	Is the server running on that host and accepting TCP/IP connections?
[2022-12-17T03:05:45.964+0000] {subprocess.py:93} INFO - 
[2022-12-17T03:05:45.965+0000] {subprocess.py:93} INFO - 
[2022-12-17T03:05:45.966+0000] {subprocess.py:93} INFO - Stack Trace:
[2022-12-17T03:05:45.967+0000] {subprocess.py:93} INFO -   File "/home/***/.local/lib/python3.7/site-packages/sqlalchemy/engine/base.py", line 3243, in _wrap_pool_connect
[2022-12-17T03:05:45.968+0000] {subprocess.py:93} INFO -     return fn()
[2022-12-17T03:05:45.969+0000] {subprocess.py:93} INFO -   File "/home/***/.local/lib/python3.7/site-packages/sqlalchemy/pool/base.py", line 310, in connect
[2022-12-17T03:05:45.969+0000] {subprocess.py:93} INFO -     return _ConnectionFairy._checkout(self)
[2022-12-17T03:05:45.970+0000] {subprocess.py:93} INFO -   File "/home/***/.local/lib/python3.7/site-packages/sqlalchemy/pool/base.py", line 868, in _checkout
[2022-12-17T03:05:45.971+0000] {subprocess.py:93} INFO -     fairy = _ConnectionRecord.checkout(pool)
[2022-12-17T03:05:45.976+0000] {subprocess.py:93} INFO -   File "/home/***/.local/lib/python3.7/site-packages/sqlalchemy/pool/base.py", line 476, in checkout
[2022-12-17T03:05:45.980+0000] {subprocess.py:93} INFO -     rec = pool._do_get()
[2022-12-17T03:05:45.981+0000] {subprocess.py:93} INFO -   File "/home/***/.local/lib/python3.7/site-packages/sqlalchemy/pool/impl.py", line 146, in _do_get
[2022-12-17T03:05:45.982+0000] {subprocess.py:93} INFO -     self._dec_overflow()
[2022-12-17T03:05:45.983+0000] {subprocess.py:93} INFO -   File "/home/***/.local/lib/python3.7/site-packages/sqlalchemy/util/langhelpers.py", line 72, in __exit__
[2022-12-17T03:05:45.984+0000] {subprocess.py:93} INFO -     with_traceback=exc_tb,
[2022-12-17T03:05:45.985+0000] {subprocess.py:93} INFO -   File "/home/***/.local/lib/python3.7/site-packages/sqlalchemy/util/compat.py", line 207, in raise_
[2022-12-17T03:05:45.986+0000] {subprocess.py:93} INFO -     raise exception
[2022-12-17T03:05:45.987+0000] {subprocess.py:93} INFO -   File "/home/***/.local/lib/python3.7/site-packages/sqlalchemy/pool/impl.py", line 143, in _do_get
[2022-12-17T03:05:45.988+0000] {subprocess.py:93} INFO -     return self._create_connection()
[2022-12-17T03:05:45.988+0000] {subprocess.py:93} INFO -   File "/home/***/.local/lib/python3.7/site-packages/sqlalchemy/pool/base.py", line 256, in _create_connection
[2022-12-17T03:05:45.989+0000] {subprocess.py:93} INFO -     return _ConnectionRecord(self)
[2022-12-17T03:05:45.999+0000] {subprocess.py:93} INFO -   File "/home/***/.local/lib/python3.7/site-packages/sqlalchemy/pool/base.py", line 371, in __init__
[2022-12-17T03:05:46.001+0000] {subprocess.py:93} INFO -     self.__connect()
[2022-12-17T03:05:46.001+0000] {subprocess.py:93} INFO -   File "/home/***/.local/lib/python3.7/site-packages/sqlalchemy/pool/base.py", line 666, in __connect
[2022-12-17T03:05:46.002+0000] {subprocess.py:93} INFO -     pool.logger.debug("Error on connect(): %s", e)
[2022-12-17T03:05:46.002+0000] {subprocess.py:93} INFO -   File "/home/***/.local/lib/python3.7/site-packages/sqlalchemy/util/langhelpers.py", line 72, in __exit__
[2022-12-17T03:05:46.003+0000] {subprocess.py:93} INFO -     with_traceback=exc_tb,
[2022-12-17T03:05:46.004+0000] {subprocess.py:93} INFO -   File "/home/***/.local/lib/python3.7/site-packages/sqlalchemy/util/compat.py", line 207, in raise_
[2022-12-17T03:05:46.005+0000] {subprocess.py:93} INFO -     raise exception
[2022-12-17T03:05:46.006+0000] {subprocess.py:93} INFO -   File "/home/***/.local/lib/python3.7/site-packages/sqlalchemy/pool/base.py", line 661, in __connect
[2022-12-17T03:05:46.008+0000] {subprocess.py:93} INFO -     self.dbapi_connection = connection = pool._invoke_creator(self)
[2022-12-17T03:05:46.010+0000] {subprocess.py:93} INFO -   File "/home/***/.local/lib/python3.7/site-packages/sqlalchemy/engine/create.py", line 590, in connect
[2022-12-17T03:05:46.012+0000] {subprocess.py:93} INFO -     return dialect.connect(*cargs, **cparams)
[2022-12-17T03:05:46.013+0000] {subprocess.py:93} INFO -   File "/home/***/.local/lib/python3.7/site-packages/sqlalchemy/engine/default.py", line 584, in connect
[2022-12-17T03:05:46.013+0000] {subprocess.py:93} INFO -     return self.dbapi.connect(*cargs, **cparams)
[2022-12-17T03:05:46.015+0000] {subprocess.py:93} INFO -   File "/home/***/.local/lib/python3.7/site-packages/psycopg2/__init__.py", line 122, in connect
[2022-12-17T03:05:46.016+0000] {subprocess.py:93} INFO -     conn = _connect(dsn, connection_factory=connection_factory, **kwasync)
[2022-12-17T03:05:46.018+0000] {subprocess.py:93} INFO - 
[2022-12-17T03:05:46.021+0000] {subprocess.py:93} INFO - Traceback (most recent call last):
[2022-12-17T03:05:46.022+0000] {subprocess.py:93} INFO -   File "/home/***/.local/lib/python3.7/site-packages/sqlalchemy/engine/base.py", line 3243, in _wrap_pool_connect
[2022-12-17T03:05:46.024+0000] {subprocess.py:93} INFO -     return fn()
[2022-12-17T03:05:46.025+0000] {subprocess.py:93} INFO -   File "/home/***/.local/lib/python3.7/site-packages/sqlalchemy/pool/base.py", line 310, in connect
[2022-12-17T03:05:46.026+0000] {subprocess.py:93} INFO -     return _ConnectionFairy._checkout(self)
[2022-12-17T03:05:46.027+0000] {subprocess.py:93} INFO -   File "/home/***/.local/lib/python3.7/site-packages/sqlalchemy/pool/base.py", line 868, in _checkout
[2022-12-17T03:05:46.028+0000] {subprocess.py:93} INFO -     fairy = _ConnectionRecord.checkout(pool)
[2022-12-17T03:05:46.029+0000] {subprocess.py:93} INFO -   File "/home/***/.local/lib/python3.7/site-packages/sqlalchemy/pool/base.py", line 476, in checkout
[2022-12-17T03:05:46.031+0000] {subprocess.py:93} INFO -     rec = pool._do_get()
[2022-12-17T03:05:46.037+0000] {subprocess.py:93} INFO -   File "/home/***/.local/lib/python3.7/site-packages/sqlalchemy/pool/impl.py", line 146, in _do_get
[2022-12-17T03:05:46.040+0000] {subprocess.py:93} INFO -     self._dec_overflow()
[2022-12-17T03:05:46.041+0000] {subprocess.py:93} INFO -   File "/home/***/.local/lib/python3.7/site-packages/sqlalchemy/util/langhelpers.py", line 72, in __exit__
[2022-12-17T03:05:46.043+0000] {subprocess.py:93} INFO -     with_traceback=exc_tb,
[2022-12-17T03:05:46.044+0000] {subprocess.py:93} INFO -   File "/home/***/.local/lib/python3.7/site-packages/sqlalchemy/util/compat.py", line 207, in raise_
[2022-12-17T03:05:46.045+0000] {subprocess.py:93} INFO -     raise exception
[2022-12-17T03:05:46.046+0000] {subprocess.py:93} INFO -   File "/home/***/.local/lib/python3.7/site-packages/sqlalchemy/pool/impl.py", line 143, in _do_get
[2022-12-17T03:05:46.048+0000] {subprocess.py:93} INFO -     return self._create_connection()
[2022-12-17T03:05:46.049+0000] {subprocess.py:93} INFO -   File "/home/***/.local/lib/python3.7/site-packages/sqlalchemy/pool/base.py", line 256, in _create_connection
[2022-12-17T03:05:46.050+0000] {subprocess.py:93} INFO -     return _ConnectionRecord(self)
[2022-12-17T03:05:46.052+0000] {subprocess.py:93} INFO -   File "/home/***/.local/lib/python3.7/site-packages/sqlalchemy/pool/base.py", line 371, in __init__
[2022-12-17T03:05:46.053+0000] {subprocess.py:93} INFO -     self.__connect()
[2022-12-17T03:05:46.054+0000] {subprocess.py:93} INFO -   File "/home/***/.local/lib/python3.7/site-packages/sqlalchemy/pool/base.py", line 666, in __connect
[2022-12-17T03:05:46.055+0000] {subprocess.py:93} INFO -     pool.logger.debug("Error on connect(): %s", e)
[2022-12-17T03:05:46.056+0000] {subprocess.py:93} INFO -   File "/home/***/.local/lib/python3.7/site-packages/sqlalchemy/util/langhelpers.py", line 72, in __exit__
[2022-12-17T03:05:46.057+0000] {subprocess.py:93} INFO -     with_traceback=exc_tb,
[2022-12-17T03:05:46.058+0000] {subprocess.py:93} INFO -   File "/home/***/.local/lib/python3.7/site-packages/sqlalchemy/util/compat.py", line 207, in raise_
[2022-12-17T03:05:46.059+0000] {subprocess.py:93} INFO -     raise exception
[2022-12-17T03:05:46.060+0000] {subprocess.py:93} INFO -   File "/home/***/.local/lib/python3.7/site-packages/sqlalchemy/pool/base.py", line 661, in __connect
[2022-12-17T03:05:46.061+0000] {subprocess.py:93} INFO -     self.dbapi_connection = connection = pool._invoke_creator(self)
[2022-12-17T03:05:46.065+0000] {subprocess.py:93} INFO -   File "/home/***/.local/lib/python3.7/site-packages/sqlalchemy/engine/create.py", line 590, in connect
[2022-12-17T03:05:46.066+0000] {subprocess.py:93} INFO -     return dialect.connect(*cargs, **cparams)
[2022-12-17T03:05:46.068+0000] {subprocess.py:93} INFO -   File "/home/***/.local/lib/python3.7/site-packages/sqlalchemy/engine/default.py", line 584, in connect
[2022-12-17T03:05:46.069+0000] {subprocess.py:93} INFO -     return self.dbapi.connect(*cargs, **cparams)
[2022-12-17T03:05:46.070+0000] {subprocess.py:93} INFO -   File "/home/***/.local/lib/python3.7/site-packages/psycopg2/__init__.py", line 122, in connect
[2022-12-17T03:05:46.071+0000] {subprocess.py:93} INFO -     conn = _connect(dsn, connection_factory=connection_factory, **kwasync)
[2022-12-17T03:05:46.073+0000] {subprocess.py:93} INFO - psycopg2.OperationalError: connection to server at "localhost" (127.0.0.1), port 5432 failed: Connection refused
[2022-12-17T03:05:46.074+0000] {subprocess.py:93} INFO - 	Is the server running on that host and accepting TCP/IP connections?
[2022-12-17T03:05:46.074+0000] {subprocess.py:93} INFO - connection to server at "localhost" (::1), port 5432 failed: Cannot assign requested address
[2022-12-17T03:05:46.075+0000] {subprocess.py:93} INFO - 	Is the server running on that host and accepting TCP/IP connections?
[2022-12-17T03:05:46.076+0000] {subprocess.py:93} INFO - 
[2022-12-17T03:05:46.076+0000] {subprocess.py:93} INFO - 
[2022-12-17T03:05:46.081+0000] {subprocess.py:93} INFO - The above exception was the direct cause of the following exception:
[2022-12-17T03:05:46.082+0000] {subprocess.py:93} INFO - 
[2022-12-17T03:05:46.083+0000] {subprocess.py:93} INFO - Traceback (most recent call last):
[2022-12-17T03:05:46.084+0000] {subprocess.py:93} INFO -   File "/opt/***/tasks/data_cleansing_basic_stat.py", line 95, in <module>
[2022-12-17T03:05:46.085+0000] {subprocess.py:93} INFO -     result = data_cleansing_whole_job.execute_in_process()
[2022-12-17T03:05:46.085+0000] {subprocess.py:93} INFO -   File "/home/***/.local/lib/python3.7/site-packages/dagster/_core/definitions/job_definition.py", line 395, in execute_in_process
[2022-12-17T03:05:46.086+0000] {subprocess.py:93} INFO -     asset_selection=frozenset(asset_selection),
[2022-12-17T03:05:46.087+0000] {subprocess.py:93} INFO -   File "/home/***/.local/lib/python3.7/site-packages/dagster/_core/execution/execute_in_process.py", line 77, in core_execute_in_process
[2022-12-17T03:05:46.089+0000] {subprocess.py:93} INFO -     event_list = list(execute_run_iterable)
[2022-12-17T03:05:46.090+0000] {subprocess.py:93} INFO -   File "/home/***/.local/lib/python3.7/site-packages/dagster/_core/execution/api.py", line 1189, in __iter__
[2022-12-17T03:05:46.091+0000] {subprocess.py:93} INFO -     pipeline_context=self.pipeline_context,
[2022-12-17T03:05:46.092+0000] {subprocess.py:93} INFO -   File "/home/***/.local/lib/python3.7/site-packages/dagster/_core/execution/api.py", line 1091, in pipeline_execution_iterator
[2022-12-17T03:05:46.093+0000] {subprocess.py:93} INFO -     for event in pipeline_context.executor.execute(pipeline_context, execution_plan):
[2022-12-17T03:05:46.094+0000] {subprocess.py:93} INFO -   File "/home/***/.local/lib/python3.7/site-packages/dagster/_core/executor/in_process.py", line 50, in execute
[2022-12-17T03:05:46.095+0000] {subprocess.py:93} INFO -     output_capture=plan_context.output_capture,
[2022-12-17T03:05:46.096+0000] {subprocess.py:93} INFO -   File "/home/***/.local/lib/python3.7/site-packages/dagster/_core/execution/api.py", line 1189, in __iter__
[2022-12-17T03:05:46.098+0000] {subprocess.py:93} INFO -     pipeline_context=self.pipeline_context,
[2022-12-17T03:05:46.099+0000] {subprocess.py:93} INFO -   File "/home/***/.local/lib/python3.7/site-packages/dagster/_core/execution/plan/execute_plan.py", line 121, in inner_plan_execution_iterator
[2022-12-17T03:05:46.101+0000] {subprocess.py:93} INFO -     dagster_event_sequence_for_step(step_context)
[2022-12-17T03:05:46.101+0000] {subprocess.py:93} INFO -   File "/home/***/.local/lib/python3.7/site-packages/dagster/_core/execution/plan/execute_plan.py", line 325, in dagster_event_sequence_for_step
[2022-12-17T03:05:46.102+0000] {subprocess.py:93} INFO -     raise dagster_user_error.user_exception
[2022-12-17T03:05:46.103+0000] {subprocess.py:93} INFO -   File "/home/***/.local/lib/python3.7/site-packages/dagster/_core/execution/plan/utils.py", line 47, in solid_execution_error_boundary
[2022-12-17T03:05:46.104+0000] {subprocess.py:93} INFO -     yield
[2022-12-17T03:05:46.105+0000] {subprocess.py:93} INFO -   File "/home/***/.local/lib/python3.7/site-packages/dagster/_utils/__init__.py", line 447, in iterate_with_context
[2022-12-17T03:05:46.107+0000] {subprocess.py:93} INFO -     next_output = next(iterator)
[2022-12-17T03:05:46.109+0000] {subprocess.py:93} INFO -   File "/home/***/.local/lib/python3.7/site-packages/dagster/_core/execution/plan/compute_generator.py", line 74, in _coerce_solid_compute_fn_to_iterator
[2022-12-17T03:05:46.110+0000] {subprocess.py:93} INFO -     result = fn(context, **kwargs) if context_arg_provided else fn(**kwargs)
[2022-12-17T03:05:46.110+0000] {subprocess.py:93} INFO -   File "/opt/***/tasks/data_cleansing_basic_stat.py", line 77, in sending_to_pg
[2022-12-17T03:05:46.111+0000] {subprocess.py:93} INFO -     df.to_sql('lol_basic_stat',con=pg_engine,if_exists="append",index=False)
[2022-12-17T03:05:46.112+0000] {subprocess.py:93} INFO -   File "/home/***/.local/lib/python3.7/site-packages/pandas/core/generic.py", line 2882, in to_sql
[2022-12-17T03:05:46.112+0000] {subprocess.py:93} INFO -     method=method,
[2022-12-17T03:05:46.113+0000] {subprocess.py:93} INFO -   File "/home/***/.local/lib/python3.7/site-packages/pandas/io/sql.py", line 728, in to_sql
[2022-12-17T03:05:46.114+0000] {subprocess.py:93} INFO -     **engine_kwargs,
[2022-12-17T03:05:46.115+0000] {subprocess.py:93} INFO -   File "/home/***/.local/lib/python3.7/site-packages/pandas/io/sql.py", line 1758, in to_sql
[2022-12-17T03:05:46.116+0000] {subprocess.py:93} INFO -     dtype=dtype,
[2022-12-17T03:05:46.117+0000] {subprocess.py:93} INFO -   File "/home/***/.local/lib/python3.7/site-packages/pandas/io/sql.py", line 1650, in prep_table
[2022-12-17T03:05:46.118+0000] {subprocess.py:93} INFO -     table.create()
[2022-12-17T03:05:46.119+0000] {subprocess.py:93} INFO -   File "/home/***/.local/lib/python3.7/site-packages/pandas/io/sql.py", line 856, in create
[2022-12-17T03:05:46.120+0000] {subprocess.py:93} INFO -     if self.exists():
[2022-12-17T03:05:46.120+0000] {subprocess.py:93} INFO -   File "/home/***/.local/lib/python3.7/site-packages/pandas/io/sql.py", line 840, in exists
[2022-12-17T03:05:46.121+0000] {subprocess.py:93} INFO -     return self.pd_sql.has_table(self.name, self.schema)
[2022-12-17T03:05:46.122+0000] {subprocess.py:93} INFO -   File "/home/***/.local/lib/python3.7/site-packages/pandas/io/sql.py", line 1783, in has_table
[2022-12-17T03:05:46.123+0000] {subprocess.py:93} INFO -     insp = sa.inspect(self.connectable)
[2022-12-17T03:05:46.123+0000] {subprocess.py:93} INFO -   File "/home/***/.local/lib/python3.7/site-packages/sqlalchemy/inspection.py", line 64, in inspect
[2022-12-17T03:05:46.124+0000] {subprocess.py:93} INFO -     ret = reg(subject)
[2022-12-17T03:05:46.126+0000] {subprocess.py:93} INFO -   File "/home/***/.local/lib/python3.7/site-packages/sqlalchemy/engine/reflection.py", line 182, in _engine_insp
[2022-12-17T03:05:46.127+0000] {subprocess.py:93} INFO -     return Inspector._construct(Inspector._init_engine, bind)
[2022-12-17T03:05:46.130+0000] {subprocess.py:93} INFO -   File "/home/***/.local/lib/python3.7/site-packages/sqlalchemy/engine/reflection.py", line 117, in _construct
[2022-12-17T03:05:46.132+0000] {subprocess.py:93} INFO -     init(self, bind)
[2022-12-17T03:05:46.133+0000] {subprocess.py:93} INFO -   File "/home/***/.local/lib/python3.7/site-packages/sqlalchemy/engine/reflection.py", line 128, in _init_engine
[2022-12-17T03:05:46.134+0000] {subprocess.py:93} INFO -     engine.connect().close()
[2022-12-17T03:05:46.135+0000] {subprocess.py:93} INFO -   File "/home/***/.local/lib/python3.7/site-packages/sqlalchemy/engine/base.py", line 3197, in connect
[2022-12-17T03:05:46.136+0000] {subprocess.py:93} INFO -     return self._connection_cls(self, close_with_result=close_with_result)
[2022-12-17T03:05:46.136+0000] {subprocess.py:93} INFO -   File "/home/***/.local/lib/python3.7/site-packages/sqlalchemy/engine/base.py", line 96, in __init__
[2022-12-17T03:05:46.137+0000] {subprocess.py:93} INFO -     else engine.raw_connection()
[2022-12-17T03:05:46.138+0000] {subprocess.py:93} INFO -   File "/home/***/.local/lib/python3.7/site-packages/sqlalchemy/engine/base.py", line 3276, in raw_connection
[2022-12-17T03:05:46.143+0000] {subprocess.py:93} INFO -     return self._wrap_pool_connect(self.pool.connect, _connection)
[2022-12-17T03:05:46.148+0000] {subprocess.py:93} INFO -   File "/home/***/.local/lib/python3.7/site-packages/sqlalchemy/engine/base.py", line 3247, in _wrap_pool_connect
[2022-12-17T03:05:46.149+0000] {subprocess.py:93} INFO -     e, dialect, self
[2022-12-17T03:05:46.151+0000] {subprocess.py:93} INFO -   File "/home/***/.local/lib/python3.7/site-packages/sqlalchemy/engine/base.py", line 2101, in _handle_dbapi_exception_noconnection
[2022-12-17T03:05:46.153+0000] {subprocess.py:93} INFO -     sqlalchemy_exception, with_traceback=exc_info[2], from_=e
[2022-12-17T03:05:46.154+0000] {subprocess.py:93} INFO -   File "/home/***/.local/lib/python3.7/site-packages/sqlalchemy/util/compat.py", line 207, in raise_
[2022-12-17T03:05:46.161+0000] {subprocess.py:93} INFO -     raise exception
[2022-12-17T03:05:46.162+0000] {subprocess.py:93} INFO -   File "/home/***/.local/lib/python3.7/site-packages/sqlalchemy/engine/base.py", line 3243, in _wrap_pool_connect
[2022-12-17T03:05:46.164+0000] {subprocess.py:93} INFO -     return fn()
[2022-12-17T03:05:46.166+0000] {subprocess.py:93} INFO -   File "/home/***/.local/lib/python3.7/site-packages/sqlalchemy/pool/base.py", line 310, in connect
[2022-12-17T03:05:46.167+0000] {subprocess.py:93} INFO -     return _ConnectionFairy._checkout(self)
[2022-12-17T03:05:46.168+0000] {subprocess.py:93} INFO -   File "/home/***/.local/lib/python3.7/site-packages/sqlalchemy/pool/base.py", line 868, in _checkout
[2022-12-17T03:05:46.169+0000] {subprocess.py:93} INFO -     fairy = _ConnectionRecord.checkout(pool)
[2022-12-17T03:05:46.170+0000] {subprocess.py:93} INFO -   File "/home/***/.local/lib/python3.7/site-packages/sqlalchemy/pool/base.py", line 476, in checkout
[2022-12-17T03:05:46.172+0000] {subprocess.py:93} INFO -     rec = pool._do_get()
[2022-12-17T03:05:46.173+0000] {subprocess.py:93} INFO -   File "/home/***/.local/lib/python3.7/site-packages/sqlalchemy/pool/impl.py", line 146, in _do_get
[2022-12-17T03:05:46.175+0000] {subprocess.py:93} INFO -     self._dec_overflow()
[2022-12-17T03:05:46.178+0000] {subprocess.py:93} INFO -   File "/home/***/.local/lib/python3.7/site-packages/sqlalchemy/util/langhelpers.py", line 72, in __exit__
[2022-12-17T03:05:46.181+0000] {subprocess.py:93} INFO -     with_traceback=exc_tb,
[2022-12-17T03:05:46.182+0000] {subprocess.py:93} INFO -   File "/home/***/.local/lib/python3.7/site-packages/sqlalchemy/util/compat.py", line 207, in raise_
[2022-12-17T03:05:46.185+0000] {subprocess.py:93} INFO -     raise exception
[2022-12-17T03:05:46.187+0000] {subprocess.py:93} INFO -   File "/home/***/.local/lib/python3.7/site-packages/sqlalchemy/pool/impl.py", line 143, in _do_get
[2022-12-17T03:05:46.189+0000] {subprocess.py:93} INFO -     return self._create_connection()
[2022-12-17T03:05:46.191+0000] {subprocess.py:93} INFO -   File "/home/***/.local/lib/python3.7/site-packages/sqlalchemy/pool/base.py", line 256, in _create_connection
[2022-12-17T03:05:46.199+0000] {subprocess.py:93} INFO -     return _ConnectionRecord(self)
[2022-12-17T03:05:46.206+0000] {subprocess.py:93} INFO -   File "/home/***/.local/lib/python3.7/site-packages/sqlalchemy/pool/base.py", line 371, in __init__
[2022-12-17T03:05:46.208+0000] {subprocess.py:93} INFO -     self.__connect()
[2022-12-17T03:05:46.209+0000] {subprocess.py:93} INFO -   File "/home/***/.local/lib/python3.7/site-packages/sqlalchemy/pool/base.py", line 666, in __connect
[2022-12-17T03:05:46.210+0000] {subprocess.py:93} INFO -     pool.logger.debug("Error on connect(): %s", e)
[2022-12-17T03:05:46.211+0000] {subprocess.py:93} INFO -   File "/home/***/.local/lib/python3.7/site-packages/sqlalchemy/util/langhelpers.py", line 72, in __exit__
[2022-12-17T03:05:46.212+0000] {subprocess.py:93} INFO -     with_traceback=exc_tb,
[2022-12-17T03:05:46.213+0000] {subprocess.py:93} INFO -   File "/home/***/.local/lib/python3.7/site-packages/sqlalchemy/util/compat.py", line 207, in raise_
[2022-12-17T03:05:46.215+0000] {subprocess.py:93} INFO -     raise exception
[2022-12-17T03:05:46.218+0000] {subprocess.py:93} INFO -   File "/home/***/.local/lib/python3.7/site-packages/sqlalchemy/pool/base.py", line 661, in __connect
[2022-12-17T03:05:46.219+0000] {subprocess.py:93} INFO -     self.dbapi_connection = connection = pool._invoke_creator(self)
[2022-12-17T03:05:46.220+0000] {subprocess.py:93} INFO -   File "/home/***/.local/lib/python3.7/site-packages/sqlalchemy/engine/create.py", line 590, in connect
[2022-12-17T03:05:46.220+0000] {subprocess.py:93} INFO -     return dialect.connect(*cargs, **cparams)
[2022-12-17T03:05:46.221+0000] {subprocess.py:93} INFO -   File "/home/***/.local/lib/python3.7/site-packages/sqlalchemy/engine/default.py", line 584, in connect
[2022-12-17T03:05:46.222+0000] {subprocess.py:93} INFO -     return self.dbapi.connect(*cargs, **cparams)
[2022-12-17T03:05:46.223+0000] {subprocess.py:93} INFO -   File "/home/***/.local/lib/python3.7/site-packages/psycopg2/__init__.py", line 122, in connect
[2022-12-17T03:05:46.225+0000] {subprocess.py:93} INFO -     conn = _connect(dsn, connection_factory=connection_factory, **kwasync)
[2022-12-17T03:05:46.226+0000] {subprocess.py:93} INFO - sqlalchemy.exc.OperationalError: (psycopg2.OperationalError) connection to server at "localhost" (127.0.0.1), port 5432 failed: Connection refused
[2022-12-17T03:05:46.226+0000] {subprocess.py:93} INFO - 	Is the server running on that host and accepting TCP/IP connections?
[2022-12-17T03:05:46.227+0000] {subprocess.py:93} INFO - connection to server at "localhost" (::1), port 5432 failed: Cannot assign requested address
[2022-12-17T03:05:46.228+0000] {subprocess.py:93} INFO - 	Is the server running on that host and accepting TCP/IP connections?
[2022-12-17T03:05:46.229+0000] {subprocess.py:93} INFO - 
[2022-12-17T03:05:46.230+0000] {subprocess.py:93} INFO - (Background on this error at: https://sqlalche.me/e/14/e3q8)
[2022-12-17T03:05:47.369+0000] {subprocess.py:97} INFO - Command exited with return code 1
[2022-12-17T03:05:47.571+0000] {taskinstance.py:1851} ERROR - Task failed with exception
Traceback (most recent call last):
  File "/home/airflow/.local/lib/python3.7/site-packages/airflow/operators/bash.py", line 197, in execute
    f'Bash command failed. The command returned a non-zero exit code {result.exit_code}.'
airflow.exceptions.AirflowException: Bash command failed. The command returned a non-zero exit code 1.
[2022-12-17T03:05:47.652+0000] {taskinstance.py:1406} INFO - Marking task as FAILED. dag_id=Can_I_change_name_to_this, task_id=task_6, execution_date=20221217T030445, start_date=20221217T030534, end_date=20221217T030547
[2022-12-17T03:05:47.763+0000] {standard_task_runner.py:105} ERROR - Failed to execute job 83 for task task_6 (Bash command failed. The command returned a non-zero exit code 1.; 284)
[2022-12-17T03:05:47.893+0000] {local_task_job.py:159} INFO - Task exited with return code 1
[2022-12-17T03:05:48.166+0000] {taskinstance.py:2623} INFO - 0 downstream tasks scheduled from follow-on schedule check
