[2022-12-17T02:45:54.187+0000] {taskinstance.py:1165} INFO - Dependencies all met for <TaskInstance: Can_I_change_name_to_this.task_7 manual__2022-12-17T02:45:14.728802+00:00 [queued]>
[2022-12-17T02:45:54.198+0000] {taskinstance.py:1165} INFO - Dependencies all met for <TaskInstance: Can_I_change_name_to_this.task_7 manual__2022-12-17T02:45:14.728802+00:00 [queued]>
[2022-12-17T02:45:54.199+0000] {taskinstance.py:1362} INFO - 
--------------------------------------------------------------------------------
[2022-12-17T02:45:54.200+0000] {taskinstance.py:1363} INFO - Starting attempt 1 of 1
[2022-12-17T02:45:54.201+0000] {taskinstance.py:1364} INFO - 
--------------------------------------------------------------------------------
[2022-12-17T02:45:54.215+0000] {taskinstance.py:1383} INFO - Executing <Task(BashOperator): task_7> on 2022-12-17 02:45:14.728802+00:00
[2022-12-17T02:45:54.222+0000] {standard_task_runner.py:55} INFO - Started process 1034 to run task
[2022-12-17T02:45:54.226+0000] {standard_task_runner.py:82} INFO - Running: ['***', 'tasks', 'run', 'Can_I_change_name_to_this', 'task_7', 'manual__2022-12-17T02:45:14.728802+00:00', '--job-id', '72', '--raw', '--subdir', 'DAGS_FOLDER/dags.py', '--cfg-path', '/tmp/tmpd3duhfnm']
[2022-12-17T02:45:54.228+0000] {standard_task_runner.py:83} INFO - Job 72: Subtask task_7
[2022-12-17T02:45:54.360+0000] {task_command.py:376} INFO - Running <TaskInstance: Can_I_change_name_to_this.task_7 manual__2022-12-17T02:45:14.728802+00:00 [running]> on host 418b9a9aa3df
[2022-12-17T02:45:54.454+0000] {taskinstance.py:1592} INFO - Exporting the following env vars:
AIRFLOW_CTX_DAG_OWNER=***
AIRFLOW_CTX_DAG_ID=Can_I_change_name_to_this
AIRFLOW_CTX_TASK_ID=task_7
AIRFLOW_CTX_EXECUTION_DATE=2022-12-17T02:45:14.728802+00:00
AIRFLOW_CTX_TRY_NUMBER=1
AIRFLOW_CTX_DAG_RUN_ID=manual__2022-12-17T02:45:14.728802+00:00
[2022-12-17T02:45:54.459+0000] {subprocess.py:63} INFO - Tmp dir root location: 
 /tmp
[2022-12-17T02:45:54.461+0000] {subprocess.py:75} INFO - Running command: ['/bin/bash', '-c', 'python /opt/***/tasks/data_cleansing_counter_stat.py']
[2022-12-17T02:45:54.480+0000] {subprocess.py:86} INFO - Output:
[2022-12-17T02:45:57.527+0000] {subprocess.py:93} INFO - 2022-12-17 02:45:57 +0000 - dagster - DEBUG - counter_stat_job - 018863e9-ad52-48dc-ae49-525d43ad6a1e - 1035 - RUN_START - Started execution of run for "counter_stat_job".
[2022-12-17T02:45:57.556+0000] {subprocess.py:93} INFO - 2022-12-17 02:45:57 +0000 - dagster - DEBUG - counter_stat_job - 018863e9-ad52-48dc-ae49-525d43ad6a1e - 1035 - ENGINE_EVENT - Executing steps in process (pid: 1035)
[2022-12-17T02:45:57.569+0000] {subprocess.py:93} INFO - 2022-12-17 02:45:57 +0000 - dagster - DEBUG - counter_stat_job - 018863e9-ad52-48dc-ae49-525d43ad6a1e - 1035 - RESOURCE_INIT_STARTED - Starting initialization of resources [io_manager].
[2022-12-17T02:45:57.575+0000] {subprocess.py:93} INFO - 2022-12-17 02:45:57 +0000 - dagster - DEBUG - counter_stat_job - 018863e9-ad52-48dc-ae49-525d43ad6a1e - 1035 - RESOURCE_INIT_SUCCESS - Finished initialization of resources [io_manager].
[2022-12-17T02:45:57.581+0000] {subprocess.py:93} INFO - 2022-12-17 02:45:57 +0000 - dagster - DEBUG - counter_stat_job - 018863e9-ad52-48dc-ae49-525d43ad6a1e - 1035 - LOGS_CAPTURED - Started capturing logs in process (pid: 1035).
[2022-12-17T02:45:57.588+0000] {subprocess.py:93} INFO - 2022-12-17 02:45:57 +0000 - dagster - DEBUG - counter_stat_job - 018863e9-ad52-48dc-ae49-525d43ad6a1e - 1035 - read_json - STEP_START - Started execution of step "read_json".
[2022-12-17T02:45:57.771+0000] {subprocess.py:93} INFO - 2022-12-17 02:45:57 +0000 - dagster - DEBUG - counter_stat_job - 018863e9-ad52-48dc-ae49-525d43ad6a1e - 1035 - read_json - STEP_OUTPUT - Yielded output "result" of type "DataFrame". (Type check passed).
[2022-12-17T02:45:57.772+0000] {subprocess.py:93} INFO - 2022-12-17 02:45:57 +0000 - dagster - DEBUG - counter_stat_job - 018863e9-ad52-48dc-ae49-525d43ad6a1e - 1035 - read_json - HANDLED_OUTPUT - Handled output "result" using IO manager "io_manager"
[2022-12-17T02:45:57.774+0000] {subprocess.py:93} INFO - 2022-12-17 02:45:57 +0000 - dagster - DEBUG - counter_stat_job - 018863e9-ad52-48dc-ae49-525d43ad6a1e - 1035 - read_json - STEP_SUCCESS - Finished execution of step "read_json" in 244ms.
[2022-12-17T02:45:57.775+0000] {subprocess.py:93} INFO - 2022-12-17 02:45:57 +0000 - dagster - DEBUG - counter_stat_job - 018863e9-ad52-48dc-ae49-525d43ad6a1e - 1035 - data_cleansing - STEP_START - Started execution of step "data_cleansing".
[2022-12-17T02:45:57.778+0000] {subprocess.py:93} INFO - 2022-12-17 02:45:57 +0000 - dagster - DEBUG - counter_stat_job - 018863e9-ad52-48dc-ae49-525d43ad6a1e - 1035 - data_cleansing - LOADED_INPUT - Loaded input "df" using input manager "io_manager", from output "result" of step "read_json"
[2022-12-17T02:45:57.779+0000] {subprocess.py:93} INFO - 2022-12-17 02:45:57 +0000 - dagster - DEBUG - counter_stat_job - 018863e9-ad52-48dc-ae49-525d43ad6a1e - 1035 - data_cleansing - STEP_INPUT - Got input "df" of type "DataFrame". (Type check passed).
[2022-12-17T02:45:57.832+0000] {subprocess.py:93} INFO - 2022-12-17 02:45:57 +0000 - dagster - DEBUG - counter_stat_job - 018863e9-ad52-48dc-ae49-525d43ad6a1e - 1035 - data_cleansing - STEP_OUTPUT - Yielded output "result" of type "DataFrame". (Type check passed).
[2022-12-17T02:45:57.833+0000] {subprocess.py:93} INFO - 2022-12-17 02:45:57 +0000 - dagster - DEBUG - counter_stat_job - 018863e9-ad52-48dc-ae49-525d43ad6a1e - 1035 - data_cleansing - HANDLED_OUTPUT - Handled output "result" using IO manager "io_manager"
[2022-12-17T02:45:57.835+0000] {subprocess.py:93} INFO - 2022-12-17 02:45:57 +0000 - dagster - DEBUG - counter_stat_job - 018863e9-ad52-48dc-ae49-525d43ad6a1e - 1035 - data_cleansing - STEP_SUCCESS - Finished execution of step "data_cleansing" in 57ms.
[2022-12-17T02:45:57.836+0000] {subprocess.py:93} INFO - 2022-12-17 02:45:57 +0000 - dagster - DEBUG - counter_stat_job - 018863e9-ad52-48dc-ae49-525d43ad6a1e - 1035 - df_to_file - STEP_START - Started execution of step "df_to_file".
[2022-12-17T02:45:57.841+0000] {subprocess.py:93} INFO - 2022-12-17 02:45:57 +0000 - dagster - DEBUG - counter_stat_job - 018863e9-ad52-48dc-ae49-525d43ad6a1e - 1035 - df_to_file - LOADED_INPUT - Loaded input "df" using input manager "io_manager", from output "result" of step "data_cleansing"
[2022-12-17T02:45:57.850+0000] {subprocess.py:93} INFO - 2022-12-17 02:45:57 +0000 - dagster - DEBUG - counter_stat_job - 018863e9-ad52-48dc-ae49-525d43ad6a1e - 1035 - df_to_file - STEP_INPUT - Got input "df" of type "DataFrame". (Type check passed).
[2022-12-17T02:45:57.916+0000] {subprocess.py:93} INFO - 2022-12-17 02:45:57 +0000 - dagster - ERROR - counter_stat_job - 018863e9-ad52-48dc-ae49-525d43ad6a1e - 1035 - df_to_file - STEP_FAILURE - Execution of step "df_to_file" failed.
[2022-12-17T02:45:57.921+0000] {subprocess.py:93} INFO - 
[2022-12-17T02:45:57.923+0000] {subprocess.py:93} INFO - dagster._core.errors.DagsterExecutionStepExecutionError: Error occurred while executing op "df_to_file"::
[2022-12-17T02:45:57.928+0000] {subprocess.py:93} INFO - 
[2022-12-17T02:45:57.932+0000] {subprocess.py:93} INFO - FileNotFoundError: [Errno 2] No such file or directory: './***/processed_zone/lol_clean_counter_stat.json'
[2022-12-17T02:45:57.937+0000] {subprocess.py:93} INFO - 
[2022-12-17T02:45:57.941+0000] {subprocess.py:93} INFO - Stack Trace:
[2022-12-17T02:45:57.943+0000] {subprocess.py:93} INFO -   File "/home/***/.local/lib/python3.7/site-packages/dagster/_core/execution/plan/utils.py", line 47, in solid_execution_error_boundary
[2022-12-17T02:45:57.945+0000] {subprocess.py:93} INFO -     yield
[2022-12-17T02:45:57.947+0000] {subprocess.py:93} INFO -   File "/home/***/.local/lib/python3.7/site-packages/dagster/_utils/__init__.py", line 447, in iterate_with_context
[2022-12-17T02:45:57.949+0000] {subprocess.py:93} INFO -     next_output = next(iterator)
[2022-12-17T02:45:57.951+0000] {subprocess.py:93} INFO -   File "/home/***/.local/lib/python3.7/site-packages/dagster/_core/execution/plan/compute_generator.py", line 74, in _coerce_solid_compute_fn_to_iterator
[2022-12-17T02:45:57.955+0000] {subprocess.py:93} INFO -     result = fn(context, **kwargs) if context_arg_provided else fn(**kwargs)
[2022-12-17T02:45:57.958+0000] {subprocess.py:93} INFO -   File "/opt/***/tasks/data_cleansing_counter_stat.py", line 64, in df_to_file
[2022-12-17T02:45:57.959+0000] {subprocess.py:93} INFO -     df.to_json("./***/processed_zone/lol_clean_counter_stat.json",orient='records',lines=True)
[2022-12-17T02:45:57.961+0000] {subprocess.py:93} INFO -   File "/home/***/.local/lib/python3.7/site-packages/pandas/core/generic.py", line 2571, in to_json
[2022-12-17T02:45:57.963+0000] {subprocess.py:93} INFO -     storage_options=storage_options,
[2022-12-17T02:45:57.966+0000] {subprocess.py:93} INFO -   File "/home/***/.local/lib/python3.7/site-packages/pandas/io/json/_json.py", line 131, in to_json
[2022-12-17T02:45:57.970+0000] {subprocess.py:93} INFO -     path_or_buf, "w", compression=compression, storage_options=storage_options
[2022-12-17T02:45:57.971+0000] {subprocess.py:93} INFO -   File "/home/***/.local/lib/python3.7/site-packages/pandas/io/common.py", line 707, in get_handle
[2022-12-17T02:45:57.973+0000] {subprocess.py:93} INFO -     newline="",
[2022-12-17T02:45:57.976+0000] {subprocess.py:93} INFO - 
[2022-12-17T02:45:57.977+0000] {subprocess.py:93} INFO - 2022-12-17 02:45:57 +0000 - dagster - ERROR - counter_stat_job - 018863e9-ad52-48dc-ae49-525d43ad6a1e - 1035 - RUN_FAILURE - Execution of run for "counter_stat_job" failed. An exception was thrown during execution.
[2022-12-17T02:45:57.979+0000] {subprocess.py:93} INFO - 
[2022-12-17T02:45:57.981+0000] {subprocess.py:93} INFO - FileNotFoundError: [Errno 2] No such file or directory: './***/processed_zone/lol_clean_counter_stat.json'
[2022-12-17T02:45:57.983+0000] {subprocess.py:93} INFO - 
[2022-12-17T02:45:57.986+0000] {subprocess.py:93} INFO - Stack Trace:
[2022-12-17T02:45:57.989+0000] {subprocess.py:93} INFO -   File "/home/***/.local/lib/python3.7/site-packages/dagster/_core/execution/api.py", line 1091, in pipeline_execution_iterator
[2022-12-17T02:45:57.996+0000] {subprocess.py:93} INFO -     for event in pipeline_context.executor.execute(pipeline_context, execution_plan):
[2022-12-17T02:45:58.000+0000] {subprocess.py:93} INFO -   File "/home/***/.local/lib/python3.7/site-packages/dagster/_core/executor/in_process.py", line 50, in execute
[2022-12-17T02:45:58.007+0000] {subprocess.py:93} INFO -     output_capture=plan_context.output_capture,
[2022-12-17T02:45:58.009+0000] {subprocess.py:93} INFO -   File "/home/***/.local/lib/python3.7/site-packages/dagster/_core/execution/api.py", line 1189, in __iter__
[2022-12-17T02:45:58.014+0000] {subprocess.py:93} INFO -     pipeline_context=self.pipeline_context,
[2022-12-17T02:45:58.018+0000] {subprocess.py:93} INFO -   File "/home/***/.local/lib/python3.7/site-packages/dagster/_core/execution/plan/execute_plan.py", line 121, in inner_plan_execution_iterator
[2022-12-17T02:45:58.021+0000] {subprocess.py:93} INFO -     dagster_event_sequence_for_step(step_context)
[2022-12-17T02:45:58.025+0000] {subprocess.py:93} INFO -   File "/home/***/.local/lib/python3.7/site-packages/dagster/_core/execution/plan/execute_plan.py", line 325, in dagster_event_sequence_for_step
[2022-12-17T02:45:58.029+0000] {subprocess.py:93} INFO -     raise dagster_user_error.user_exception
[2022-12-17T02:45:58.033+0000] {subprocess.py:93} INFO -   File "/home/***/.local/lib/python3.7/site-packages/dagster/_core/execution/plan/utils.py", line 47, in solid_execution_error_boundary
[2022-12-17T02:45:58.035+0000] {subprocess.py:93} INFO -     yield
[2022-12-17T02:45:58.088+0000] {subprocess.py:93} INFO -   File "/home/***/.local/lib/python3.7/site-packages/dagster/_utils/__init__.py", line 447, in iterate_with_context
[2022-12-17T02:45:58.090+0000] {subprocess.py:93} INFO -     next_output = next(iterator)
[2022-12-17T02:45:58.103+0000] {subprocess.py:93} INFO -   File "/home/***/.local/lib/python3.7/site-packages/dagster/_core/execution/plan/compute_generator.py", line 74, in _coerce_solid_compute_fn_to_iterator
[2022-12-17T02:45:58.146+0000] {subprocess.py:93} INFO -     result = fn(context, **kwargs) if context_arg_provided else fn(**kwargs)
[2022-12-17T02:45:58.147+0000] {subprocess.py:93} INFO -   File "/opt/***/tasks/data_cleansing_counter_stat.py", line 64, in df_to_file
[2022-12-17T02:45:58.149+0000] {subprocess.py:93} INFO -     df.to_json("./***/processed_zone/lol_clean_counter_stat.json",orient='records',lines=True)
[2022-12-17T02:45:58.150+0000] {subprocess.py:93} INFO -   File "/home/***/.local/lib/python3.7/site-packages/pandas/core/generic.py", line 2571, in to_json
[2022-12-17T02:45:58.151+0000] {subprocess.py:93} INFO -     storage_options=storage_options,
[2022-12-17T02:45:58.152+0000] {subprocess.py:93} INFO -   File "/home/***/.local/lib/python3.7/site-packages/pandas/io/json/_json.py", line 131, in to_json
[2022-12-17T02:45:58.152+0000] {subprocess.py:93} INFO -     path_or_buf, "w", compression=compression, storage_options=storage_options
[2022-12-17T02:45:58.155+0000] {subprocess.py:93} INFO -   File "/home/***/.local/lib/python3.7/site-packages/pandas/io/common.py", line 707, in get_handle
[2022-12-17T02:45:58.158+0000] {subprocess.py:93} INFO -     newline="",
[2022-12-17T02:45:58.162+0000] {subprocess.py:93} INFO - 
[2022-12-17T02:45:58.165+0000] {subprocess.py:93} INFO - Traceback (most recent call last):
[2022-12-17T02:45:58.172+0000] {subprocess.py:93} INFO -   File "/home/***/.local/lib/python3.7/site-packages/dagster/_core/execution/plan/execute_plan.py", line 251, in dagster_event_sequence_for_step
[2022-12-17T02:45:58.173+0000] {subprocess.py:93} INFO -     for step_event in check.generator(step_events):
[2022-12-17T02:45:58.177+0000] {subprocess.py:93} INFO -   File "/home/***/.local/lib/python3.7/site-packages/dagster/_core/execution/plan/execute_step.py", line 390, in core_dagster_event_sequence_for_step
[2022-12-17T02:45:58.181+0000] {subprocess.py:93} INFO -     _step_output_error_checked_user_event_sequence(step_context, user_event_sequence)
[2022-12-17T02:45:58.187+0000] {subprocess.py:93} INFO -   File "/home/***/.local/lib/python3.7/site-packages/dagster/_core/execution/plan/execute_step.py", line 95, in _step_output_error_checked_user_event_sequence
[2022-12-17T02:45:58.190+0000] {subprocess.py:93} INFO -     for user_event in user_event_sequence:
[2022-12-17T02:45:58.192+0000] {subprocess.py:93} INFO -   File "/home/***/.local/lib/python3.7/site-packages/dagster/_core/execution/plan/compute.py", line 174, in execute_core_compute
[2022-12-17T02:45:58.193+0000] {subprocess.py:93} INFO -     for step_output in _yield_compute_results(step_context, inputs, compute_fn):
[2022-12-17T02:45:58.198+0000] {subprocess.py:93} INFO -   File "/home/***/.local/lib/python3.7/site-packages/dagster/_core/execution/plan/compute.py", line 151, in _yield_compute_results
[2022-12-17T02:45:58.201+0000] {subprocess.py:93} INFO -     user_event_generator,
[2022-12-17T02:45:58.207+0000] {subprocess.py:93} INFO -   File "/home/***/.local/lib/python3.7/site-packages/dagster/_utils/__init__.py", line 449, in iterate_with_context
[2022-12-17T02:45:58.208+0000] {subprocess.py:93} INFO -     return
[2022-12-17T02:45:58.211+0000] {subprocess.py:93} INFO -   File "/usr/local/lib/python3.7/contextlib.py", line 130, in __exit__
[2022-12-17T02:45:58.213+0000] {subprocess.py:93} INFO -     self.gen.throw(type, value, traceback)
[2022-12-17T02:45:58.214+0000] {subprocess.py:93} INFO -   File "/home/***/.local/lib/python3.7/site-packages/dagster/_core/execution/plan/utils.py", line 82, in solid_execution_error_boundary
[2022-12-17T02:45:58.214+0000] {subprocess.py:93} INFO -     ) from e
[2022-12-17T02:45:58.215+0000] {subprocess.py:93} INFO - dagster._core.errors.DagsterExecutionStepExecutionError: Error occurred while executing op "df_to_file":
[2022-12-17T02:45:58.216+0000] {subprocess.py:93} INFO - 
[2022-12-17T02:45:58.217+0000] {subprocess.py:93} INFO - During handling of the above exception, another exception occurred:
[2022-12-17T02:45:58.219+0000] {subprocess.py:93} INFO - 
[2022-12-17T02:45:58.219+0000] {subprocess.py:93} INFO - Traceback (most recent call last):
[2022-12-17T02:45:58.225+0000] {subprocess.py:93} INFO -   File "/opt/***/tasks/data_cleansing_counter_stat.py", line 75, in <module>
[2022-12-17T02:45:58.226+0000] {subprocess.py:93} INFO -     result = counter_stat_job.execute_in_process()
[2022-12-17T02:45:58.226+0000] {subprocess.py:93} INFO -   File "/home/***/.local/lib/python3.7/site-packages/dagster/_core/definitions/job_definition.py", line 395, in execute_in_process
[2022-12-17T02:45:58.227+0000] {subprocess.py:93} INFO -     asset_selection=frozenset(asset_selection),
[2022-12-17T02:45:58.230+0000] {subprocess.py:93} INFO -   File "/home/***/.local/lib/python3.7/site-packages/dagster/_core/execution/execute_in_process.py", line 77, in core_execute_in_process
[2022-12-17T02:45:58.231+0000] {subprocess.py:93} INFO -     event_list = list(execute_run_iterable)
[2022-12-17T02:45:58.235+0000] {subprocess.py:93} INFO -   File "/home/***/.local/lib/python3.7/site-packages/dagster/_core/execution/api.py", line 1189, in __iter__
[2022-12-17T02:45:58.238+0000] {subprocess.py:93} INFO -     pipeline_context=self.pipeline_context,
[2022-12-17T02:45:58.242+0000] {subprocess.py:93} INFO -   File "/home/***/.local/lib/python3.7/site-packages/dagster/_core/execution/api.py", line 1091, in pipeline_execution_iterator
[2022-12-17T02:45:58.269+0000] {subprocess.py:93} INFO -     for event in pipeline_context.executor.execute(pipeline_context, execution_plan):
[2022-12-17T02:45:58.270+0000] {subprocess.py:93} INFO -   File "/home/***/.local/lib/python3.7/site-packages/dagster/_core/executor/in_process.py", line 50, in execute
[2022-12-17T02:45:58.281+0000] {subprocess.py:93} INFO -     output_capture=plan_context.output_capture,
[2022-12-17T02:45:58.289+0000] {subprocess.py:93} INFO -   File "/home/***/.local/lib/python3.7/site-packages/dagster/_core/execution/api.py", line 1189, in __iter__
[2022-12-17T02:45:58.298+0000] {subprocess.py:93} INFO -     pipeline_context=self.pipeline_context,
[2022-12-17T02:45:58.304+0000] {subprocess.py:93} INFO -   File "/home/***/.local/lib/python3.7/site-packages/dagster/_core/execution/plan/execute_plan.py", line 121, in inner_plan_execution_iterator
[2022-12-17T02:45:58.312+0000] {subprocess.py:93} INFO -     dagster_event_sequence_for_step(step_context)
[2022-12-17T02:45:58.314+0000] {subprocess.py:93} INFO -   File "/home/***/.local/lib/python3.7/site-packages/dagster/_core/execution/plan/execute_plan.py", line 325, in dagster_event_sequence_for_step
[2022-12-17T02:45:58.316+0000] {subprocess.py:93} INFO -     raise dagster_user_error.user_exception
[2022-12-17T02:45:58.320+0000] {subprocess.py:93} INFO -   File "/home/***/.local/lib/python3.7/site-packages/dagster/_core/execution/plan/utils.py", line 47, in solid_execution_error_boundary
[2022-12-17T02:45:58.322+0000] {subprocess.py:93} INFO -     yield
[2022-12-17T02:45:58.325+0000] {subprocess.py:93} INFO -   File "/home/***/.local/lib/python3.7/site-packages/dagster/_utils/__init__.py", line 447, in iterate_with_context
[2022-12-17T02:45:58.326+0000] {subprocess.py:93} INFO -     next_output = next(iterator)
[2022-12-17T02:45:58.327+0000] {subprocess.py:93} INFO -   File "/home/***/.local/lib/python3.7/site-packages/dagster/_core/execution/plan/compute_generator.py", line 74, in _coerce_solid_compute_fn_to_iterator
[2022-12-17T02:45:58.330+0000] {subprocess.py:93} INFO -     result = fn(context, **kwargs) if context_arg_provided else fn(**kwargs)
[2022-12-17T02:45:58.332+0000] {subprocess.py:93} INFO -   File "/opt/***/tasks/data_cleansing_counter_stat.py", line 64, in df_to_file
[2022-12-17T02:45:58.333+0000] {subprocess.py:93} INFO -     df.to_json("./***/processed_zone/lol_clean_counter_stat.json",orient='records',lines=True)
[2022-12-17T02:45:58.334+0000] {subprocess.py:93} INFO -   File "/home/***/.local/lib/python3.7/site-packages/pandas/core/generic.py", line 2571, in to_json
[2022-12-17T02:45:58.341+0000] {subprocess.py:93} INFO -     storage_options=storage_options,
[2022-12-17T02:45:58.342+0000] {subprocess.py:93} INFO -   File "/home/***/.local/lib/python3.7/site-packages/pandas/io/json/_json.py", line 131, in to_json
[2022-12-17T02:45:58.348+0000] {subprocess.py:93} INFO -     path_or_buf, "w", compression=compression, storage_options=storage_options
[2022-12-17T02:45:58.353+0000] {subprocess.py:93} INFO -   File "/home/***/.local/lib/python3.7/site-packages/pandas/io/common.py", line 707, in get_handle
[2022-12-17T02:45:58.359+0000] {subprocess.py:93} INFO -     newline="",
[2022-12-17T02:45:58.366+0000] {subprocess.py:93} INFO - FileNotFoundError: [Errno 2] No such file or directory: './***/processed_zone/lol_clean_counter_stat.json'
[2022-12-17T02:45:58.650+0000] {subprocess.py:97} INFO - Command exited with return code 1
[2022-12-17T02:45:58.754+0000] {taskinstance.py:1851} ERROR - Task failed with exception
Traceback (most recent call last):
  File "/home/airflow/.local/lib/python3.7/site-packages/airflow/operators/bash.py", line 197, in execute
    f'Bash command failed. The command returned a non-zero exit code {result.exit_code}.'
airflow.exceptions.AirflowException: Bash command failed. The command returned a non-zero exit code 1.
[2022-12-17T02:45:58.786+0000] {taskinstance.py:1406} INFO - Marking task as FAILED. dag_id=Can_I_change_name_to_this, task_id=task_7, execution_date=20221217T024514, start_date=20221217T024554, end_date=20221217T024558
[2022-12-17T02:45:58.861+0000] {standard_task_runner.py:105} ERROR - Failed to execute job 72 for task task_7 (Bash command failed. The command returned a non-zero exit code 1.; 1034)
[2022-12-17T02:45:58.947+0000] {local_task_job.py:159} INFO - Task exited with return code 1
[2022-12-17T02:45:59.026+0000] {taskinstance.py:2623} INFO - 0 downstream tasks scheduled from follow-on schedule check
