[2022-12-17T02:51:16.094+0000] {taskinstance.py:1165} INFO - Dependencies all met for <TaskInstance: Can_I_change_name_to_this.task_7 manual__2022-12-17T02:50:41.373960+00:00 [queued]>
[2022-12-17T02:51:16.115+0000] {taskinstance.py:1165} INFO - Dependencies all met for <TaskInstance: Can_I_change_name_to_this.task_7 manual__2022-12-17T02:50:41.373960+00:00 [queued]>
[2022-12-17T02:51:16.116+0000] {taskinstance.py:1362} INFO - 
--------------------------------------------------------------------------------
[2022-12-17T02:51:16.117+0000] {taskinstance.py:1363} INFO - Starting attempt 1 of 1
[2022-12-17T02:51:16.118+0000] {taskinstance.py:1364} INFO - 
--------------------------------------------------------------------------------
[2022-12-17T02:51:16.137+0000] {taskinstance.py:1383} INFO - Executing <Task(BashOperator): task_7> on 2022-12-17 02:50:41.373960+00:00
[2022-12-17T02:51:16.152+0000] {standard_task_runner.py:55} INFO - Started process 1327 to run task
[2022-12-17T02:51:16.185+0000] {standard_task_runner.py:82} INFO - Running: ['***', 'tasks', 'run', 'Can_I_change_name_to_this', 'task_7', 'manual__2022-12-17T02:50:41.373960+00:00', '--job-id', '78', '--raw', '--subdir', 'DAGS_FOLDER/dags.py', '--cfg-path', '/tmp/tmpu0_u2po0']
[2022-12-17T02:51:16.189+0000] {standard_task_runner.py:83} INFO - Job 78: Subtask task_7
[2022-12-17T02:51:16.425+0000] {task_command.py:376} INFO - Running <TaskInstance: Can_I_change_name_to_this.task_7 manual__2022-12-17T02:50:41.373960+00:00 [running]> on host 418b9a9aa3df
[2022-12-17T02:51:16.537+0000] {taskinstance.py:1592} INFO - Exporting the following env vars:
AIRFLOW_CTX_DAG_OWNER=***
AIRFLOW_CTX_DAG_ID=Can_I_change_name_to_this
AIRFLOW_CTX_TASK_ID=task_7
AIRFLOW_CTX_EXECUTION_DATE=2022-12-17T02:50:41.373960+00:00
AIRFLOW_CTX_TRY_NUMBER=1
AIRFLOW_CTX_DAG_RUN_ID=manual__2022-12-17T02:50:41.373960+00:00
[2022-12-17T02:51:16.545+0000] {subprocess.py:63} INFO - Tmp dir root location: 
 /tmp
[2022-12-17T02:51:16.547+0000] {subprocess.py:75} INFO - Running command: ['/bin/bash', '-c', 'python /opt/***/tasks/data_cleansing_counter_stat.py']
[2022-12-17T02:51:16.567+0000] {subprocess.py:86} INFO - Output:
[2022-12-17T02:51:20.748+0000] {subprocess.py:93} INFO - 2022-12-17 02:51:20 +0000 - dagster - DEBUG - counter_stat_job - 29de8896-91d9-4dfa-8624-5e0f0363f9b4 - 1328 - RUN_START - Started execution of run for "counter_stat_job".
[2022-12-17T02:51:20.806+0000] {subprocess.py:93} INFO - 2022-12-17 02:51:20 +0000 - dagster - DEBUG - counter_stat_job - 29de8896-91d9-4dfa-8624-5e0f0363f9b4 - 1328 - ENGINE_EVENT - Executing steps in process (pid: 1328)
[2022-12-17T02:51:20.810+0000] {subprocess.py:93} INFO - 2022-12-17 02:51:20 +0000 - dagster - DEBUG - counter_stat_job - 29de8896-91d9-4dfa-8624-5e0f0363f9b4 - 1328 - RESOURCE_INIT_STARTED - Starting initialization of resources [io_manager].
[2022-12-17T02:51:20.812+0000] {subprocess.py:93} INFO - 2022-12-17 02:51:20 +0000 - dagster - DEBUG - counter_stat_job - 29de8896-91d9-4dfa-8624-5e0f0363f9b4 - 1328 - RESOURCE_INIT_SUCCESS - Finished initialization of resources [io_manager].
[2022-12-17T02:51:20.814+0000] {subprocess.py:93} INFO - 2022-12-17 02:51:20 +0000 - dagster - DEBUG - counter_stat_job - 29de8896-91d9-4dfa-8624-5e0f0363f9b4 - 1328 - LOGS_CAPTURED - Started capturing logs in process (pid: 1328).
[2022-12-17T02:51:20.815+0000] {subprocess.py:93} INFO - 2022-12-17 02:51:20 +0000 - dagster - DEBUG - counter_stat_job - 29de8896-91d9-4dfa-8624-5e0f0363f9b4 - 1328 - read_json - STEP_START - Started execution of step "read_json".
[2022-12-17T02:51:21.193+0000] {subprocess.py:93} INFO - 2022-12-17 02:51:21 +0000 - dagster - DEBUG - counter_stat_job - 29de8896-91d9-4dfa-8624-5e0f0363f9b4 - 1328 - read_json - STEP_OUTPUT - Yielded output "result" of type "DataFrame". (Type check passed).
[2022-12-17T02:51:21.198+0000] {subprocess.py:93} INFO - 2022-12-17 02:51:21 +0000 - dagster - DEBUG - counter_stat_job - 29de8896-91d9-4dfa-8624-5e0f0363f9b4 - 1328 - read_json - HANDLED_OUTPUT - Handled output "result" using IO manager "io_manager"
[2022-12-17T02:51:21.200+0000] {subprocess.py:93} INFO - 2022-12-17 02:51:21 +0000 - dagster - DEBUG - counter_stat_job - 29de8896-91d9-4dfa-8624-5e0f0363f9b4 - 1328 - read_json - STEP_SUCCESS - Finished execution of step "read_json" in 410ms.
[2022-12-17T02:51:21.203+0000] {subprocess.py:93} INFO - 2022-12-17 02:51:21 +0000 - dagster - DEBUG - counter_stat_job - 29de8896-91d9-4dfa-8624-5e0f0363f9b4 - 1328 - data_cleansing - STEP_START - Started execution of step "data_cleansing".
[2022-12-17T02:51:21.205+0000] {subprocess.py:93} INFO - 2022-12-17 02:51:21 +0000 - dagster - DEBUG - counter_stat_job - 29de8896-91d9-4dfa-8624-5e0f0363f9b4 - 1328 - data_cleansing - LOADED_INPUT - Loaded input "df" using input manager "io_manager", from output "result" of step "read_json"
[2022-12-17T02:51:21.208+0000] {subprocess.py:93} INFO - 2022-12-17 02:51:21 +0000 - dagster - DEBUG - counter_stat_job - 29de8896-91d9-4dfa-8624-5e0f0363f9b4 - 1328 - data_cleansing - STEP_INPUT - Got input "df" of type "DataFrame". (Type check passed).
[2022-12-17T02:51:21.262+0000] {subprocess.py:93} INFO - 2022-12-17 02:51:21 +0000 - dagster - DEBUG - counter_stat_job - 29de8896-91d9-4dfa-8624-5e0f0363f9b4 - 1328 - data_cleansing - STEP_OUTPUT - Yielded output "result" of type "DataFrame". (Type check passed).
[2022-12-17T02:51:21.264+0000] {subprocess.py:93} INFO - 2022-12-17 02:51:21 +0000 - dagster - DEBUG - counter_stat_job - 29de8896-91d9-4dfa-8624-5e0f0363f9b4 - 1328 - data_cleansing - HANDLED_OUTPUT - Handled output "result" using IO manager "io_manager"
[2022-12-17T02:51:21.266+0000] {subprocess.py:93} INFO - 2022-12-17 02:51:21 +0000 - dagster - DEBUG - counter_stat_job - 29de8896-91d9-4dfa-8624-5e0f0363f9b4 - 1328 - data_cleansing - STEP_SUCCESS - Finished execution of step "data_cleansing" in 64ms.
[2022-12-17T02:51:21.269+0000] {subprocess.py:93} INFO - 2022-12-17 02:51:21 +0000 - dagster - DEBUG - counter_stat_job - 29de8896-91d9-4dfa-8624-5e0f0363f9b4 - 1328 - df_to_file - STEP_START - Started execution of step "df_to_file".
[2022-12-17T02:51:21.274+0000] {subprocess.py:93} INFO - 2022-12-17 02:51:21 +0000 - dagster - DEBUG - counter_stat_job - 29de8896-91d9-4dfa-8624-5e0f0363f9b4 - 1328 - df_to_file - LOADED_INPUT - Loaded input "df" using input manager "io_manager", from output "result" of step "data_cleansing"
[2022-12-17T02:51:21.277+0000] {subprocess.py:93} INFO - 2022-12-17 02:51:21 +0000 - dagster - DEBUG - counter_stat_job - 29de8896-91d9-4dfa-8624-5e0f0363f9b4 - 1328 - df_to_file - STEP_INPUT - Got input "df" of type "DataFrame". (Type check passed).
[2022-12-17T02:51:21.302+0000] {subprocess.py:93} INFO - 2022-12-17 02:51:21 +0000 - dagster - ERROR - counter_stat_job - 29de8896-91d9-4dfa-8624-5e0f0363f9b4 - 1328 - df_to_file - STEP_FAILURE - Execution of step "df_to_file" failed.
[2022-12-17T02:51:21.304+0000] {subprocess.py:93} INFO - 
[2022-12-17T02:51:21.309+0000] {subprocess.py:93} INFO - dagster._core.errors.DagsterExecutionStepExecutionError: Error occurred while executing op "df_to_file"::
[2022-12-17T02:51:21.311+0000] {subprocess.py:93} INFO - 
[2022-12-17T02:51:21.314+0000] {subprocess.py:93} INFO - FileNotFoundError: [Errno 2] No such file or directory: '/opt/***/processed_zone/lol_clean_counter_stat.json'
[2022-12-17T02:51:21.317+0000] {subprocess.py:93} INFO - 
[2022-12-17T02:51:21.318+0000] {subprocess.py:93} INFO - Stack Trace:
[2022-12-17T02:51:21.320+0000] {subprocess.py:93} INFO -   File "/home/***/.local/lib/python3.7/site-packages/dagster/_core/execution/plan/utils.py", line 47, in solid_execution_error_boundary
[2022-12-17T02:51:21.322+0000] {subprocess.py:93} INFO -     yield
[2022-12-17T02:51:21.323+0000] {subprocess.py:93} INFO -   File "/home/***/.local/lib/python3.7/site-packages/dagster/_utils/__init__.py", line 447, in iterate_with_context
[2022-12-17T02:51:21.326+0000] {subprocess.py:93} INFO -     next_output = next(iterator)
[2022-12-17T02:51:21.329+0000] {subprocess.py:93} INFO -   File "/home/***/.local/lib/python3.7/site-packages/dagster/_core/execution/plan/compute_generator.py", line 74, in _coerce_solid_compute_fn_to_iterator
[2022-12-17T02:51:21.334+0000] {subprocess.py:93} INFO -     result = fn(context, **kwargs) if context_arg_provided else fn(**kwargs)
[2022-12-17T02:51:21.343+0000] {subprocess.py:93} INFO -   File "/opt/***/tasks/data_cleansing_counter_stat.py", line 64, in df_to_file
[2022-12-17T02:51:21.349+0000] {subprocess.py:93} INFO -     df.to_json("/opt/***/processed_zone/lol_clean_counter_stat.json",orient='records',lines=True)
[2022-12-17T02:51:21.354+0000] {subprocess.py:93} INFO -   File "/home/***/.local/lib/python3.7/site-packages/pandas/core/generic.py", line 2571, in to_json
[2022-12-17T02:51:21.356+0000] {subprocess.py:93} INFO -     storage_options=storage_options,
[2022-12-17T02:51:21.358+0000] {subprocess.py:93} INFO -   File "/home/***/.local/lib/python3.7/site-packages/pandas/io/json/_json.py", line 131, in to_json
[2022-12-17T02:51:21.360+0000] {subprocess.py:93} INFO -     path_or_buf, "w", compression=compression, storage_options=storage_options
[2022-12-17T02:51:21.365+0000] {subprocess.py:93} INFO -   File "/home/***/.local/lib/python3.7/site-packages/pandas/io/common.py", line 707, in get_handle
[2022-12-17T02:51:21.367+0000] {subprocess.py:93} INFO -     newline="",
[2022-12-17T02:51:21.369+0000] {subprocess.py:93} INFO - 
[2022-12-17T02:51:21.371+0000] {subprocess.py:93} INFO - 2022-12-17 02:51:21 +0000 - dagster - ERROR - counter_stat_job - 29de8896-91d9-4dfa-8624-5e0f0363f9b4 - 1328 - RUN_FAILURE - Execution of run for "counter_stat_job" failed. An exception was thrown during execution.
[2022-12-17T02:51:21.372+0000] {subprocess.py:93} INFO - 
[2022-12-17T02:51:21.375+0000] {subprocess.py:93} INFO - FileNotFoundError: [Errno 2] No such file or directory: '/opt/***/processed_zone/lol_clean_counter_stat.json'
[2022-12-17T02:51:21.378+0000] {subprocess.py:93} INFO - 
[2022-12-17T02:51:21.380+0000] {subprocess.py:93} INFO - Stack Trace:
[2022-12-17T02:51:21.382+0000] {subprocess.py:93} INFO -   File "/home/***/.local/lib/python3.7/site-packages/dagster/_core/execution/api.py", line 1091, in pipeline_execution_iterator
[2022-12-17T02:51:21.384+0000] {subprocess.py:93} INFO -     for event in pipeline_context.executor.execute(pipeline_context, execution_plan):
[2022-12-17T02:51:21.386+0000] {subprocess.py:93} INFO -   File "/home/***/.local/lib/python3.7/site-packages/dagster/_core/executor/in_process.py", line 50, in execute
[2022-12-17T02:51:21.388+0000] {subprocess.py:93} INFO -     output_capture=plan_context.output_capture,
[2022-12-17T02:51:21.391+0000] {subprocess.py:93} INFO -   File "/home/***/.local/lib/python3.7/site-packages/dagster/_core/execution/api.py", line 1189, in __iter__
[2022-12-17T02:51:21.396+0000] {subprocess.py:93} INFO -     pipeline_context=self.pipeline_context,
[2022-12-17T02:51:21.400+0000] {subprocess.py:93} INFO -   File "/home/***/.local/lib/python3.7/site-packages/dagster/_core/execution/plan/execute_plan.py", line 121, in inner_plan_execution_iterator
[2022-12-17T02:51:21.403+0000] {subprocess.py:93} INFO -     dagster_event_sequence_for_step(step_context)
[2022-12-17T02:51:21.406+0000] {subprocess.py:93} INFO -   File "/home/***/.local/lib/python3.7/site-packages/dagster/_core/execution/plan/execute_plan.py", line 325, in dagster_event_sequence_for_step
[2022-12-17T02:51:21.407+0000] {subprocess.py:93} INFO -     raise dagster_user_error.user_exception
[2022-12-17T02:51:21.409+0000] {subprocess.py:93} INFO -   File "/home/***/.local/lib/python3.7/site-packages/dagster/_core/execution/plan/utils.py", line 47, in solid_execution_error_boundary
[2022-12-17T02:51:21.411+0000] {subprocess.py:93} INFO -     yield
[2022-12-17T02:51:21.413+0000] {subprocess.py:93} INFO -   File "/home/***/.local/lib/python3.7/site-packages/dagster/_utils/__init__.py", line 447, in iterate_with_context
[2022-12-17T02:51:21.414+0000] {subprocess.py:93} INFO -     next_output = next(iterator)
[2022-12-17T02:51:21.416+0000] {subprocess.py:93} INFO -   File "/home/***/.local/lib/python3.7/site-packages/dagster/_core/execution/plan/compute_generator.py", line 74, in _coerce_solid_compute_fn_to_iterator
[2022-12-17T02:51:21.418+0000] {subprocess.py:93} INFO -     result = fn(context, **kwargs) if context_arg_provided else fn(**kwargs)
[2022-12-17T02:51:21.419+0000] {subprocess.py:93} INFO -   File "/opt/***/tasks/data_cleansing_counter_stat.py", line 64, in df_to_file
[2022-12-17T02:51:21.421+0000] {subprocess.py:93} INFO -     df.to_json("/opt/***/processed_zone/lol_clean_counter_stat.json",orient='records',lines=True)
[2022-12-17T02:51:21.424+0000] {subprocess.py:93} INFO -   File "/home/***/.local/lib/python3.7/site-packages/pandas/core/generic.py", line 2571, in to_json
[2022-12-17T02:51:21.426+0000] {subprocess.py:93} INFO -     storage_options=storage_options,
[2022-12-17T02:51:21.427+0000] {subprocess.py:93} INFO -   File "/home/***/.local/lib/python3.7/site-packages/pandas/io/json/_json.py", line 131, in to_json
[2022-12-17T02:51:21.428+0000] {subprocess.py:93} INFO -     path_or_buf, "w", compression=compression, storage_options=storage_options
[2022-12-17T02:51:21.433+0000] {subprocess.py:93} INFO -   File "/home/***/.local/lib/python3.7/site-packages/pandas/io/common.py", line 707, in get_handle
[2022-12-17T02:51:21.435+0000] {subprocess.py:93} INFO -     newline="",
[2022-12-17T02:51:21.437+0000] {subprocess.py:93} INFO - 
[2022-12-17T02:51:21.438+0000] {subprocess.py:93} INFO - Traceback (most recent call last):
[2022-12-17T02:51:21.440+0000] {subprocess.py:93} INFO -   File "/home/***/.local/lib/python3.7/site-packages/dagster/_core/execution/plan/execute_plan.py", line 251, in dagster_event_sequence_for_step
[2022-12-17T02:51:21.443+0000] {subprocess.py:93} INFO -     for step_event in check.generator(step_events):
[2022-12-17T02:51:21.444+0000] {subprocess.py:93} INFO -   File "/home/***/.local/lib/python3.7/site-packages/dagster/_core/execution/plan/execute_step.py", line 390, in core_dagster_event_sequence_for_step
[2022-12-17T02:51:21.445+0000] {subprocess.py:93} INFO -     _step_output_error_checked_user_event_sequence(step_context, user_event_sequence)
[2022-12-17T02:51:21.446+0000] {subprocess.py:93} INFO -   File "/home/***/.local/lib/python3.7/site-packages/dagster/_core/execution/plan/execute_step.py", line 95, in _step_output_error_checked_user_event_sequence
[2022-12-17T02:51:21.448+0000] {subprocess.py:93} INFO -     for user_event in user_event_sequence:
[2022-12-17T02:51:21.449+0000] {subprocess.py:93} INFO -   File "/home/***/.local/lib/python3.7/site-packages/dagster/_core/execution/plan/compute.py", line 174, in execute_core_compute
[2022-12-17T02:51:21.451+0000] {subprocess.py:93} INFO -     for step_output in _yield_compute_results(step_context, inputs, compute_fn):
[2022-12-17T02:51:21.452+0000] {subprocess.py:93} INFO -   File "/home/***/.local/lib/python3.7/site-packages/dagster/_core/execution/plan/compute.py", line 151, in _yield_compute_results
[2022-12-17T02:51:21.453+0000] {subprocess.py:93} INFO -     user_event_generator,
[2022-12-17T02:51:21.454+0000] {subprocess.py:93} INFO -   File "/home/***/.local/lib/python3.7/site-packages/dagster/_utils/__init__.py", line 449, in iterate_with_context
[2022-12-17T02:51:21.456+0000] {subprocess.py:93} INFO -     return
[2022-12-17T02:51:21.458+0000] {subprocess.py:93} INFO -   File "/usr/local/lib/python3.7/contextlib.py", line 130, in __exit__
[2022-12-17T02:51:21.460+0000] {subprocess.py:93} INFO -     self.gen.throw(type, value, traceback)
[2022-12-17T02:51:21.463+0000] {subprocess.py:93} INFO -   File "/home/***/.local/lib/python3.7/site-packages/dagster/_core/execution/plan/utils.py", line 82, in solid_execution_error_boundary
[2022-12-17T02:51:21.464+0000] {subprocess.py:93} INFO -     ) from e
[2022-12-17T02:51:21.466+0000] {subprocess.py:93} INFO - dagster._core.errors.DagsterExecutionStepExecutionError: Error occurred while executing op "df_to_file":
[2022-12-17T02:51:21.467+0000] {subprocess.py:93} INFO - 
[2022-12-17T02:51:21.468+0000] {subprocess.py:93} INFO - During handling of the above exception, another exception occurred:
[2022-12-17T02:51:21.471+0000] {subprocess.py:93} INFO - 
[2022-12-17T02:51:21.472+0000] {subprocess.py:93} INFO - Traceback (most recent call last):
[2022-12-17T02:51:21.477+0000] {subprocess.py:93} INFO -   File "/opt/***/tasks/data_cleansing_counter_stat.py", line 75, in <module>
[2022-12-17T02:51:21.479+0000] {subprocess.py:93} INFO -     result = counter_stat_job.execute_in_process()
[2022-12-17T02:51:21.483+0000] {subprocess.py:93} INFO -   File "/home/***/.local/lib/python3.7/site-packages/dagster/_core/definitions/job_definition.py", line 395, in execute_in_process
[2022-12-17T02:51:21.485+0000] {subprocess.py:93} INFO -     asset_selection=frozenset(asset_selection),
[2022-12-17T02:51:21.486+0000] {subprocess.py:93} INFO -   File "/home/***/.local/lib/python3.7/site-packages/dagster/_core/execution/execute_in_process.py", line 77, in core_execute_in_process
[2022-12-17T02:51:21.489+0000] {subprocess.py:93} INFO -     event_list = list(execute_run_iterable)
[2022-12-17T02:51:21.491+0000] {subprocess.py:93} INFO -   File "/home/***/.local/lib/python3.7/site-packages/dagster/_core/execution/api.py", line 1189, in __iter__
[2022-12-17T02:51:21.494+0000] {subprocess.py:93} INFO -     pipeline_context=self.pipeline_context,
[2022-12-17T02:51:21.496+0000] {subprocess.py:93} INFO -   File "/home/***/.local/lib/python3.7/site-packages/dagster/_core/execution/api.py", line 1091, in pipeline_execution_iterator
[2022-12-17T02:51:21.499+0000] {subprocess.py:93} INFO -     for event in pipeline_context.executor.execute(pipeline_context, execution_plan):
[2022-12-17T02:51:21.500+0000] {subprocess.py:93} INFO -   File "/home/***/.local/lib/python3.7/site-packages/dagster/_core/executor/in_process.py", line 50, in execute
[2022-12-17T02:51:21.504+0000] {subprocess.py:93} INFO -     output_capture=plan_context.output_capture,
[2022-12-17T02:51:21.506+0000] {subprocess.py:93} INFO -   File "/home/***/.local/lib/python3.7/site-packages/dagster/_core/execution/api.py", line 1189, in __iter__
[2022-12-17T02:51:21.510+0000] {subprocess.py:93} INFO -     pipeline_context=self.pipeline_context,
[2022-12-17T02:51:21.513+0000] {subprocess.py:93} INFO -   File "/home/***/.local/lib/python3.7/site-packages/dagster/_core/execution/plan/execute_plan.py", line 121, in inner_plan_execution_iterator
[2022-12-17T02:51:21.517+0000] {subprocess.py:93} INFO -     dagster_event_sequence_for_step(step_context)
[2022-12-17T02:51:21.519+0000] {subprocess.py:93} INFO -   File "/home/***/.local/lib/python3.7/site-packages/dagster/_core/execution/plan/execute_plan.py", line 325, in dagster_event_sequence_for_step
[2022-12-17T02:51:21.521+0000] {subprocess.py:93} INFO -     raise dagster_user_error.user_exception
[2022-12-17T02:51:21.524+0000] {subprocess.py:93} INFO -   File "/home/***/.local/lib/python3.7/site-packages/dagster/_core/execution/plan/utils.py", line 47, in solid_execution_error_boundary
[2022-12-17T02:51:21.528+0000] {subprocess.py:93} INFO -     yield
[2022-12-17T02:51:21.530+0000] {subprocess.py:93} INFO -   File "/home/***/.local/lib/python3.7/site-packages/dagster/_utils/__init__.py", line 447, in iterate_with_context
[2022-12-17T02:51:21.534+0000] {subprocess.py:93} INFO -     next_output = next(iterator)
[2022-12-17T02:51:21.537+0000] {subprocess.py:93} INFO -   File "/home/***/.local/lib/python3.7/site-packages/dagster/_core/execution/plan/compute_generator.py", line 74, in _coerce_solid_compute_fn_to_iterator
[2022-12-17T02:51:21.542+0000] {subprocess.py:93} INFO -     result = fn(context, **kwargs) if context_arg_provided else fn(**kwargs)
[2022-12-17T02:51:21.547+0000] {subprocess.py:93} INFO -   File "/opt/***/tasks/data_cleansing_counter_stat.py", line 64, in df_to_file
[2022-12-17T02:51:21.549+0000] {subprocess.py:93} INFO -     df.to_json("/opt/***/processed_zone/lol_clean_counter_stat.json",orient='records',lines=True)
[2022-12-17T02:51:21.553+0000] {subprocess.py:93} INFO -   File "/home/***/.local/lib/python3.7/site-packages/pandas/core/generic.py", line 2571, in to_json
[2022-12-17T02:51:21.554+0000] {subprocess.py:93} INFO -     storage_options=storage_options,
[2022-12-17T02:51:21.555+0000] {subprocess.py:93} INFO -   File "/home/***/.local/lib/python3.7/site-packages/pandas/io/json/_json.py", line 131, in to_json
[2022-12-17T02:51:21.560+0000] {subprocess.py:93} INFO -     path_or_buf, "w", compression=compression, storage_options=storage_options
[2022-12-17T02:51:21.561+0000] {subprocess.py:93} INFO -   File "/home/***/.local/lib/python3.7/site-packages/pandas/io/common.py", line 707, in get_handle
[2022-12-17T02:51:21.563+0000] {subprocess.py:93} INFO -     newline="",
[2022-12-17T02:51:21.564+0000] {subprocess.py:93} INFO - FileNotFoundError: [Errno 2] No such file or directory: '/opt/***/processed_zone/lol_clean_counter_stat.json'
[2022-12-17T02:51:21.961+0000] {subprocess.py:97} INFO - Command exited with return code 1
[2022-12-17T02:51:22.015+0000] {taskinstance.py:1851} ERROR - Task failed with exception
Traceback (most recent call last):
  File "/home/airflow/.local/lib/python3.7/site-packages/airflow/operators/bash.py", line 197, in execute
    f'Bash command failed. The command returned a non-zero exit code {result.exit_code}.'
airflow.exceptions.AirflowException: Bash command failed. The command returned a non-zero exit code 1.
[2022-12-17T02:51:22.030+0000] {taskinstance.py:1406} INFO - Marking task as FAILED. dag_id=Can_I_change_name_to_this, task_id=task_7, execution_date=20221217T025041, start_date=20221217T025116, end_date=20221217T025122
[2022-12-17T02:51:22.072+0000] {standard_task_runner.py:105} ERROR - Failed to execute job 78 for task task_7 (Bash command failed. The command returned a non-zero exit code 1.; 1327)
[2022-12-17T02:51:22.108+0000] {local_task_job.py:159} INFO - Task exited with return code 1
[2022-12-17T02:51:22.132+0000] {taskinstance.py:2623} INFO - 0 downstream tasks scheduled from follow-on schedule check
