[2022-12-17T02:51:15.412+0000] {taskinstance.py:1165} INFO - Dependencies all met for <TaskInstance: Can_I_change_name_to_this.task_6 manual__2022-12-17T02:50:41.373960+00:00 [queued]>
[2022-12-17T02:51:15.448+0000] {taskinstance.py:1165} INFO - Dependencies all met for <TaskInstance: Can_I_change_name_to_this.task_6 manual__2022-12-17T02:50:41.373960+00:00 [queued]>
[2022-12-17T02:51:15.451+0000] {taskinstance.py:1362} INFO - 
--------------------------------------------------------------------------------
[2022-12-17T02:51:15.453+0000] {taskinstance.py:1363} INFO - Starting attempt 1 of 1
[2022-12-17T02:51:15.455+0000] {taskinstance.py:1364} INFO - 
--------------------------------------------------------------------------------
[2022-12-17T02:51:15.471+0000] {taskinstance.py:1383} INFO - Executing <Task(BashOperator): task_6> on 2022-12-17 02:50:41.373960+00:00
[2022-12-17T02:51:15.483+0000] {standard_task_runner.py:55} INFO - Started process 1318 to run task
[2022-12-17T02:51:15.493+0000] {standard_task_runner.py:82} INFO - Running: ['***', 'tasks', 'run', 'Can_I_change_name_to_this', 'task_6', 'manual__2022-12-17T02:50:41.373960+00:00', '--job-id', '76', '--raw', '--subdir', 'DAGS_FOLDER/dags.py', '--cfg-path', '/tmp/tmpj9altbtw']
[2022-12-17T02:51:15.495+0000] {standard_task_runner.py:83} INFO - Job 76: Subtask task_6
[2022-12-17T02:51:15.576+0000] {task_command.py:376} INFO - Running <TaskInstance: Can_I_change_name_to_this.task_6 manual__2022-12-17T02:50:41.373960+00:00 [running]> on host 418b9a9aa3df
[2022-12-17T02:51:15.649+0000] {taskinstance.py:1592} INFO - Exporting the following env vars:
AIRFLOW_CTX_DAG_OWNER=***
AIRFLOW_CTX_DAG_ID=Can_I_change_name_to_this
AIRFLOW_CTX_TASK_ID=task_6
AIRFLOW_CTX_EXECUTION_DATE=2022-12-17T02:50:41.373960+00:00
AIRFLOW_CTX_TRY_NUMBER=1
AIRFLOW_CTX_DAG_RUN_ID=manual__2022-12-17T02:50:41.373960+00:00
[2022-12-17T02:51:15.653+0000] {subprocess.py:63} INFO - Tmp dir root location: 
 /tmp
[2022-12-17T02:51:15.657+0000] {subprocess.py:75} INFO - Running command: ['/bin/bash', '-c', 'python /opt/***/tasks/data_cleansing_basic_stat.py']
[2022-12-17T02:51:15.674+0000] {subprocess.py:86} INFO - Output:
[2022-12-17T02:51:21.197+0000] {subprocess.py:93} INFO - 2022-12-17 02:51:21 +0000 - dagster - DEBUG - data_cleansing_whole_job - 6d51e6cb-65ac-4c9e-8222-0d21d1a67f31 - 1320 - RUN_START - Started execution of run for "data_cleansing_whole_job".
[2022-12-17T02:51:21.206+0000] {subprocess.py:93} INFO - 2022-12-17 02:51:21 +0000 - dagster - DEBUG - data_cleansing_whole_job - 6d51e6cb-65ac-4c9e-8222-0d21d1a67f31 - 1320 - ENGINE_EVENT - Executing steps in process (pid: 1320)
[2022-12-17T02:51:21.214+0000] {subprocess.py:93} INFO - 2022-12-17 02:51:21 +0000 - dagster - DEBUG - data_cleansing_whole_job - 6d51e6cb-65ac-4c9e-8222-0d21d1a67f31 - 1320 - RESOURCE_INIT_STARTED - Starting initialization of resources [io_manager].
[2022-12-17T02:51:21.218+0000] {subprocess.py:93} INFO - 2022-12-17 02:51:21 +0000 - dagster - DEBUG - data_cleansing_whole_job - 6d51e6cb-65ac-4c9e-8222-0d21d1a67f31 - 1320 - RESOURCE_INIT_SUCCESS - Finished initialization of resources [io_manager].
[2022-12-17T02:51:21.223+0000] {subprocess.py:93} INFO - 2022-12-17 02:51:21 +0000 - dagster - DEBUG - data_cleansing_whole_job - 6d51e6cb-65ac-4c9e-8222-0d21d1a67f31 - 1320 - LOGS_CAPTURED - Started capturing logs in process (pid: 1320).
[2022-12-17T02:51:21.228+0000] {subprocess.py:93} INFO - 2022-12-17 02:51:21 +0000 - dagster - DEBUG - data_cleansing_whole_job - 6d51e6cb-65ac-4c9e-8222-0d21d1a67f31 - 1320 - reading_json - STEP_START - Started execution of step "reading_json".
[2022-12-17T02:51:21.277+0000] {subprocess.py:93} INFO - 2022-12-17 02:51:21 +0000 - dagster - DEBUG - data_cleansing_whole_job - 6d51e6cb-65ac-4c9e-8222-0d21d1a67f31 - 1320 - reading_json - STEP_OUTPUT - Yielded output "result" of type "DataFrame". (Type check passed).
[2022-12-17T02:51:21.285+0000] {subprocess.py:93} INFO - 2022-12-17 02:51:21 +0000 - dagster - DEBUG - data_cleansing_whole_job - 6d51e6cb-65ac-4c9e-8222-0d21d1a67f31 - 1320 - reading_json - HANDLED_OUTPUT - Handled output "result" using IO manager "io_manager"
[2022-12-17T02:51:21.290+0000] {subprocess.py:93} INFO - 2022-12-17 02:51:21 +0000 - dagster - DEBUG - data_cleansing_whole_job - 6d51e6cb-65ac-4c9e-8222-0d21d1a67f31 - 1320 - reading_json - STEP_SUCCESS - Finished execution of step "reading_json" in 55ms.
[2022-12-17T02:51:21.291+0000] {subprocess.py:93} INFO - 2022-12-17 02:51:21 +0000 - dagster - DEBUG - data_cleansing_whole_job - 6d51e6cb-65ac-4c9e-8222-0d21d1a67f31 - 1320 - data_validation - STEP_START - Started execution of step "data_validation".
[2022-12-17T02:51:21.294+0000] {subprocess.py:93} INFO - 2022-12-17 02:51:21 +0000 - dagster - DEBUG - data_cleansing_whole_job - 6d51e6cb-65ac-4c9e-8222-0d21d1a67f31 - 1320 - data_validation - LOADED_INPUT - Loaded input "df" using input manager "io_manager", from output "result" of step "reading_json"
[2022-12-17T02:51:21.296+0000] {subprocess.py:93} INFO - 2022-12-17 02:51:21 +0000 - dagster - DEBUG - data_cleansing_whole_job - 6d51e6cb-65ac-4c9e-8222-0d21d1a67f31 - 1320 - data_validation - STEP_INPUT - Got input "df" of type "DataFrame". (Type check passed).
[2022-12-17T02:51:21.313+0000] {subprocess.py:93} INFO - 2022-12-17 02:51:21 +0000 - dagster - DEBUG - data_cleansing_whole_job - 6d51e6cb-65ac-4c9e-8222-0d21d1a67f31 - 1320 - data_validation - STEP_OUTPUT - Yielded output "result" of type "DataFrame". (Type check passed).
[2022-12-17T02:51:21.315+0000] {subprocess.py:93} INFO - 2022-12-17 02:51:21 +0000 - dagster - DEBUG - data_cleansing_whole_job - 6d51e6cb-65ac-4c9e-8222-0d21d1a67f31 - 1320 - data_validation - HANDLED_OUTPUT - Handled output "result" using IO manager "io_manager"
[2022-12-17T02:51:21.316+0000] {subprocess.py:93} INFO - 2022-12-17 02:51:21 +0000 - dagster - DEBUG - data_cleansing_whole_job - 6d51e6cb-65ac-4c9e-8222-0d21d1a67f31 - 1320 - data_validation - STEP_SUCCESS - Finished execution of step "data_validation" in 18ms.
[2022-12-17T02:51:21.319+0000] {subprocess.py:93} INFO - 2022-12-17 02:51:21 +0000 - dagster - DEBUG - data_cleansing_whole_job - 6d51e6cb-65ac-4c9e-8222-0d21d1a67f31 - 1320 - data_cleaning - STEP_START - Started execution of step "data_cleaning".
[2022-12-17T02:51:21.322+0000] {subprocess.py:93} INFO - 2022-12-17 02:51:21 +0000 - dagster - DEBUG - data_cleansing_whole_job - 6d51e6cb-65ac-4c9e-8222-0d21d1a67f31 - 1320 - data_cleaning - LOADED_INPUT - Loaded input "df" using input manager "io_manager", from output "result" of step "data_validation"
[2022-12-17T02:51:21.323+0000] {subprocess.py:93} INFO - 2022-12-17 02:51:21 +0000 - dagster - DEBUG - data_cleansing_whole_job - 6d51e6cb-65ac-4c9e-8222-0d21d1a67f31 - 1320 - data_cleaning - STEP_INPUT - Got input "df" of type "DataFrame". (Type check passed).
[2022-12-17T02:51:21.325+0000] {subprocess.py:93} INFO - {"message": "now perform data cleansing on lol_basic_stat", "time": "2022-12-17T02:51:21.324742"}
[2022-12-17T02:51:21.471+0000] {subprocess.py:93} INFO - {"message": "successfully perform data cleansing on lol_basic_stat", "time": "2022-12-17T02:51:21.471266"}
[2022-12-17T02:51:21.473+0000] {subprocess.py:93} INFO - {"message": "Now putting dataframe into pg and redshift", "time": "2022-12-17T02:51:21.473311"}
[2022-12-17T02:51:21.479+0000] {subprocess.py:93} INFO - 2022-12-17 02:51:21 +0000 - dagster - DEBUG - data_cleansing_whole_job - 6d51e6cb-65ac-4c9e-8222-0d21d1a67f31 - 1320 - data_cleaning - STEP_OUTPUT - Yielded output "result" of type "DataFrame". (Type check passed).
[2022-12-17T02:51:21.484+0000] {subprocess.py:93} INFO - 2022-12-17 02:51:21 +0000 - dagster - DEBUG - data_cleansing_whole_job - 6d51e6cb-65ac-4c9e-8222-0d21d1a67f31 - 1320 - data_cleaning - HANDLED_OUTPUT - Handled output "result" using IO manager "io_manager"
[2022-12-17T02:51:21.486+0000] {subprocess.py:93} INFO - 2022-12-17 02:51:21 +0000 - dagster - DEBUG - data_cleansing_whole_job - 6d51e6cb-65ac-4c9e-8222-0d21d1a67f31 - 1320 - data_cleaning - STEP_SUCCESS - Finished execution of step "data_cleaning" in 160ms.
[2022-12-17T02:51:21.499+0000] {subprocess.py:93} INFO - 2022-12-17 02:51:21 +0000 - dagster - DEBUG - data_cleansing_whole_job - 6d51e6cb-65ac-4c9e-8222-0d21d1a67f31 - 1320 - df_to_file - STEP_START - Started execution of step "df_to_file".
[2022-12-17T02:51:21.507+0000] {subprocess.py:93} INFO - 2022-12-17 02:51:21 +0000 - dagster - DEBUG - data_cleansing_whole_job - 6d51e6cb-65ac-4c9e-8222-0d21d1a67f31 - 1320 - df_to_file - LOADED_INPUT - Loaded input "df" using input manager "io_manager", from output "result" of step "data_cleaning"
[2022-12-17T02:51:21.512+0000] {subprocess.py:93} INFO - 2022-12-17 02:51:21 +0000 - dagster - DEBUG - data_cleansing_whole_job - 6d51e6cb-65ac-4c9e-8222-0d21d1a67f31 - 1320 - df_to_file - STEP_INPUT - Got input "df" of type "DataFrame". (Type check passed).
[2022-12-17T02:51:21.530+0000] {subprocess.py:93} INFO - 2022-12-17 02:51:21 +0000 - dagster - ERROR - data_cleansing_whole_job - 6d51e6cb-65ac-4c9e-8222-0d21d1a67f31 - 1320 - df_to_file - STEP_FAILURE - Execution of step "df_to_file" failed.
[2022-12-17T02:51:21.532+0000] {subprocess.py:93} INFO - 
[2022-12-17T02:51:21.535+0000] {subprocess.py:93} INFO - dagster._core.errors.DagsterExecutionStepExecutionError: Error occurred while executing op "df_to_file"::
[2022-12-17T02:51:21.538+0000] {subprocess.py:93} INFO - 
[2022-12-17T02:51:21.546+0000] {subprocess.py:93} INFO - FileNotFoundError: [Errno 2] No such file or directory: '/opt/***/processed_zone/lol_clean_basic_stat.json'
[2022-12-17T02:51:21.549+0000] {subprocess.py:93} INFO - 
[2022-12-17T02:51:21.552+0000] {subprocess.py:93} INFO - Stack Trace:
[2022-12-17T02:51:21.555+0000] {subprocess.py:93} INFO -   File "/home/***/.local/lib/python3.7/site-packages/dagster/_core/execution/plan/utils.py", line 47, in solid_execution_error_boundary
[2022-12-17T02:51:21.556+0000] {subprocess.py:93} INFO -     yield
[2022-12-17T02:51:21.560+0000] {subprocess.py:93} INFO -   File "/home/***/.local/lib/python3.7/site-packages/dagster/_utils/__init__.py", line 447, in iterate_with_context
[2022-12-17T02:51:21.561+0000] {subprocess.py:93} INFO -     next_output = next(iterator)
[2022-12-17T02:51:21.562+0000] {subprocess.py:93} INFO -   File "/home/***/.local/lib/python3.7/site-packages/dagster/_core/execution/plan/compute_generator.py", line 74, in _coerce_solid_compute_fn_to_iterator
[2022-12-17T02:51:21.563+0000] {subprocess.py:93} INFO -     result = fn(context, **kwargs) if context_arg_provided else fn(**kwargs)
[2022-12-17T02:51:21.565+0000] {subprocess.py:93} INFO -   File "/opt/***/tasks/data_cleansing_basic_stat.py", line 83, in df_to_file
[2022-12-17T02:51:21.565+0000] {subprocess.py:93} INFO -     df.to_json("/opt/***/processed_zone/lol_clean_basic_stat.json",orient='records',lines=True)
[2022-12-17T02:51:21.566+0000] {subprocess.py:93} INFO -   File "/home/***/.local/lib/python3.7/site-packages/pandas/core/generic.py", line 2571, in to_json
[2022-12-17T02:51:21.566+0000] {subprocess.py:93} INFO -     storage_options=storage_options,
[2022-12-17T02:51:21.567+0000] {subprocess.py:93} INFO -   File "/home/***/.local/lib/python3.7/site-packages/pandas/io/json/_json.py", line 131, in to_json
[2022-12-17T02:51:21.568+0000] {subprocess.py:93} INFO -     path_or_buf, "w", compression=compression, storage_options=storage_options
[2022-12-17T02:51:21.578+0000] {subprocess.py:93} INFO -   File "/home/***/.local/lib/python3.7/site-packages/pandas/io/common.py", line 707, in get_handle
[2022-12-17T02:51:21.580+0000] {subprocess.py:93} INFO -     newline="",
[2022-12-17T02:51:21.582+0000] {subprocess.py:93} INFO - 
[2022-12-17T02:51:21.584+0000] {subprocess.py:93} INFO - 2022-12-17 02:51:21 +0000 - dagster - ERROR - data_cleansing_whole_job - 6d51e6cb-65ac-4c9e-8222-0d21d1a67f31 - 1320 - RUN_FAILURE - Execution of run for "data_cleansing_whole_job" failed. An exception was thrown during execution.
[2022-12-17T02:51:21.584+0000] {subprocess.py:93} INFO - 
[2022-12-17T02:51:21.585+0000] {subprocess.py:93} INFO - FileNotFoundError: [Errno 2] No such file or directory: '/opt/***/processed_zone/lol_clean_basic_stat.json'
[2022-12-17T02:51:21.585+0000] {subprocess.py:93} INFO - 
[2022-12-17T02:51:21.615+0000] {subprocess.py:93} INFO - Stack Trace:
[2022-12-17T02:51:21.624+0000] {subprocess.py:93} INFO -   File "/home/***/.local/lib/python3.7/site-packages/dagster/_core/execution/api.py", line 1091, in pipeline_execution_iterator
[2022-12-17T02:51:21.626+0000] {subprocess.py:93} INFO -     for event in pipeline_context.executor.execute(pipeline_context, execution_plan):
[2022-12-17T02:51:21.629+0000] {subprocess.py:93} INFO -   File "/home/***/.local/lib/python3.7/site-packages/dagster/_core/executor/in_process.py", line 50, in execute
[2022-12-17T02:51:21.633+0000] {subprocess.py:93} INFO -     output_capture=plan_context.output_capture,
[2022-12-17T02:51:21.637+0000] {subprocess.py:93} INFO -   File "/home/***/.local/lib/python3.7/site-packages/dagster/_core/execution/api.py", line 1189, in __iter__
[2022-12-17T02:51:21.639+0000] {subprocess.py:93} INFO -     pipeline_context=self.pipeline_context,
[2022-12-17T02:51:21.641+0000] {subprocess.py:93} INFO -   File "/home/***/.local/lib/python3.7/site-packages/dagster/_core/execution/plan/execute_plan.py", line 121, in inner_plan_execution_iterator
[2022-12-17T02:51:21.643+0000] {subprocess.py:93} INFO -     dagster_event_sequence_for_step(step_context)
[2022-12-17T02:51:21.645+0000] {subprocess.py:93} INFO -   File "/home/***/.local/lib/python3.7/site-packages/dagster/_core/execution/plan/execute_plan.py", line 325, in dagster_event_sequence_for_step
[2022-12-17T02:51:21.647+0000] {subprocess.py:93} INFO -     raise dagster_user_error.user_exception
[2022-12-17T02:51:21.651+0000] {subprocess.py:93} INFO -   File "/home/***/.local/lib/python3.7/site-packages/dagster/_core/execution/plan/utils.py", line 47, in solid_execution_error_boundary
[2022-12-17T02:51:21.654+0000] {subprocess.py:93} INFO -     yield
[2022-12-17T02:51:21.656+0000] {subprocess.py:93} INFO -   File "/home/***/.local/lib/python3.7/site-packages/dagster/_utils/__init__.py", line 447, in iterate_with_context
[2022-12-17T02:51:21.658+0000] {subprocess.py:93} INFO -     next_output = next(iterator)
[2022-12-17T02:51:21.659+0000] {subprocess.py:93} INFO -   File "/home/***/.local/lib/python3.7/site-packages/dagster/_core/execution/plan/compute_generator.py", line 74, in _coerce_solid_compute_fn_to_iterator
[2022-12-17T02:51:21.660+0000] {subprocess.py:93} INFO -     result = fn(context, **kwargs) if context_arg_provided else fn(**kwargs)
[2022-12-17T02:51:21.661+0000] {subprocess.py:93} INFO -   File "/opt/***/tasks/data_cleansing_basic_stat.py", line 83, in df_to_file
[2022-12-17T02:51:21.666+0000] {subprocess.py:93} INFO -     df.to_json("/opt/***/processed_zone/lol_clean_basic_stat.json",orient='records',lines=True)
[2022-12-17T02:51:21.671+0000] {subprocess.py:93} INFO -   File "/home/***/.local/lib/python3.7/site-packages/pandas/core/generic.py", line 2571, in to_json
[2022-12-17T02:51:21.675+0000] {subprocess.py:93} INFO -     storage_options=storage_options,
[2022-12-17T02:51:21.677+0000] {subprocess.py:93} INFO -   File "/home/***/.local/lib/python3.7/site-packages/pandas/io/json/_json.py", line 131, in to_json
[2022-12-17T02:51:21.677+0000] {subprocess.py:93} INFO -     path_or_buf, "w", compression=compression, storage_options=storage_options
[2022-12-17T02:51:21.678+0000] {subprocess.py:93} INFO -   File "/home/***/.local/lib/python3.7/site-packages/pandas/io/common.py", line 707, in get_handle
[2022-12-17T02:51:21.679+0000] {subprocess.py:93} INFO -     newline="",
[2022-12-17T02:51:21.680+0000] {subprocess.py:93} INFO - 
[2022-12-17T02:51:21.681+0000] {subprocess.py:93} INFO - Traceback (most recent call last):
[2022-12-17T02:51:21.682+0000] {subprocess.py:93} INFO -   File "/home/***/.local/lib/python3.7/site-packages/dagster/_core/execution/plan/execute_plan.py", line 251, in dagster_event_sequence_for_step
[2022-12-17T02:51:21.686+0000] {subprocess.py:93} INFO -     for step_event in check.generator(step_events):
[2022-12-17T02:51:21.689+0000] {subprocess.py:93} INFO -   File "/home/***/.local/lib/python3.7/site-packages/dagster/_core/execution/plan/execute_step.py", line 390, in core_dagster_event_sequence_for_step
[2022-12-17T02:51:21.691+0000] {subprocess.py:93} INFO -     _step_output_error_checked_user_event_sequence(step_context, user_event_sequence)
[2022-12-17T02:51:21.692+0000] {subprocess.py:93} INFO -   File "/home/***/.local/lib/python3.7/site-packages/dagster/_core/execution/plan/execute_step.py", line 95, in _step_output_error_checked_user_event_sequence
[2022-12-17T02:51:21.694+0000] {subprocess.py:93} INFO -     for user_event in user_event_sequence:
[2022-12-17T02:51:21.695+0000] {subprocess.py:93} INFO -   File "/home/***/.local/lib/python3.7/site-packages/dagster/_core/execution/plan/compute.py", line 174, in execute_core_compute
[2022-12-17T02:51:21.696+0000] {subprocess.py:93} INFO -     for step_output in _yield_compute_results(step_context, inputs, compute_fn):
[2022-12-17T02:51:21.696+0000] {subprocess.py:93} INFO -   File "/home/***/.local/lib/python3.7/site-packages/dagster/_core/execution/plan/compute.py", line 151, in _yield_compute_results
[2022-12-17T02:51:21.697+0000] {subprocess.py:93} INFO -     user_event_generator,
[2022-12-17T02:51:21.697+0000] {subprocess.py:93} INFO -   File "/home/***/.local/lib/python3.7/site-packages/dagster/_utils/__init__.py", line 449, in iterate_with_context
[2022-12-17T02:51:21.698+0000] {subprocess.py:93} INFO -     return
[2022-12-17T02:51:21.698+0000] {subprocess.py:93} INFO -   File "/usr/local/lib/python3.7/contextlib.py", line 130, in __exit__
[2022-12-17T02:51:21.699+0000] {subprocess.py:93} INFO -     self.gen.throw(type, value, traceback)
[2022-12-17T02:51:21.699+0000] {subprocess.py:93} INFO -   File "/home/***/.local/lib/python3.7/site-packages/dagster/_core/execution/plan/utils.py", line 82, in solid_execution_error_boundary
[2022-12-17T02:51:21.699+0000] {subprocess.py:93} INFO -     ) from e
[2022-12-17T02:51:21.700+0000] {subprocess.py:93} INFO - dagster._core.errors.DagsterExecutionStepExecutionError: Error occurred while executing op "df_to_file":
[2022-12-17T02:51:21.700+0000] {subprocess.py:93} INFO - 
[2022-12-17T02:51:21.703+0000] {subprocess.py:93} INFO - During handling of the above exception, another exception occurred:
[2022-12-17T02:51:21.704+0000] {subprocess.py:93} INFO - 
[2022-12-17T02:51:21.705+0000] {subprocess.py:93} INFO - Traceback (most recent call last):
[2022-12-17T02:51:21.706+0000] {subprocess.py:93} INFO -   File "/opt/***/tasks/data_cleansing_basic_stat.py", line 95, in <module>
[2022-12-17T02:51:21.707+0000] {subprocess.py:93} INFO -     result = data_cleansing_whole_job.execute_in_process()
[2022-12-17T02:51:21.707+0000] {subprocess.py:93} INFO -   File "/home/***/.local/lib/python3.7/site-packages/dagster/_core/definitions/job_definition.py", line 395, in execute_in_process
[2022-12-17T02:51:21.708+0000] {subprocess.py:93} INFO -     asset_selection=frozenset(asset_selection),
[2022-12-17T02:51:21.709+0000] {subprocess.py:93} INFO -   File "/home/***/.local/lib/python3.7/site-packages/dagster/_core/execution/execute_in_process.py", line 77, in core_execute_in_process
[2022-12-17T02:51:21.713+0000] {subprocess.py:93} INFO -     event_list = list(execute_run_iterable)
[2022-12-17T02:51:21.715+0000] {subprocess.py:93} INFO -   File "/home/***/.local/lib/python3.7/site-packages/dagster/_core/execution/api.py", line 1189, in __iter__
[2022-12-17T02:51:21.718+0000] {subprocess.py:93} INFO -     pipeline_context=self.pipeline_context,
[2022-12-17T02:51:21.721+0000] {subprocess.py:93} INFO -   File "/home/***/.local/lib/python3.7/site-packages/dagster/_core/execution/api.py", line 1091, in pipeline_execution_iterator
[2022-12-17T02:51:21.723+0000] {subprocess.py:93} INFO -     for event in pipeline_context.executor.execute(pipeline_context, execution_plan):
[2022-12-17T02:51:21.723+0000] {subprocess.py:93} INFO -   File "/home/***/.local/lib/python3.7/site-packages/dagster/_core/executor/in_process.py", line 50, in execute
[2022-12-17T02:51:21.724+0000] {subprocess.py:93} INFO -     output_capture=plan_context.output_capture,
[2022-12-17T02:51:21.727+0000] {subprocess.py:93} INFO -   File "/home/***/.local/lib/python3.7/site-packages/dagster/_core/execution/api.py", line 1189, in __iter__
[2022-12-17T02:51:21.733+0000] {subprocess.py:93} INFO -     pipeline_context=self.pipeline_context,
[2022-12-17T02:51:21.734+0000] {subprocess.py:93} INFO -   File "/home/***/.local/lib/python3.7/site-packages/dagster/_core/execution/plan/execute_plan.py", line 121, in inner_plan_execution_iterator
[2022-12-17T02:51:21.736+0000] {subprocess.py:93} INFO -     dagster_event_sequence_for_step(step_context)
[2022-12-17T02:51:21.738+0000] {subprocess.py:93} INFO -   File "/home/***/.local/lib/python3.7/site-packages/dagster/_core/execution/plan/execute_plan.py", line 325, in dagster_event_sequence_for_step
[2022-12-17T02:51:21.739+0000] {subprocess.py:93} INFO -     raise dagster_user_error.user_exception
[2022-12-17T02:51:21.741+0000] {subprocess.py:93} INFO -   File "/home/***/.local/lib/python3.7/site-packages/dagster/_core/execution/plan/utils.py", line 47, in solid_execution_error_boundary
[2022-12-17T02:51:21.743+0000] {subprocess.py:93} INFO -     yield
[2022-12-17T02:51:21.744+0000] {subprocess.py:93} INFO -   File "/home/***/.local/lib/python3.7/site-packages/dagster/_utils/__init__.py", line 447, in iterate_with_context
[2022-12-17T02:51:21.746+0000] {subprocess.py:93} INFO -     next_output = next(iterator)
[2022-12-17T02:51:21.747+0000] {subprocess.py:93} INFO -   File "/home/***/.local/lib/python3.7/site-packages/dagster/_core/execution/plan/compute_generator.py", line 74, in _coerce_solid_compute_fn_to_iterator
[2022-12-17T02:51:21.757+0000] {subprocess.py:93} INFO -     result = fn(context, **kwargs) if context_arg_provided else fn(**kwargs)
[2022-12-17T02:51:21.760+0000] {subprocess.py:93} INFO -   File "/opt/***/tasks/data_cleansing_basic_stat.py", line 83, in df_to_file
[2022-12-17T02:51:21.763+0000] {subprocess.py:93} INFO -     df.to_json("/opt/***/processed_zone/lol_clean_basic_stat.json",orient='records',lines=True)
[2022-12-17T02:51:21.764+0000] {subprocess.py:93} INFO -   File "/home/***/.local/lib/python3.7/site-packages/pandas/core/generic.py", line 2571, in to_json
[2022-12-17T02:51:21.769+0000] {subprocess.py:93} INFO -     storage_options=storage_options,
[2022-12-17T02:51:21.772+0000] {subprocess.py:93} INFO -   File "/home/***/.local/lib/python3.7/site-packages/pandas/io/json/_json.py", line 131, in to_json
[2022-12-17T02:51:21.774+0000] {subprocess.py:93} INFO -     path_or_buf, "w", compression=compression, storage_options=storage_options
[2022-12-17T02:51:21.775+0000] {subprocess.py:93} INFO -   File "/home/***/.local/lib/python3.7/site-packages/pandas/io/common.py", line 707, in get_handle
[2022-12-17T02:51:21.776+0000] {subprocess.py:93} INFO -     newline="",
[2022-12-17T02:51:21.777+0000] {subprocess.py:93} INFO - FileNotFoundError: [Errno 2] No such file or directory: '/opt/***/processed_zone/lol_clean_basic_stat.json'
[2022-12-17T02:51:22.010+0000] {subprocess.py:97} INFO - Command exited with return code 1
[2022-12-17T02:51:22.049+0000] {taskinstance.py:1851} ERROR - Task failed with exception
Traceback (most recent call last):
  File "/home/airflow/.local/lib/python3.7/site-packages/airflow/operators/bash.py", line 197, in execute
    f'Bash command failed. The command returned a non-zero exit code {result.exit_code}.'
airflow.exceptions.AirflowException: Bash command failed. The command returned a non-zero exit code 1.
[2022-12-17T02:51:22.066+0000] {taskinstance.py:1406} INFO - Marking task as FAILED. dag_id=Can_I_change_name_to_this, task_id=task_6, execution_date=20221217T025041, start_date=20221217T025115, end_date=20221217T025122
[2022-12-17T02:51:22.089+0000] {standard_task_runner.py:105} ERROR - Failed to execute job 76 for task task_6 (Bash command failed. The command returned a non-zero exit code 1.; 1318)
[2022-12-17T02:51:22.147+0000] {local_task_job.py:159} INFO - Task exited with return code 1
[2022-12-17T02:51:22.194+0000] {taskinstance.py:2623} INFO - 0 downstream tasks scheduled from follow-on schedule check
