[2022-12-20T10:01:30.800+0000] {taskinstance.py:1087} INFO - Dependencies all met for <TaskInstance: Can_I_change_name_to_this.basic_data_cleansing scheduled__2022-12-19T10:00:00+00:00 [queued]>
[2022-12-20T10:01:30.949+0000] {taskinstance.py:1087} INFO - Dependencies all met for <TaskInstance: Can_I_change_name_to_this.basic_data_cleansing scheduled__2022-12-19T10:00:00+00:00 [queued]>
[2022-12-20T10:01:30.951+0000] {taskinstance.py:1283} INFO - 
--------------------------------------------------------------------------------
[2022-12-20T10:01:30.960+0000] {taskinstance.py:1284} INFO - Starting attempt 1 of 1
[2022-12-20T10:01:30.972+0000] {taskinstance.py:1285} INFO - 
--------------------------------------------------------------------------------
[2022-12-20T10:01:31.072+0000] {taskinstance.py:1304} INFO - Executing <Task(BashOperator): basic_data_cleansing> on 2022-12-19 10:00:00+00:00
[2022-12-20T10:01:31.114+0000] {standard_task_runner.py:55} INFO - Started process 2804 to run task
[2022-12-20T10:01:31.134+0000] {standard_task_runner.py:82} INFO - Running: ['***', 'tasks', 'run', 'Can_I_change_name_to_this', 'basic_data_cleansing', 'scheduled__2022-12-19T10:00:00+00:00', '--job-id', '167', '--raw', '--subdir', 'DAGS_FOLDER/dags.py', '--cfg-path', '/tmp/tmp2q20a3nc']
[2022-12-20T10:01:31.183+0000] {standard_task_runner.py:83} INFO - Job 167: Subtask basic_data_cleansing
[2022-12-20T10:01:31.415+0000] {task_command.py:389} INFO - Running <TaskInstance: Can_I_change_name_to_this.basic_data_cleansing scheduled__2022-12-19T10:00:00+00:00 [running]> on host 502390ac5559
[2022-12-20T10:01:31.622+0000] {taskinstance.py:1513} INFO - Exporting the following env vars:
AIRFLOW_CTX_DAG_OWNER=***
AIRFLOW_CTX_DAG_ID=Can_I_change_name_to_this
AIRFLOW_CTX_TASK_ID=basic_data_cleansing
AIRFLOW_CTX_EXECUTION_DATE=2022-12-19T10:00:00+00:00
AIRFLOW_CTX_TRY_NUMBER=1
AIRFLOW_CTX_DAG_RUN_ID=scheduled__2022-12-19T10:00:00+00:00
[2022-12-20T10:01:31.707+0000] {subprocess.py:63} INFO - Tmp dir root location: 
 /tmp
[2022-12-20T10:01:31.758+0000] {subprocess.py:75} INFO - Running command: ['/bin/bash', '-c', 'python /opt/***/tasks/data_cleansing_basic_stat.py']
[2022-12-20T10:01:31.899+0000] {subprocess.py:86} INFO - Output:
[2022-12-20T10:02:05.555+0000] {subprocess.py:93} INFO - 2022-12-20 10:02:05 +0000 - dagster - DEBUG - data_cleansing_whole_job - 9d7e36ac-441d-42ae-9b63-5cdba3951427 - 2807 - RUN_START - Started execution of run for "data_cleansing_whole_job".
[2022-12-20T10:02:05.647+0000] {subprocess.py:93} INFO - 2022-12-20 10:02:05 +0000 - dagster - DEBUG - data_cleansing_whole_job - 9d7e36ac-441d-42ae-9b63-5cdba3951427 - 2807 - ENGINE_EVENT - Executing steps in process (pid: 2807)
[2022-12-20T10:02:05.654+0000] {subprocess.py:93} INFO - 2022-12-20 10:02:05 +0000 - dagster - DEBUG - data_cleansing_whole_job - 9d7e36ac-441d-42ae-9b63-5cdba3951427 - 2807 - RESOURCE_INIT_STARTED - Starting initialization of resources [io_manager].
[2022-12-20T10:02:05.658+0000] {subprocess.py:93} INFO - 2022-12-20 10:02:05 +0000 - dagster - DEBUG - data_cleansing_whole_job - 9d7e36ac-441d-42ae-9b63-5cdba3951427 - 2807 - RESOURCE_INIT_SUCCESS - Finished initialization of resources [io_manager].
[2022-12-20T10:02:05.660+0000] {subprocess.py:93} INFO - 2022-12-20 10:02:05 +0000 - dagster - DEBUG - data_cleansing_whole_job - 9d7e36ac-441d-42ae-9b63-5cdba3951427 - 2807 - LOGS_CAPTURED - Started capturing logs in process (pid: 2807).
[2022-12-20T10:02:05.665+0000] {subprocess.py:93} INFO - 2022-12-20 10:02:05 +0000 - dagster - DEBUG - data_cleansing_whole_job - 9d7e36ac-441d-42ae-9b63-5cdba3951427 - 2807 - reading_json - STEP_START - Started execution of step "reading_json".
[2022-12-20T10:02:05.668+0000] {subprocess.py:93} INFO - 2022-12-20 10:02:05 +0000 - dagster - DEBUG - data_cleansing_whole_job - 9d7e36ac-441d-42ae-9b63-5cdba3951427 - 2807 - reading_json - STEP_OUTPUT - Yielded output "result" of type "DataFrame". (Type check passed).
[2022-12-20T10:02:05.670+0000] {subprocess.py:93} INFO - 2022-12-20 10:02:05 +0000 - dagster - DEBUG - data_cleansing_whole_job - 9d7e36ac-441d-42ae-9b63-5cdba3951427 - 2807 - reading_json - HANDLED_OUTPUT - Handled output "result" using IO manager "io_manager"
[2022-12-20T10:02:05.675+0000] {subprocess.py:93} INFO - 2022-12-20 10:02:05 +0000 - dagster - DEBUG - data_cleansing_whole_job - 9d7e36ac-441d-42ae-9b63-5cdba3951427 - 2807 - reading_json - STEP_SUCCESS - Finished execution of step "reading_json" in 236ms.
[2022-12-20T10:02:05.677+0000] {subprocess.py:93} INFO - 2022-12-20 10:02:05 +0000 - dagster - DEBUG - data_cleansing_whole_job - 9d7e36ac-441d-42ae-9b63-5cdba3951427 - 2807 - data_validation - STEP_START - Started execution of step "data_validation".
[2022-12-20T10:02:05.679+0000] {subprocess.py:93} INFO - 2022-12-20 10:02:05 +0000 - dagster - DEBUG - data_cleansing_whole_job - 9d7e36ac-441d-42ae-9b63-5cdba3951427 - 2807 - data_validation - LOADED_INPUT - Loaded input "df" using input manager "io_manager", from output "result" of step "reading_json"
[2022-12-20T10:02:05.680+0000] {subprocess.py:93} INFO - 2022-12-20 10:02:05 +0000 - dagster - DEBUG - data_cleansing_whole_job - 9d7e36ac-441d-42ae-9b63-5cdba3951427 - 2807 - data_validation - STEP_INPUT - Got input "df" of type "DataFrame". (Type check passed).
[2022-12-20T10:02:06.143+0000] {subprocess.py:93} INFO - 2022-12-20 10:02:06 +0000 - dagster - ERROR - data_cleansing_whole_job - 9d7e36ac-441d-42ae-9b63-5cdba3951427 - 2807 - data_validation - STEP_FAILURE - Execution of step "data_validation" failed.
[2022-12-20T10:02:06.145+0000] {subprocess.py:93} INFO - 
[2022-12-20T10:02:06.146+0000] {subprocess.py:93} INFO - dagster._core.errors.DagsterExecutionStepExecutionError: Error occurred while executing op "data_validation"::
[2022-12-20T10:02:06.152+0000] {subprocess.py:93} INFO - 
[2022-12-20T10:02:06.153+0000] {subprocess.py:93} INFO - pandera.errors.SchemaErrors: Schema None: A total of 1 schema errors were found.
[2022-12-20T10:02:06.154+0000] {subprocess.py:93} INFO - 
[2022-12-20T10:02:06.154+0000] {subprocess.py:93} INFO - Error Counts
[2022-12-20T10:02:06.156+0000] {subprocess.py:93} INFO - ------------
[2022-12-20T10:02:06.157+0000] {subprocess.py:93} INFO - - column_not_in_dataframe: 1
[2022-12-20T10:02:06.181+0000] {subprocess.py:93} INFO - 
[2022-12-20T10:02:06.193+0000] {subprocess.py:93} INFO - Schema Error Summary
[2022-12-20T10:02:06.194+0000] {subprocess.py:93} INFO - --------------------
[2022-12-20T10:02:06.195+0000] {subprocess.py:93} INFO -                                            failure_cases  n_failure_cases
[2022-12-20T10:02:06.220+0000] {subprocess.py:93} INFO - schema_context  column check
[2022-12-20T10:02:06.221+0000] {subprocess.py:93} INFO - DataFrameSchema <NA>   column_in_dataframe        [name]                1
[2022-12-20T10:02:06.251+0000] {subprocess.py:93} INFO - 
[2022-12-20T10:02:06.261+0000] {subprocess.py:93} INFO - Usage Tip
[2022-12-20T10:02:06.280+0000] {subprocess.py:93} INFO - ---------
[2022-12-20T10:02:06.281+0000] {subprocess.py:93} INFO - 
[2022-12-20T10:02:06.282+0000] {subprocess.py:93} INFO - Directly inspect all errors by catching the exception:
[2022-12-20T10:02:06.282+0000] {subprocess.py:93} INFO - 
[2022-12-20T10:02:06.283+0000] {subprocess.py:93} INFO - ```
[2022-12-20T10:02:06.283+0000] {subprocess.py:93} INFO - try:
[2022-12-20T10:02:06.284+0000] {subprocess.py:93} INFO -     schema.validate(dataframe, lazy=True)
[2022-12-20T10:02:06.285+0000] {subprocess.py:93} INFO - except SchemaErrors as err:
[2022-12-20T10:02:06.285+0000] {subprocess.py:93} INFO -     err.failure_cases  # dataframe of schema errors
[2022-12-20T10:02:06.286+0000] {subprocess.py:93} INFO -     err.data  # invalid dataframe
[2022-12-20T10:02:06.287+0000] {subprocess.py:93} INFO - ```
[2022-12-20T10:02:06.287+0000] {subprocess.py:93} INFO - 
[2022-12-20T10:02:06.288+0000] {subprocess.py:93} INFO - 
[2022-12-20T10:02:06.289+0000] {subprocess.py:93} INFO - Stack Trace:
[2022-12-20T10:02:06.289+0000] {subprocess.py:93} INFO -   File "/home/***/.local/lib/python3.7/site-packages/dagster/_core/execution/plan/utils.py", line 56, in op_execution_error_boundary
[2022-12-20T10:02:06.290+0000] {subprocess.py:93} INFO -     yield
[2022-12-20T10:02:06.291+0000] {subprocess.py:93} INFO -   File "/home/***/.local/lib/python3.7/site-packages/dagster/_utils/__init__.py", line 458, in iterate_with_context
[2022-12-20T10:02:06.292+0000] {subprocess.py:93} INFO -     next_output = next(iterator)
[2022-12-20T10:02:06.341+0000] {subprocess.py:93} INFO -   File "/home/***/.local/lib/python3.7/site-packages/dagster/_core/execution/plan/compute_generator.py", line 75, in _coerce_solid_compute_fn_to_iterator
[2022-12-20T10:02:06.370+0000] {subprocess.py:93} INFO -     result = fn(context, **kwargs) if context_arg_provided else fn(**kwargs)
[2022-12-20T10:02:06.371+0000] {subprocess.py:93} INFO -   File "/opt/***/tasks/data_cleansing_basic_stat.py", line 42, in data_validation
[2022-12-20T10:02:06.372+0000] {subprocess.py:93} INFO -     result = schema.validate(df,lazy=True)
[2022-12-20T10:02:06.373+0000] {subprocess.py:93} INFO -   File "/home/***/.local/lib/python3.7/site-packages/pandera/schemas.py", line 541, in validate
[2022-12-20T10:02:06.377+0000] {subprocess.py:93} INFO -     inplace=inplace,
[2022-12-20T10:02:06.400+0000] {subprocess.py:93} INFO -   File "/home/***/.local/lib/python3.7/site-packages/pandera/schemas.py", line 795, in _validate
[2022-12-20T10:02:06.422+0000] {subprocess.py:93} INFO -     self, error_handler.collected_errors, check_obj
[2022-12-20T10:02:06.441+0000] {subprocess.py:93} INFO - 
[2022-12-20T10:02:06.449+0000] {subprocess.py:93} INFO - 2022-12-20 10:02:06 +0000 - dagster - ERROR - data_cleansing_whole_job - 9d7e36ac-441d-42ae-9b63-5cdba3951427 - 2807 - RUN_FAILURE - Execution of run for "data_cleansing_whole_job" failed. An exception was thrown during execution.
[2022-12-20T10:02:06.450+0000] {subprocess.py:93} INFO - 
[2022-12-20T10:02:06.451+0000] {subprocess.py:93} INFO - pandera.errors.SchemaErrors: Schema None: A total of 1 schema errors were found.
[2022-12-20T10:02:06.452+0000] {subprocess.py:93} INFO - 
[2022-12-20T10:02:06.453+0000] {subprocess.py:93} INFO - Error Counts
[2022-12-20T10:02:06.453+0000] {subprocess.py:93} INFO - ------------
[2022-12-20T10:02:06.469+0000] {subprocess.py:93} INFO - - column_not_in_dataframe: 1
[2022-12-20T10:02:06.479+0000] {subprocess.py:93} INFO - 
[2022-12-20T10:02:06.480+0000] {subprocess.py:93} INFO - Schema Error Summary
[2022-12-20T10:02:06.481+0000] {subprocess.py:93} INFO - --------------------
[2022-12-20T10:02:06.500+0000] {subprocess.py:93} INFO -                                            failure_cases  n_failure_cases
[2022-12-20T10:02:06.501+0000] {subprocess.py:93} INFO - schema_context  column check
[2022-12-20T10:02:06.522+0000] {subprocess.py:93} INFO - DataFrameSchema <NA>   column_in_dataframe        [name]                1
[2022-12-20T10:02:06.523+0000] {subprocess.py:93} INFO - 
[2022-12-20T10:02:06.524+0000] {subprocess.py:93} INFO - Usage Tip
[2022-12-20T10:02:06.539+0000] {subprocess.py:93} INFO - ---------
[2022-12-20T10:02:06.642+0000] {subprocess.py:93} INFO - 
[2022-12-20T10:02:06.681+0000] {subprocess.py:93} INFO - Directly inspect all errors by catching the exception:
[2022-12-20T10:02:06.731+0000] {subprocess.py:93} INFO - 
[2022-12-20T10:02:06.813+0000] {subprocess.py:93} INFO - ```
[2022-12-20T10:02:06.841+0000] {subprocess.py:93} INFO - try:
[2022-12-20T10:02:06.882+0000] {subprocess.py:93} INFO -     schema.validate(dataframe, lazy=True)
[2022-12-20T10:02:06.910+0000] {subprocess.py:93} INFO - except SchemaErrors as err:
[2022-12-20T10:02:06.911+0000] {subprocess.py:93} INFO -     err.failure_cases  # dataframe of schema errors
[2022-12-20T10:02:06.912+0000] {subprocess.py:93} INFO -     err.data  # invalid dataframe
[2022-12-20T10:02:06.915+0000] {subprocess.py:93} INFO - ```
[2022-12-20T10:02:06.916+0000] {subprocess.py:93} INFO - 
[2022-12-20T10:02:06.918+0000] {subprocess.py:93} INFO - 
[2022-12-20T10:02:06.920+0000] {subprocess.py:93} INFO - Stack Trace:
[2022-12-20T10:02:06.922+0000] {subprocess.py:93} INFO -   File "/home/***/.local/lib/python3.7/site-packages/dagster/_core/execution/api.py", line 1089, in pipeline_execution_iterator
[2022-12-20T10:02:06.927+0000] {subprocess.py:93} INFO -     for event in pipeline_context.executor.execute(pipeline_context, execution_plan):
[2022-12-20T10:02:06.936+0000] {subprocess.py:93} INFO -   File "/home/***/.local/lib/python3.7/site-packages/dagster/_core/executor/in_process.py", line 50, in execute
[2022-12-20T10:02:06.939+0000] {subprocess.py:93} INFO -     output_capture=plan_context.output_capture,
[2022-12-20T10:02:06.940+0000] {subprocess.py:93} INFO -   File "/home/***/.local/lib/python3.7/site-packages/dagster/_core/execution/api.py", line 1192, in __iter__
[2022-12-20T10:02:06.957+0000] {subprocess.py:93} INFO -     pipeline_context=self.pipeline_context,
[2022-12-20T10:02:06.958+0000] {subprocess.py:93} INFO -   File "/home/***/.local/lib/python3.7/site-packages/dagster/_core/execution/plan/execute_plan.py", line 115, in inner_plan_execution_iterator
[2022-12-20T10:02:06.960+0000] {subprocess.py:93} INFO -     dagster_event_sequence_for_step(step_context)
[2022-12-20T10:02:06.962+0000] {subprocess.py:93} INFO -   File "/home/***/.local/lib/python3.7/site-packages/dagster/_core/execution/plan/execute_plan.py", line 340, in dagster_event_sequence_for_step
[2022-12-20T10:02:06.963+0000] {subprocess.py:93} INFO -     raise dagster_user_error.user_exception
[2022-12-20T10:02:06.965+0000] {subprocess.py:93} INFO -   File "/home/***/.local/lib/python3.7/site-packages/dagster/_core/execution/plan/utils.py", line 56, in op_execution_error_boundary
[2022-12-20T10:02:06.966+0000] {subprocess.py:93} INFO -     yield
[2022-12-20T10:02:06.970+0000] {subprocess.py:93} INFO -   File "/home/***/.local/lib/python3.7/site-packages/dagster/_utils/__init__.py", line 458, in iterate_with_context
[2022-12-20T10:02:06.971+0000] {subprocess.py:93} INFO -     next_output = next(iterator)
[2022-12-20T10:02:06.972+0000] {subprocess.py:93} INFO -   File "/home/***/.local/lib/python3.7/site-packages/dagster/_core/execution/plan/compute_generator.py", line 75, in _coerce_solid_compute_fn_to_iterator
[2022-12-20T10:02:06.973+0000] {subprocess.py:93} INFO -     result = fn(context, **kwargs) if context_arg_provided else fn(**kwargs)
[2022-12-20T10:02:06.974+0000] {subprocess.py:93} INFO -   File "/opt/***/tasks/data_cleansing_basic_stat.py", line 42, in data_validation
[2022-12-20T10:02:06.975+0000] {subprocess.py:93} INFO -     result = schema.validate(df,lazy=True)
[2022-12-20T10:02:06.976+0000] {subprocess.py:93} INFO -   File "/home/***/.local/lib/python3.7/site-packages/pandera/schemas.py", line 541, in validate
[2022-12-20T10:02:06.977+0000] {subprocess.py:93} INFO -     inplace=inplace,
[2022-12-20T10:02:06.978+0000] {subprocess.py:93} INFO -   File "/home/***/.local/lib/python3.7/site-packages/pandera/schemas.py", line 795, in _validate
[2022-12-20T10:02:06.979+0000] {subprocess.py:93} INFO -     self, error_handler.collected_errors, check_obj
[2022-12-20T10:02:06.980+0000] {subprocess.py:93} INFO - 
[2022-12-20T10:02:06.981+0000] {subprocess.py:93} INFO - Traceback (most recent call last):
[2022-12-20T10:02:06.982+0000] {subprocess.py:93} INFO -   File "/home/***/.local/lib/python3.7/site-packages/dagster/_core/execution/plan/execute_plan.py", line 266, in dagster_event_sequence_for_step
[2022-12-20T10:02:06.983+0000] {subprocess.py:93} INFO -     for step_event in check.generator(step_events):
[2022-12-20T10:02:06.983+0000] {subprocess.py:93} INFO -   File "/home/***/.local/lib/python3.7/site-packages/dagster/_core/execution/plan/execute_step.py", line 389, in core_dagster_event_sequence_for_step
[2022-12-20T10:02:06.985+0000] {subprocess.py:93} INFO -     _step_output_error_checked_user_event_sequence(step_context, user_event_sequence)
[2022-12-20T10:02:06.985+0000] {subprocess.py:93} INFO -   File "/home/***/.local/lib/python3.7/site-packages/dagster/_core/execution/plan/execute_step.py", line 94, in _step_output_error_checked_user_event_sequence
[2022-12-20T10:02:06.986+0000] {subprocess.py:93} INFO -     for user_event in user_event_sequence:
[2022-12-20T10:02:06.987+0000] {subprocess.py:93} INFO -   File "/home/***/.local/lib/python3.7/site-packages/dagster/_core/execution/plan/compute.py", line 177, in execute_core_compute
[2022-12-20T10:02:06.989+0000] {subprocess.py:93} INFO -     for step_output in _yield_compute_results(step_context, inputs, compute_fn):
[2022-12-20T10:02:06.990+0000] {subprocess.py:93} INFO -   File "/home/***/.local/lib/python3.7/site-packages/dagster/_core/execution/plan/compute.py", line 154, in _yield_compute_results
[2022-12-20T10:02:06.992+0000] {subprocess.py:93} INFO -     user_event_generator,
[2022-12-20T10:02:06.993+0000] {subprocess.py:93} INFO -   File "/home/***/.local/lib/python3.7/site-packages/dagster/_utils/__init__.py", line 460, in iterate_with_context
[2022-12-20T10:02:06.994+0000] {subprocess.py:93} INFO -     return
[2022-12-20T10:02:07.010+0000] {subprocess.py:93} INFO -   File "/usr/local/lib/python3.7/contextlib.py", line 130, in __exit__
[2022-12-20T10:02:07.012+0000] {subprocess.py:93} INFO -     self.gen.throw(type, value, traceback)
[2022-12-20T10:02:07.013+0000] {subprocess.py:93} INFO -   File "/home/***/.local/lib/python3.7/site-packages/dagster/_core/execution/plan/utils.py", line 91, in op_execution_error_boundary
[2022-12-20T10:02:07.014+0000] {subprocess.py:93} INFO -     ) from e
[2022-12-20T10:02:07.015+0000] {subprocess.py:93} INFO - dagster._core.errors.DagsterExecutionStepExecutionError: Error occurred while executing op "data_validation":
[2022-12-20T10:02:07.017+0000] {subprocess.py:93} INFO - 
[2022-12-20T10:02:07.018+0000] {subprocess.py:93} INFO - During handling of the above exception, another exception occurred:
[2022-12-20T10:02:07.019+0000] {subprocess.py:93} INFO - 
[2022-12-20T10:02:07.021+0000] {subprocess.py:93} INFO - Traceback (most recent call last):
[2022-12-20T10:02:07.024+0000] {subprocess.py:93} INFO -   File "/opt/***/tasks/data_cleansing_basic_stat.py", line 95, in <module>
[2022-12-20T10:02:07.026+0000] {subprocess.py:93} INFO -     result = data_cleansing_whole_job.execute_in_process()
[2022-12-20T10:02:07.030+0000] {subprocess.py:93} INFO -   File "/home/***/.local/lib/python3.7/site-packages/dagster/_core/definitions/job_definition.py", line 394, in execute_in_process
[2022-12-20T10:02:07.037+0000] {subprocess.py:93} INFO -     asset_selection=frozenset(asset_selection),
[2022-12-20T10:02:07.038+0000] {subprocess.py:93} INFO -   File "/home/***/.local/lib/python3.7/site-packages/dagster/_core/execution/execute_in_process.py", line 77, in core_execute_in_process
[2022-12-20T10:02:07.041+0000] {subprocess.py:93} INFO -     event_list = list(execute_run_iterable)
[2022-12-20T10:02:07.044+0000] {subprocess.py:93} INFO -   File "/home/***/.local/lib/python3.7/site-packages/dagster/_core/execution/api.py", line 1192, in __iter__
[2022-12-20T10:02:07.045+0000] {subprocess.py:93} INFO -     pipeline_context=self.pipeline_context,
[2022-12-20T10:02:07.046+0000] {subprocess.py:93} INFO -   File "/home/***/.local/lib/python3.7/site-packages/dagster/_core/execution/api.py", line 1089, in pipeline_execution_iterator
[2022-12-20T10:02:07.047+0000] {subprocess.py:93} INFO -     for event in pipeline_context.executor.execute(pipeline_context, execution_plan):
[2022-12-20T10:02:07.048+0000] {subprocess.py:93} INFO -   File "/home/***/.local/lib/python3.7/site-packages/dagster/_core/executor/in_process.py", line 50, in execute
[2022-12-20T10:02:07.050+0000] {subprocess.py:93} INFO -     output_capture=plan_context.output_capture,
[2022-12-20T10:02:07.051+0000] {subprocess.py:93} INFO -   File "/home/***/.local/lib/python3.7/site-packages/dagster/_core/execution/api.py", line 1192, in __iter__
[2022-12-20T10:02:07.052+0000] {subprocess.py:93} INFO -     pipeline_context=self.pipeline_context,
[2022-12-20T10:02:07.063+0000] {subprocess.py:93} INFO -   File "/home/***/.local/lib/python3.7/site-packages/dagster/_core/execution/plan/execute_plan.py", line 115, in inner_plan_execution_iterator
[2022-12-20T10:02:07.067+0000] {subprocess.py:93} INFO -     dagster_event_sequence_for_step(step_context)
[2022-12-20T10:02:07.069+0000] {subprocess.py:93} INFO -   File "/home/***/.local/lib/python3.7/site-packages/dagster/_core/execution/plan/execute_plan.py", line 340, in dagster_event_sequence_for_step
[2022-12-20T10:02:07.079+0000] {subprocess.py:93} INFO -     raise dagster_user_error.user_exception
[2022-12-20T10:02:07.080+0000] {subprocess.py:93} INFO -   File "/home/***/.local/lib/python3.7/site-packages/dagster/_core/execution/plan/utils.py", line 56, in op_execution_error_boundary
[2022-12-20T10:02:07.080+0000] {subprocess.py:93} INFO -     yield
[2022-12-20T10:02:07.082+0000] {subprocess.py:93} INFO -   File "/home/***/.local/lib/python3.7/site-packages/dagster/_utils/__init__.py", line 458, in iterate_with_context
[2022-12-20T10:02:07.083+0000] {subprocess.py:93} INFO -     next_output = next(iterator)
[2022-12-20T10:02:07.086+0000] {subprocess.py:93} INFO -   File "/home/***/.local/lib/python3.7/site-packages/dagster/_core/execution/plan/compute_generator.py", line 75, in _coerce_solid_compute_fn_to_iterator
[2022-12-20T10:02:07.087+0000] {subprocess.py:93} INFO -     result = fn(context, **kwargs) if context_arg_provided else fn(**kwargs)
[2022-12-20T10:02:07.088+0000] {subprocess.py:93} INFO -   File "/opt/***/tasks/data_cleansing_basic_stat.py", line 42, in data_validation
[2022-12-20T10:02:07.089+0000] {subprocess.py:93} INFO -     result = schema.validate(df,lazy=True)
[2022-12-20T10:02:07.090+0000] {subprocess.py:93} INFO -   File "/home/***/.local/lib/python3.7/site-packages/pandera/schemas.py", line 541, in validate
[2022-12-20T10:02:07.092+0000] {subprocess.py:93} INFO -     inplace=inplace,
[2022-12-20T10:02:07.093+0000] {subprocess.py:93} INFO -   File "/home/***/.local/lib/python3.7/site-packages/pandera/schemas.py", line 795, in _validate
[2022-12-20T10:02:07.093+0000] {subprocess.py:93} INFO -     self, error_handler.collected_errors, check_obj
[2022-12-20T10:02:07.095+0000] {subprocess.py:93} INFO - pandera.errors.SchemaErrors: Schema None: A total of 1 schema errors were found.
[2022-12-20T10:02:07.096+0000] {subprocess.py:93} INFO - 
[2022-12-20T10:02:07.097+0000] {subprocess.py:93} INFO - Error Counts
[2022-12-20T10:02:07.098+0000] {subprocess.py:93} INFO - ------------
[2022-12-20T10:02:07.099+0000] {subprocess.py:93} INFO - - column_not_in_dataframe: 1
[2022-12-20T10:02:07.100+0000] {subprocess.py:93} INFO - 
[2022-12-20T10:02:07.102+0000] {subprocess.py:93} INFO - Schema Error Summary
[2022-12-20T10:02:07.103+0000] {subprocess.py:93} INFO - --------------------
[2022-12-20T10:02:07.104+0000] {subprocess.py:93} INFO -                                            failure_cases  n_failure_cases
[2022-12-20T10:02:07.104+0000] {subprocess.py:93} INFO - schema_context  column check
[2022-12-20T10:02:07.105+0000] {subprocess.py:93} INFO - DataFrameSchema <NA>   column_in_dataframe        [name]                1
[2022-12-20T10:02:07.106+0000] {subprocess.py:93} INFO - 
[2022-12-20T10:02:07.108+0000] {subprocess.py:93} INFO - Usage Tip
[2022-12-20T10:02:07.109+0000] {subprocess.py:93} INFO - ---------
[2022-12-20T10:02:07.111+0000] {subprocess.py:93} INFO - 
[2022-12-20T10:02:07.113+0000] {subprocess.py:93} INFO - Directly inspect all errors by catching the exception:
[2022-12-20T10:02:07.114+0000] {subprocess.py:93} INFO - 
[2022-12-20T10:02:07.115+0000] {subprocess.py:93} INFO - ```
[2022-12-20T10:02:07.116+0000] {subprocess.py:93} INFO - try:
[2022-12-20T10:02:07.117+0000] {subprocess.py:93} INFO -     schema.validate(dataframe, lazy=True)
[2022-12-20T10:02:07.118+0000] {subprocess.py:93} INFO - except SchemaErrors as err:
[2022-12-20T10:02:07.118+0000] {subprocess.py:93} INFO -     err.failure_cases  # dataframe of schema errors
[2022-12-20T10:02:07.119+0000] {subprocess.py:93} INFO -     err.data  # invalid dataframe
[2022-12-20T10:02:07.120+0000] {subprocess.py:93} INFO - ```
[2022-12-20T10:02:07.120+0000] {subprocess.py:93} INFO - 
[2022-12-20T10:02:07.146+0000] {subprocess.py:97} INFO - Command exited with return code 1
[2022-12-20T10:02:07.321+0000] {taskinstance.py:1772} ERROR - Task failed with exception
Traceback (most recent call last):
  File "/home/airflow/.local/lib/python3.7/site-packages/airflow/operators/bash.py", line 197, in execute
    f"Bash command failed. The command returned a non-zero exit code {result.exit_code}."
airflow.exceptions.AirflowException: Bash command failed. The command returned a non-zero exit code 1.
[2022-12-20T10:02:07.365+0000] {taskinstance.py:1327} INFO - Marking task as FAILED. dag_id=Can_I_change_name_to_this, task_id=basic_data_cleansing, execution_date=20221219T100000, start_date=20221220T100130, end_date=20221220T100207
[2022-12-20T10:02:07.483+0000] {standard_task_runner.py:105} ERROR - Failed to execute job 167 for task basic_data_cleansing (Bash command failed. The command returned a non-zero exit code 1.; 2804)
[2022-12-20T10:02:07.643+0000] {local_task_job.py:159} INFO - Task exited with return code 1
[2022-12-20T10:02:07.803+0000] {taskinstance.py:2582} INFO - 0 downstream tasks scheduled from follow-on schedule check
