[2022-11-28T02:31:39.563+0000] {taskinstance.py:1165} INFO - Dependencies all met for <TaskInstance: Can_I_change_name_to_this.task_2 scheduled__2022-11-27T00:00:00+00:00 [queued]>
[2022-11-28T02:31:39.578+0000] {taskinstance.py:1165} INFO - Dependencies all met for <TaskInstance: Can_I_change_name_to_this.task_2 scheduled__2022-11-27T00:00:00+00:00 [queued]>
[2022-11-28T02:31:39.580+0000] {taskinstance.py:1362} INFO - 
--------------------------------------------------------------------------------
[2022-11-28T02:31:39.581+0000] {taskinstance.py:1363} INFO - Starting attempt 1 of 1
[2022-11-28T02:31:39.583+0000] {taskinstance.py:1364} INFO - 
--------------------------------------------------------------------------------
[2022-11-28T02:31:39.613+0000] {taskinstance.py:1383} INFO - Executing <Task(BashOperator): task_2> on 2022-11-27 00:00:00+00:00
[2022-11-28T02:31:39.619+0000] {standard_task_runner.py:55} INFO - Started process 181 to run task
[2022-11-28T02:31:39.627+0000] {standard_task_runner.py:82} INFO - Running: ['***', 'tasks', 'run', 'Can_I_change_name_to_this', 'task_2', 'scheduled__2022-11-27T00:00:00+00:00', '--job-id', '2', '--raw', '--subdir', 'DAGS_FOLDER/dags.py', '--cfg-path', '/tmp/tmpw36j9wxt']
[2022-11-28T02:31:39.631+0000] {standard_task_runner.py:83} INFO - Job 2: Subtask task_2
[2022-11-28T02:31:39.735+0000] {task_command.py:376} INFO - Running <TaskInstance: Can_I_change_name_to_this.task_2 scheduled__2022-11-27T00:00:00+00:00 [running]> on host 7667c9be398a
[2022-11-28T02:31:39.848+0000] {taskinstance.py:1592} INFO - Exporting the following env vars:
AIRFLOW_CTX_DAG_OWNER=***
AIRFLOW_CTX_DAG_ID=Can_I_change_name_to_this
AIRFLOW_CTX_TASK_ID=task_2
AIRFLOW_CTX_EXECUTION_DATE=2022-11-27T00:00:00+00:00
AIRFLOW_CTX_TRY_NUMBER=1
AIRFLOW_CTX_DAG_RUN_ID=scheduled__2022-11-27T00:00:00+00:00
[2022-11-28T02:31:39.864+0000] {subprocess.py:63} INFO - Tmp dir root location: 
 /tmp
[2022-11-28T02:31:39.872+0000] {subprocess.py:75} INFO - Running command: ['/bin/bash', '-c', 'python /opt/***s/tasks/lol_champ_counter_stat.py ']
[2022-11-28T02:31:39.908+0000] {subprocess.py:86} INFO - Output:
[2022-11-28T02:31:40.031+0000] {subprocess.py:93} INFO - python: can't open file '/opt/***s/tasks/lol_champ_counter_stat.py': [Errno 2] No such file or directory
[2022-11-28T02:31:40.038+0000] {subprocess.py:97} INFO - Command exited with return code 2
[2022-11-28T02:31:40.063+0000] {taskinstance.py:1851} ERROR - Task failed with exception
Traceback (most recent call last):
  File "/home/airflow/.local/lib/python3.7/site-packages/airflow/operators/bash.py", line 197, in execute
    f'Bash command failed. The command returned a non-zero exit code {result.exit_code}.'
airflow.exceptions.AirflowException: Bash command failed. The command returned a non-zero exit code 2.
[2022-11-28T02:31:40.075+0000] {taskinstance.py:1406} INFO - Marking task as FAILED. dag_id=Can_I_change_name_to_this, task_id=task_2, execution_date=20221127T000000, start_date=20221128T023139, end_date=20221128T023140
[2022-11-28T02:31:40.122+0000] {standard_task_runner.py:105} ERROR - Failed to execute job 2 for task task_2 (Bash command failed. The command returned a non-zero exit code 2.; 181)
[2022-11-28T02:31:40.203+0000] {local_task_job.py:159} INFO - Task exited with return code 1
[2022-11-28T02:31:40.341+0000] {taskinstance.py:2623} INFO - 0 downstream tasks scheduled from follow-on schedule check
