[2022-12-17T02:40:34.727+0000] {taskinstance.py:1165} INFO - Dependencies all met for <TaskInstance: Can_I_change_name_to_this.task_7 manual__2022-12-17T02:39:16.922161+00:00 [queued]>
[2022-12-17T02:40:34.741+0000] {taskinstance.py:1165} INFO - Dependencies all met for <TaskInstance: Can_I_change_name_to_this.task_7 manual__2022-12-17T02:39:16.922161+00:00 [queued]>
[2022-12-17T02:40:34.742+0000] {taskinstance.py:1362} INFO - 
--------------------------------------------------------------------------------
[2022-12-17T02:40:34.743+0000] {taskinstance.py:1363} INFO - Starting attempt 1 of 1
[2022-12-17T02:40:34.744+0000] {taskinstance.py:1364} INFO - 
--------------------------------------------------------------------------------
[2022-12-17T02:40:34.763+0000] {taskinstance.py:1383} INFO - Executing <Task(BashOperator): task_7> on 2022-12-17 02:39:16.922161+00:00
[2022-12-17T02:40:34.775+0000] {standard_task_runner.py:55} INFO - Started process 746 to run task
[2022-12-17T02:40:34.780+0000] {standard_task_runner.py:82} INFO - Running: ['***', 'tasks', 'run', 'Can_I_change_name_to_this', 'task_7', 'manual__2022-12-17T02:39:16.922161+00:00', '--job-id', '65', '--raw', '--subdir', 'DAGS_FOLDER/dags.py', '--cfg-path', '/tmp/tmp3tv0810d']
[2022-12-17T02:40:34.786+0000] {standard_task_runner.py:83} INFO - Job 65: Subtask task_7
[2022-12-17T02:40:34.867+0000] {task_command.py:376} INFO - Running <TaskInstance: Can_I_change_name_to_this.task_7 manual__2022-12-17T02:39:16.922161+00:00 [running]> on host 418b9a9aa3df
[2022-12-17T02:40:34.930+0000] {taskinstance.py:1592} INFO - Exporting the following env vars:
AIRFLOW_CTX_DAG_OWNER=***
AIRFLOW_CTX_DAG_ID=Can_I_change_name_to_this
AIRFLOW_CTX_TASK_ID=task_7
AIRFLOW_CTX_EXECUTION_DATE=2022-12-17T02:39:16.922161+00:00
AIRFLOW_CTX_TRY_NUMBER=1
AIRFLOW_CTX_DAG_RUN_ID=manual__2022-12-17T02:39:16.922161+00:00
[2022-12-17T02:40:34.934+0000] {subprocess.py:63} INFO - Tmp dir root location: 
 /tmp
[2022-12-17T02:40:34.937+0000] {subprocess.py:75} INFO - Running command: ['/bin/bash', '-c', 'python /opt/***/tasks/data_cleansing_counter_stat.py']
[2022-12-17T02:40:34.950+0000] {subprocess.py:86} INFO - Output:
[2022-12-17T02:40:41.941+0000] {subprocess.py:93} INFO - 2022-12-17 02:40:41 +0000 - dagster - DEBUG - counter_stat_job - e4915a06-a390-42b8-9098-3d35bf673cbe - 748 - RUN_START - Started execution of run for "counter_stat_job".
[2022-12-17T02:40:41.957+0000] {subprocess.py:93} INFO - 2022-12-17 02:40:41 +0000 - dagster - DEBUG - counter_stat_job - e4915a06-a390-42b8-9098-3d35bf673cbe - 748 - ENGINE_EVENT - Executing steps in process (pid: 748)
[2022-12-17T02:40:41.960+0000] {subprocess.py:93} INFO - 2022-12-17 02:40:41 +0000 - dagster - DEBUG - counter_stat_job - e4915a06-a390-42b8-9098-3d35bf673cbe - 748 - RESOURCE_INIT_STARTED - Starting initialization of resources [io_manager].
[2022-12-17T02:40:41.961+0000] {subprocess.py:93} INFO - 2022-12-17 02:40:41 +0000 - dagster - DEBUG - counter_stat_job - e4915a06-a390-42b8-9098-3d35bf673cbe - 748 - RESOURCE_INIT_SUCCESS - Finished initialization of resources [io_manager].
[2022-12-17T02:40:41.962+0000] {subprocess.py:93} INFO - 2022-12-17 02:40:41 +0000 - dagster - DEBUG - counter_stat_job - e4915a06-a390-42b8-9098-3d35bf673cbe - 748 - LOGS_CAPTURED - Started capturing logs in process (pid: 748).
[2022-12-17T02:40:41.963+0000] {subprocess.py:93} INFO - 2022-12-17 02:40:41 +0000 - dagster - DEBUG - counter_stat_job - e4915a06-a390-42b8-9098-3d35bf673cbe - 748 - read_json - STEP_START - Started execution of step "read_json".
[2022-12-17T02:40:42.261+0000] {subprocess.py:93} INFO - 2022-12-17 02:40:42 +0000 - dagster - ERROR - counter_stat_job - e4915a06-a390-42b8-9098-3d35bf673cbe - 748 - read_json - STEP_FAILURE - Execution of step "read_json" failed.
[2022-12-17T02:40:42.267+0000] {subprocess.py:93} INFO - 
[2022-12-17T02:40:42.274+0000] {subprocess.py:93} INFO - dagster._core.errors.DagsterExecutionStepExecutionError: Error occurred while executing op "read_json"::
[2022-12-17T02:40:42.275+0000] {subprocess.py:93} INFO - 
[2022-12-17T02:40:42.279+0000] {subprocess.py:93} INFO - ValueError: Expected object or value
[2022-12-17T02:40:42.285+0000] {subprocess.py:93} INFO - 
[2022-12-17T02:40:42.287+0000] {subprocess.py:93} INFO - Stack Trace:
[2022-12-17T02:40:42.293+0000] {subprocess.py:93} INFO -   File "/home/***/.local/lib/python3.7/site-packages/dagster/_core/execution/plan/utils.py", line 47, in solid_execution_error_boundary
[2022-12-17T02:40:42.306+0000] {subprocess.py:93} INFO -     yield
[2022-12-17T02:40:42.309+0000] {subprocess.py:93} INFO -   File "/home/***/.local/lib/python3.7/site-packages/dagster/_utils/__init__.py", line 447, in iterate_with_context
[2022-12-17T02:40:42.313+0000] {subprocess.py:93} INFO -     next_output = next(iterator)
[2022-12-17T02:40:42.315+0000] {subprocess.py:93} INFO -   File "/home/***/.local/lib/python3.7/site-packages/dagster/_core/execution/plan/compute_generator.py", line 74, in _coerce_solid_compute_fn_to_iterator
[2022-12-17T02:40:42.318+0000] {subprocess.py:93} INFO -     result = fn(context, **kwargs) if context_arg_provided else fn(**kwargs)
[2022-12-17T02:40:42.319+0000] {subprocess.py:93} INFO -   File "/opt/***/tasks/data_cleansing_counter_stat.py", line 20, in read_json
[2022-12-17T02:40:42.322+0000] {subprocess.py:93} INFO -     df = pd.read_json("./***/zone1/lol_counter_stat.json",lines=True)
[2022-12-17T02:40:42.323+0000] {subprocess.py:93} INFO -   File "/home/***/.local/lib/python3.7/site-packages/pandas/util/_decorators.py", line 207, in wrapper
[2022-12-17T02:40:42.324+0000] {subprocess.py:93} INFO -     return func(*args, **kwargs)
[2022-12-17T02:40:42.326+0000] {subprocess.py:93} INFO -   File "/home/***/.local/lib/python3.7/site-packages/pandas/util/_decorators.py", line 311, in wrapper
[2022-12-17T02:40:42.328+0000] {subprocess.py:93} INFO -     return func(*args, **kwargs)
[2022-12-17T02:40:42.330+0000] {subprocess.py:93} INFO -   File "/home/***/.local/lib/python3.7/site-packages/pandas/io/json/_json.py", line 614, in read_json
[2022-12-17T02:40:42.333+0000] {subprocess.py:93} INFO -     return json_reader.read()
[2022-12-17T02:40:42.337+0000] {subprocess.py:93} INFO -   File "/home/***/.local/lib/python3.7/site-packages/pandas/io/json/_json.py", line 746, in read
[2022-12-17T02:40:42.339+0000] {subprocess.py:93} INFO -     obj = self._get_object_parser(self._combine_lines(data_lines))
[2022-12-17T02:40:42.341+0000] {subprocess.py:93} INFO -   File "/home/***/.local/lib/python3.7/site-packages/pandas/io/json/_json.py", line 770, in _get_object_parser
[2022-12-17T02:40:42.343+0000] {subprocess.py:93} INFO -     obj = FrameParser(json, **kwargs).parse()
[2022-12-17T02:40:42.344+0000] {subprocess.py:93} INFO -   File "/home/***/.local/lib/python3.7/site-packages/pandas/io/json/_json.py", line 885, in parse
[2022-12-17T02:40:42.347+0000] {subprocess.py:93} INFO -     self._parse_no_numpy()
[2022-12-17T02:40:42.348+0000] {subprocess.py:93} INFO -   File "/home/***/.local/lib/python3.7/site-packages/pandas/io/json/_json.py", line 1140, in _parse_no_numpy
[2022-12-17T02:40:42.349+0000] {subprocess.py:93} INFO -     loads(json, precise_float=self.precise_float), dtype=None
[2022-12-17T02:40:42.352+0000] {subprocess.py:93} INFO - 
[2022-12-17T02:40:42.353+0000] {subprocess.py:93} INFO - 2022-12-17 02:40:42 +0000 - dagster - ERROR - counter_stat_job - e4915a06-a390-42b8-9098-3d35bf673cbe - 748 - RUN_FAILURE - Execution of run for "counter_stat_job" failed. An exception was thrown during execution.
[2022-12-17T02:40:42.357+0000] {subprocess.py:93} INFO - 
[2022-12-17T02:40:42.359+0000] {subprocess.py:93} INFO - ValueError: Expected object or value
[2022-12-17T02:40:42.361+0000] {subprocess.py:93} INFO - 
[2022-12-17T02:40:42.371+0000] {subprocess.py:93} INFO - Stack Trace:
[2022-12-17T02:40:42.374+0000] {subprocess.py:93} INFO -   File "/home/***/.local/lib/python3.7/site-packages/dagster/_core/execution/api.py", line 1091, in pipeline_execution_iterator
[2022-12-17T02:40:42.375+0000] {subprocess.py:93} INFO -     for event in pipeline_context.executor.execute(pipeline_context, execution_plan):
[2022-12-17T02:40:42.377+0000] {subprocess.py:93} INFO -   File "/home/***/.local/lib/python3.7/site-packages/dagster/_core/executor/in_process.py", line 50, in execute
[2022-12-17T02:40:42.378+0000] {subprocess.py:93} INFO -     output_capture=plan_context.output_capture,
[2022-12-17T02:40:42.379+0000] {subprocess.py:93} INFO -   File "/home/***/.local/lib/python3.7/site-packages/dagster/_core/execution/api.py", line 1189, in __iter__
[2022-12-17T02:40:42.380+0000] {subprocess.py:93} INFO -     pipeline_context=self.pipeline_context,
[2022-12-17T02:40:42.381+0000] {subprocess.py:93} INFO -   File "/home/***/.local/lib/python3.7/site-packages/dagster/_core/execution/plan/execute_plan.py", line 121, in inner_plan_execution_iterator
[2022-12-17T02:40:42.382+0000] {subprocess.py:93} INFO -     dagster_event_sequence_for_step(step_context)
[2022-12-17T02:40:42.383+0000] {subprocess.py:93} INFO -   File "/home/***/.local/lib/python3.7/site-packages/dagster/_core/execution/plan/execute_plan.py", line 325, in dagster_event_sequence_for_step
[2022-12-17T02:40:42.384+0000] {subprocess.py:93} INFO -     raise dagster_user_error.user_exception
[2022-12-17T02:40:42.385+0000] {subprocess.py:93} INFO -   File "/home/***/.local/lib/python3.7/site-packages/dagster/_core/execution/plan/utils.py", line 47, in solid_execution_error_boundary
[2022-12-17T02:40:42.387+0000] {subprocess.py:93} INFO -     yield
[2022-12-17T02:40:42.388+0000] {subprocess.py:93} INFO -   File "/home/***/.local/lib/python3.7/site-packages/dagster/_utils/__init__.py", line 447, in iterate_with_context
[2022-12-17T02:40:42.389+0000] {subprocess.py:93} INFO -     next_output = next(iterator)
[2022-12-17T02:40:42.389+0000] {subprocess.py:93} INFO -   File "/home/***/.local/lib/python3.7/site-packages/dagster/_core/execution/plan/compute_generator.py", line 74, in _coerce_solid_compute_fn_to_iterator
[2022-12-17T02:40:42.390+0000] {subprocess.py:93} INFO -     result = fn(context, **kwargs) if context_arg_provided else fn(**kwargs)
[2022-12-17T02:40:42.392+0000] {subprocess.py:93} INFO -   File "/opt/***/tasks/data_cleansing_counter_stat.py", line 20, in read_json
[2022-12-17T02:40:42.393+0000] {subprocess.py:93} INFO -     df = pd.read_json("./***/zone1/lol_counter_stat.json",lines=True)
[2022-12-17T02:40:42.393+0000] {subprocess.py:93} INFO -   File "/home/***/.local/lib/python3.7/site-packages/pandas/util/_decorators.py", line 207, in wrapper
[2022-12-17T02:40:42.394+0000] {subprocess.py:93} INFO -     return func(*args, **kwargs)
[2022-12-17T02:40:42.395+0000] {subprocess.py:93} INFO -   File "/home/***/.local/lib/python3.7/site-packages/pandas/util/_decorators.py", line 311, in wrapper
[2022-12-17T02:40:42.396+0000] {subprocess.py:93} INFO -     return func(*args, **kwargs)
[2022-12-17T02:40:42.397+0000] {subprocess.py:93} INFO -   File "/home/***/.local/lib/python3.7/site-packages/pandas/io/json/_json.py", line 614, in read_json
[2022-12-17T02:40:42.398+0000] {subprocess.py:93} INFO -     return json_reader.read()
[2022-12-17T02:40:42.399+0000] {subprocess.py:93} INFO -   File "/home/***/.local/lib/python3.7/site-packages/pandas/io/json/_json.py", line 746, in read
[2022-12-17T02:40:42.400+0000] {subprocess.py:93} INFO -     obj = self._get_object_parser(self._combine_lines(data_lines))
[2022-12-17T02:40:42.401+0000] {subprocess.py:93} INFO -   File "/home/***/.local/lib/python3.7/site-packages/pandas/io/json/_json.py", line 770, in _get_object_parser
[2022-12-17T02:40:42.401+0000] {subprocess.py:93} INFO -     obj = FrameParser(json, **kwargs).parse()
[2022-12-17T02:40:42.402+0000] {subprocess.py:93} INFO -   File "/home/***/.local/lib/python3.7/site-packages/pandas/io/json/_json.py", line 885, in parse
[2022-12-17T02:40:42.403+0000] {subprocess.py:93} INFO -     self._parse_no_numpy()
[2022-12-17T02:40:42.405+0000] {subprocess.py:93} INFO -   File "/home/***/.local/lib/python3.7/site-packages/pandas/io/json/_json.py", line 1140, in _parse_no_numpy
[2022-12-17T02:40:42.407+0000] {subprocess.py:93} INFO -     loads(json, precise_float=self.precise_float), dtype=None
[2022-12-17T02:40:42.408+0000] {subprocess.py:93} INFO - 
[2022-12-17T02:40:42.409+0000] {subprocess.py:93} INFO - Traceback (most recent call last):
[2022-12-17T02:40:42.410+0000] {subprocess.py:93} INFO -   File "/home/***/.local/lib/python3.7/site-packages/dagster/_core/execution/plan/execute_plan.py", line 251, in dagster_event_sequence_for_step
[2022-12-17T02:40:42.411+0000] {subprocess.py:93} INFO -     for step_event in check.generator(step_events):
[2022-12-17T02:40:42.411+0000] {subprocess.py:93} INFO -   File "/home/***/.local/lib/python3.7/site-packages/dagster/_core/execution/plan/execute_step.py", line 390, in core_dagster_event_sequence_for_step
[2022-12-17T02:40:42.412+0000] {subprocess.py:93} INFO -     _step_output_error_checked_user_event_sequence(step_context, user_event_sequence)
[2022-12-17T02:40:42.413+0000] {subprocess.py:93} INFO -   File "/home/***/.local/lib/python3.7/site-packages/dagster/_core/execution/plan/execute_step.py", line 95, in _step_output_error_checked_user_event_sequence
[2022-12-17T02:40:42.414+0000] {subprocess.py:93} INFO -     for user_event in user_event_sequence:
[2022-12-17T02:40:42.414+0000] {subprocess.py:93} INFO -   File "/home/***/.local/lib/python3.7/site-packages/dagster/_core/execution/plan/compute.py", line 174, in execute_core_compute
[2022-12-17T02:40:42.415+0000] {subprocess.py:93} INFO -     for step_output in _yield_compute_results(step_context, inputs, compute_fn):
[2022-12-17T02:40:42.416+0000] {subprocess.py:93} INFO -   File "/home/***/.local/lib/python3.7/site-packages/dagster/_core/execution/plan/compute.py", line 151, in _yield_compute_results
[2022-12-17T02:40:42.420+0000] {subprocess.py:93} INFO -     user_event_generator,
[2022-12-17T02:40:42.421+0000] {subprocess.py:93} INFO -   File "/home/***/.local/lib/python3.7/site-packages/dagster/_utils/__init__.py", line 449, in iterate_with_context
[2022-12-17T02:40:42.422+0000] {subprocess.py:93} INFO -     return
[2022-12-17T02:40:42.423+0000] {subprocess.py:93} INFO -   File "/usr/local/lib/python3.7/contextlib.py", line 130, in __exit__
[2022-12-17T02:40:42.424+0000] {subprocess.py:93} INFO -     self.gen.throw(type, value, traceback)
[2022-12-17T02:40:42.425+0000] {subprocess.py:93} INFO -   File "/home/***/.local/lib/python3.7/site-packages/dagster/_core/execution/plan/utils.py", line 82, in solid_execution_error_boundary
[2022-12-17T02:40:42.426+0000] {subprocess.py:93} INFO -     ) from e
[2022-12-17T02:40:42.427+0000] {subprocess.py:93} INFO - dagster._core.errors.DagsterExecutionStepExecutionError: Error occurred while executing op "read_json":
[2022-12-17T02:40:42.428+0000] {subprocess.py:93} INFO - 
[2022-12-17T02:40:42.429+0000] {subprocess.py:93} INFO - During handling of the above exception, another exception occurred:
[2022-12-17T02:40:42.430+0000] {subprocess.py:93} INFO - 
[2022-12-17T02:40:42.432+0000] {subprocess.py:93} INFO - Traceback (most recent call last):
[2022-12-17T02:40:42.433+0000] {subprocess.py:93} INFO -   File "/opt/***/tasks/data_cleansing_counter_stat.py", line 75, in <module>
[2022-12-17T02:40:42.434+0000] {subprocess.py:93} INFO -     result = counter_stat_job.execute_in_process()
[2022-12-17T02:40:42.435+0000] {subprocess.py:93} INFO -   File "/home/***/.local/lib/python3.7/site-packages/dagster/_core/definitions/job_definition.py", line 395, in execute_in_process
[2022-12-17T02:40:42.436+0000] {subprocess.py:93} INFO -     asset_selection=frozenset(asset_selection),
[2022-12-17T02:40:42.436+0000] {subprocess.py:93} INFO -   File "/home/***/.local/lib/python3.7/site-packages/dagster/_core/execution/execute_in_process.py", line 77, in core_execute_in_process
[2022-12-17T02:40:42.438+0000] {subprocess.py:93} INFO -     event_list = list(execute_run_iterable)
[2022-12-17T02:40:42.439+0000] {subprocess.py:93} INFO -   File "/home/***/.local/lib/python3.7/site-packages/dagster/_core/execution/api.py", line 1189, in __iter__
[2022-12-17T02:40:42.440+0000] {subprocess.py:93} INFO -     pipeline_context=self.pipeline_context,
[2022-12-17T02:40:42.441+0000] {subprocess.py:93} INFO -   File "/home/***/.local/lib/python3.7/site-packages/dagster/_core/execution/api.py", line 1091, in pipeline_execution_iterator
[2022-12-17T02:40:42.442+0000] {subprocess.py:93} INFO -     for event in pipeline_context.executor.execute(pipeline_context, execution_plan):
[2022-12-17T02:40:42.442+0000] {subprocess.py:93} INFO -   File "/home/***/.local/lib/python3.7/site-packages/dagster/_core/executor/in_process.py", line 50, in execute
[2022-12-17T02:40:42.443+0000] {subprocess.py:93} INFO -     output_capture=plan_context.output_capture,
[2022-12-17T02:40:42.444+0000] {subprocess.py:93} INFO -   File "/home/***/.local/lib/python3.7/site-packages/dagster/_core/execution/api.py", line 1189, in __iter__
[2022-12-17T02:40:42.445+0000] {subprocess.py:93} INFO -     pipeline_context=self.pipeline_context,
[2022-12-17T02:40:42.446+0000] {subprocess.py:93} INFO -   File "/home/***/.local/lib/python3.7/site-packages/dagster/_core/execution/plan/execute_plan.py", line 121, in inner_plan_execution_iterator
[2022-12-17T02:40:42.447+0000] {subprocess.py:93} INFO -     dagster_event_sequence_for_step(step_context)
[2022-12-17T02:40:42.448+0000] {subprocess.py:93} INFO -   File "/home/***/.local/lib/python3.7/site-packages/dagster/_core/execution/plan/execute_plan.py", line 325, in dagster_event_sequence_for_step
[2022-12-17T02:40:42.449+0000] {subprocess.py:93} INFO -     raise dagster_user_error.user_exception
[2022-12-17T02:40:42.450+0000] {subprocess.py:93} INFO -   File "/home/***/.local/lib/python3.7/site-packages/dagster/_core/execution/plan/utils.py", line 47, in solid_execution_error_boundary
[2022-12-17T02:40:42.451+0000] {subprocess.py:93} INFO -     yield
[2022-12-17T02:40:42.452+0000] {subprocess.py:93} INFO -   File "/home/***/.local/lib/python3.7/site-packages/dagster/_utils/__init__.py", line 447, in iterate_with_context
[2022-12-17T02:40:42.453+0000] {subprocess.py:93} INFO -     next_output = next(iterator)
[2022-12-17T02:40:42.453+0000] {subprocess.py:93} INFO -   File "/home/***/.local/lib/python3.7/site-packages/dagster/_core/execution/plan/compute_generator.py", line 74, in _coerce_solid_compute_fn_to_iterator
[2022-12-17T02:40:42.454+0000] {subprocess.py:93} INFO -     result = fn(context, **kwargs) if context_arg_provided else fn(**kwargs)
[2022-12-17T02:40:42.454+0000] {subprocess.py:93} INFO -   File "/opt/***/tasks/data_cleansing_counter_stat.py", line 20, in read_json
[2022-12-17T02:40:42.455+0000] {subprocess.py:93} INFO -     df = pd.read_json("./***/zone1/lol_counter_stat.json",lines=True)
[2022-12-17T02:40:42.456+0000] {subprocess.py:93} INFO -   File "/home/***/.local/lib/python3.7/site-packages/pandas/util/_decorators.py", line 207, in wrapper
[2022-12-17T02:40:42.456+0000] {subprocess.py:93} INFO -     return func(*args, **kwargs)
[2022-12-17T02:40:42.457+0000] {subprocess.py:93} INFO -   File "/home/***/.local/lib/python3.7/site-packages/pandas/util/_decorators.py", line 311, in wrapper
[2022-12-17T02:40:42.457+0000] {subprocess.py:93} INFO -     return func(*args, **kwargs)
[2022-12-17T02:40:42.458+0000] {subprocess.py:93} INFO -   File "/home/***/.local/lib/python3.7/site-packages/pandas/io/json/_json.py", line 614, in read_json
[2022-12-17T02:40:42.459+0000] {subprocess.py:93} INFO -     return json_reader.read()
[2022-12-17T02:40:42.459+0000] {subprocess.py:93} INFO -   File "/home/***/.local/lib/python3.7/site-packages/pandas/io/json/_json.py", line 746, in read
[2022-12-17T02:40:42.460+0000] {subprocess.py:93} INFO -     obj = self._get_object_parser(self._combine_lines(data_lines))
[2022-12-17T02:40:42.461+0000] {subprocess.py:93} INFO -   File "/home/***/.local/lib/python3.7/site-packages/pandas/io/json/_json.py", line 770, in _get_object_parser
[2022-12-17T02:40:42.461+0000] {subprocess.py:93} INFO -     obj = FrameParser(json, **kwargs).parse()
[2022-12-17T02:40:42.462+0000] {subprocess.py:93} INFO -   File "/home/***/.local/lib/python3.7/site-packages/pandas/io/json/_json.py", line 885, in parse
[2022-12-17T02:40:42.463+0000] {subprocess.py:93} INFO -     self._parse_no_numpy()
[2022-12-17T02:40:42.463+0000] {subprocess.py:93} INFO -   File "/home/***/.local/lib/python3.7/site-packages/pandas/io/json/_json.py", line 1140, in _parse_no_numpy
[2022-12-17T02:40:42.464+0000] {subprocess.py:93} INFO -     loads(json, precise_float=self.precise_float), dtype=None
[2022-12-17T02:40:42.465+0000] {subprocess.py:93} INFO - ValueError: Expected object or value
[2022-12-17T02:40:42.673+0000] {subprocess.py:97} INFO - Command exited with return code 1
[2022-12-17T02:40:42.742+0000] {taskinstance.py:1851} ERROR - Task failed with exception
Traceback (most recent call last):
  File "/home/airflow/.local/lib/python3.7/site-packages/airflow/operators/bash.py", line 197, in execute
    f'Bash command failed. The command returned a non-zero exit code {result.exit_code}.'
airflow.exceptions.AirflowException: Bash command failed. The command returned a non-zero exit code 1.
[2022-12-17T02:40:42.821+0000] {taskinstance.py:1406} INFO - Marking task as FAILED. dag_id=Can_I_change_name_to_this, task_id=task_7, execution_date=20221217T023916, start_date=20221217T024034, end_date=20221217T024042
[2022-12-17T02:40:42.849+0000] {standard_task_runner.py:105} ERROR - Failed to execute job 65 for task task_7 (Bash command failed. The command returned a non-zero exit code 1.; 746)
[2022-12-17T02:40:42.940+0000] {local_task_job.py:159} INFO - Task exited with return code 1
[2022-12-17T02:40:42.994+0000] {taskinstance.py:2623} INFO - 0 downstream tasks scheduled from follow-on schedule check
