[2022-12-17T02:40:32.007+0000] {taskinstance.py:1165} INFO - Dependencies all met for <TaskInstance: Can_I_change_name_to_this.task_5 manual__2022-12-17T02:39:16.922161+00:00 [queued]>
[2022-12-17T02:40:32.044+0000] {taskinstance.py:1165} INFO - Dependencies all met for <TaskInstance: Can_I_change_name_to_this.task_5 manual__2022-12-17T02:39:16.922161+00:00 [queued]>
[2022-12-17T02:40:32.046+0000] {taskinstance.py:1362} INFO - 
--------------------------------------------------------------------------------
[2022-12-17T02:40:32.049+0000] {taskinstance.py:1363} INFO - Starting attempt 1 of 1
[2022-12-17T02:40:32.051+0000] {taskinstance.py:1364} INFO - 
--------------------------------------------------------------------------------
[2022-12-17T02:40:32.075+0000] {taskinstance.py:1383} INFO - Executing <Task(BashOperator): task_5> on 2022-12-17 02:39:16.922161+00:00
[2022-12-17T02:40:32.116+0000] {standard_task_runner.py:55} INFO - Started process 742 to run task
[2022-12-17T02:40:32.153+0000] {standard_task_runner.py:82} INFO - Running: ['***', 'tasks', 'run', 'Can_I_change_name_to_this', 'task_5', 'manual__2022-12-17T02:39:16.922161+00:00', '--job-id', '64', '--raw', '--subdir', 'DAGS_FOLDER/dags.py', '--cfg-path', '/tmp/tmptv9zjpzt']
[2022-12-17T02:40:32.164+0000] {standard_task_runner.py:83} INFO - Job 64: Subtask task_5
[2022-12-17T02:40:32.383+0000] {task_command.py:376} INFO - Running <TaskInstance: Can_I_change_name_to_this.task_5 manual__2022-12-17T02:39:16.922161+00:00 [running]> on host 418b9a9aa3df
[2022-12-17T02:40:32.726+0000] {taskinstance.py:1592} INFO - Exporting the following env vars:
AIRFLOW_CTX_DAG_OWNER=***
AIRFLOW_CTX_DAG_ID=Can_I_change_name_to_this
AIRFLOW_CTX_TASK_ID=task_5
AIRFLOW_CTX_EXECUTION_DATE=2022-12-17T02:39:16.922161+00:00
AIRFLOW_CTX_TRY_NUMBER=1
AIRFLOW_CTX_DAG_RUN_ID=manual__2022-12-17T02:39:16.922161+00:00
[2022-12-17T02:40:32.757+0000] {subprocess.py:63} INFO - Tmp dir root location: 
 /tmp
[2022-12-17T02:40:32.773+0000] {subprocess.py:75} INFO - Running command: ['/bin/bash', '-c', 'python /opt/***/tasks/put_to_s3.py ']
[2022-12-17T02:40:32.808+0000] {subprocess.py:86} INFO - Output:
[2022-12-17T02:40:32.981+0000] {subprocess.py:93} INFO - python: can't open file '/opt/***/tasks/put_to_s3.py': [Errno 2] No such file or directory
[2022-12-17T02:40:32.988+0000] {subprocess.py:97} INFO - Command exited with return code 2
[2022-12-17T02:40:33.049+0000] {taskinstance.py:1851} ERROR - Task failed with exception
Traceback (most recent call last):
  File "/home/airflow/.local/lib/python3.7/site-packages/airflow/operators/bash.py", line 197, in execute
    f'Bash command failed. The command returned a non-zero exit code {result.exit_code}.'
airflow.exceptions.AirflowException: Bash command failed. The command returned a non-zero exit code 2.
[2022-12-17T02:40:33.153+0000] {taskinstance.py:1406} INFO - Marking task as FAILED. dag_id=Can_I_change_name_to_this, task_id=task_5, execution_date=20221217T023916, start_date=20221217T024032, end_date=20221217T024033
[2022-12-17T02:40:33.213+0000] {standard_task_runner.py:105} ERROR - Failed to execute job 64 for task task_5 (Bash command failed. The command returned a non-zero exit code 2.; 742)
[2022-12-17T02:40:33.290+0000] {local_task_job.py:159} INFO - Task exited with return code 1
[2022-12-17T02:40:33.432+0000] {taskinstance.py:2623} INFO - 0 downstream tasks scheduled from follow-on schedule check
