[2022-12-17T03:05:34.547+0000] {taskinstance.py:1165} INFO - Dependencies all met for <TaskInstance: Can_I_change_name_to_this.task_7 manual__2022-12-17T03:04:45.117451+00:00 [queued]>
[2022-12-17T03:05:34.564+0000] {taskinstance.py:1165} INFO - Dependencies all met for <TaskInstance: Can_I_change_name_to_this.task_7 manual__2022-12-17T03:04:45.117451+00:00 [queued]>
[2022-12-17T03:05:34.566+0000] {taskinstance.py:1362} INFO - 
--------------------------------------------------------------------------------
[2022-12-17T03:05:34.568+0000] {taskinstance.py:1363} INFO - Starting attempt 1 of 1
[2022-12-17T03:05:34.570+0000] {taskinstance.py:1364} INFO - 
--------------------------------------------------------------------------------
[2022-12-17T03:05:34.596+0000] {taskinstance.py:1383} INFO - Executing <Task(BashOperator): task_7> on 2022-12-17 03:04:45.117451+00:00
[2022-12-17T03:05:34.618+0000] {standard_task_runner.py:55} INFO - Started process 285 to run task
[2022-12-17T03:05:34.635+0000] {standard_task_runner.py:82} INFO - Running: ['***', 'tasks', 'run', 'Can_I_change_name_to_this', 'task_7', 'manual__2022-12-17T03:04:45.117451+00:00', '--job-id', '84', '--raw', '--subdir', 'DAGS_FOLDER/dags.py', '--cfg-path', '/tmp/tmprkesq4_q']
[2022-12-17T03:05:34.636+0000] {standard_task_runner.py:83} INFO - Job 84: Subtask task_7
[2022-12-17T03:05:34.769+0000] {task_command.py:376} INFO - Running <TaskInstance: Can_I_change_name_to_this.task_7 manual__2022-12-17T03:04:45.117451+00:00 [running]> on host c8f80f7eb8b2
[2022-12-17T03:05:34.911+0000] {taskinstance.py:1592} INFO - Exporting the following env vars:
AIRFLOW_CTX_DAG_OWNER=***
AIRFLOW_CTX_DAG_ID=Can_I_change_name_to_this
AIRFLOW_CTX_TASK_ID=task_7
AIRFLOW_CTX_EXECUTION_DATE=2022-12-17T03:04:45.117451+00:00
AIRFLOW_CTX_TRY_NUMBER=1
AIRFLOW_CTX_DAG_RUN_ID=manual__2022-12-17T03:04:45.117451+00:00
[2022-12-17T03:05:34.919+0000] {subprocess.py:63} INFO - Tmp dir root location: 
 /tmp
[2022-12-17T03:05:34.926+0000] {subprocess.py:75} INFO - Running command: ['/bin/bash', '-c', 'python /opt/***/tasks/data_cleansing_counter_stat.py']
[2022-12-17T03:05:34.969+0000] {subprocess.py:86} INFO - Output:
[2022-12-17T03:05:43.356+0000] {subprocess.py:93} INFO - 2022-12-17 03:05:43 +0000 - dagster - DEBUG - counter_stat_job - 9d4fd384-2209-44a3-aefa-3f1152a40410 - 287 - RUN_START - Started execution of run for "counter_stat_job".
[2022-12-17T03:05:43.365+0000] {subprocess.py:93} INFO - 2022-12-17 03:05:43 +0000 - dagster - DEBUG - counter_stat_job - 9d4fd384-2209-44a3-aefa-3f1152a40410 - 287 - ENGINE_EVENT - Executing steps in process (pid: 287)
[2022-12-17T03:05:43.373+0000] {subprocess.py:93} INFO - 2022-12-17 03:05:43 +0000 - dagster - DEBUG - counter_stat_job - 9d4fd384-2209-44a3-aefa-3f1152a40410 - 287 - RESOURCE_INIT_STARTED - Starting initialization of resources [io_manager].
[2022-12-17T03:05:43.378+0000] {subprocess.py:93} INFO - 2022-12-17 03:05:43 +0000 - dagster - DEBUG - counter_stat_job - 9d4fd384-2209-44a3-aefa-3f1152a40410 - 287 - RESOURCE_INIT_SUCCESS - Finished initialization of resources [io_manager].
[2022-12-17T03:05:43.385+0000] {subprocess.py:93} INFO - 2022-12-17 03:05:43 +0000 - dagster - DEBUG - counter_stat_job - 9d4fd384-2209-44a3-aefa-3f1152a40410 - 287 - LOGS_CAPTURED - Started capturing logs in process (pid: 287).
[2022-12-17T03:05:43.390+0000] {subprocess.py:93} INFO - 2022-12-17 03:05:43 +0000 - dagster - DEBUG - counter_stat_job - 9d4fd384-2209-44a3-aefa-3f1152a40410 - 287 - read_json - STEP_START - Started execution of step "read_json".
[2022-12-17T03:05:43.882+0000] {subprocess.py:93} INFO - 2022-12-17 03:05:43 +0000 - dagster - DEBUG - counter_stat_job - 9d4fd384-2209-44a3-aefa-3f1152a40410 - 287 - read_json - STEP_OUTPUT - Yielded output "result" of type "DataFrame". (Type check passed).
[2022-12-17T03:05:43.891+0000] {subprocess.py:93} INFO - 2022-12-17 03:05:43 +0000 - dagster - DEBUG - counter_stat_job - 9d4fd384-2209-44a3-aefa-3f1152a40410 - 287 - read_json - HANDLED_OUTPUT - Handled output "result" using IO manager "io_manager"
[2022-12-17T03:05:43.901+0000] {subprocess.py:93} INFO - 2022-12-17 03:05:43 +0000 - dagster - DEBUG - counter_stat_job - 9d4fd384-2209-44a3-aefa-3f1152a40410 - 287 - read_json - STEP_SUCCESS - Finished execution of step "read_json" in 502ms.
[2022-12-17T03:05:43.916+0000] {subprocess.py:93} INFO - 2022-12-17 03:05:43 +0000 - dagster - DEBUG - counter_stat_job - 9d4fd384-2209-44a3-aefa-3f1152a40410 - 287 - data_cleansing - STEP_START - Started execution of step "data_cleansing".
[2022-12-17T03:05:43.973+0000] {subprocess.py:93} INFO - 2022-12-17 03:05:43 +0000 - dagster - DEBUG - counter_stat_job - 9d4fd384-2209-44a3-aefa-3f1152a40410 - 287 - data_cleansing - LOADED_INPUT - Loaded input "df" using input manager "io_manager", from output "result" of step "read_json"
[2022-12-17T03:05:44.018+0000] {subprocess.py:93} INFO - 2022-12-17 03:05:43 +0000 - dagster - DEBUG - counter_stat_job - 9d4fd384-2209-44a3-aefa-3f1152a40410 - 287 - data_cleansing - STEP_INPUT - Got input "df" of type "DataFrame". (Type check passed).
[2022-12-17T03:05:44.094+0000] {subprocess.py:93} INFO - 2022-12-17 03:05:44 +0000 - dagster - DEBUG - counter_stat_job - 9d4fd384-2209-44a3-aefa-3f1152a40410 - 287 - data_cleansing - STEP_OUTPUT - Yielded output "result" of type "DataFrame". (Type check passed).
[2022-12-17T03:05:44.101+0000] {subprocess.py:93} INFO - 2022-12-17 03:05:44 +0000 - dagster - DEBUG - counter_stat_job - 9d4fd384-2209-44a3-aefa-3f1152a40410 - 287 - data_cleansing - HANDLED_OUTPUT - Handled output "result" using IO manager "io_manager"
[2022-12-17T03:05:44.104+0000] {subprocess.py:93} INFO - 2022-12-17 03:05:44 +0000 - dagster - DEBUG - counter_stat_job - 9d4fd384-2209-44a3-aefa-3f1152a40410 - 287 - data_cleansing - STEP_SUCCESS - Finished execution of step "data_cleansing" in 122ms.
[2022-12-17T03:05:44.106+0000] {subprocess.py:93} INFO - 2022-12-17 03:05:44 +0000 - dagster - DEBUG - counter_stat_job - 9d4fd384-2209-44a3-aefa-3f1152a40410 - 287 - df_to_file - STEP_START - Started execution of step "df_to_file".
[2022-12-17T03:05:44.112+0000] {subprocess.py:93} INFO - 2022-12-17 03:05:44 +0000 - dagster - DEBUG - counter_stat_job - 9d4fd384-2209-44a3-aefa-3f1152a40410 - 287 - df_to_file - LOADED_INPUT - Loaded input "df" using input manager "io_manager", from output "result" of step "data_cleansing"
[2022-12-17T03:05:44.115+0000] {subprocess.py:93} INFO - 2022-12-17 03:05:44 +0000 - dagster - DEBUG - counter_stat_job - 9d4fd384-2209-44a3-aefa-3f1152a40410 - 287 - df_to_file - STEP_INPUT - Got input "df" of type "DataFrame". (Type check passed).
[2022-12-17T03:05:44.248+0000] {subprocess.py:93} INFO - 2022-12-17 03:05:44 +0000 - dagster - DEBUG - counter_stat_job - 9d4fd384-2209-44a3-aefa-3f1152a40410 - 287 - df_to_file - STEP_OUTPUT - Yielded output "result" of type "Any". (Type check passed).
[2022-12-17T03:05:44.253+0000] {subprocess.py:93} INFO - 2022-12-17 03:05:44 +0000 - dagster - DEBUG - counter_stat_job - 9d4fd384-2209-44a3-aefa-3f1152a40410 - 287 - df_to_file - HANDLED_OUTPUT - Handled output "result" using IO manager "io_manager"
[2022-12-17T03:05:44.257+0000] {subprocess.py:93} INFO - 2022-12-17 03:05:44 +0000 - dagster - DEBUG - counter_stat_job - 9d4fd384-2209-44a3-aefa-3f1152a40410 - 287 - df_to_file - STEP_SUCCESS - Finished execution of step "df_to_file" in 140ms.
[2022-12-17T03:05:44.264+0000] {subprocess.py:93} INFO - 2022-12-17 03:05:44 +0000 - dagster - DEBUG - counter_stat_job - 9d4fd384-2209-44a3-aefa-3f1152a40410 - 287 - df_to_pg - STEP_START - Started execution of step "df_to_pg".
[2022-12-17T03:05:44.296+0000] {subprocess.py:93} INFO - 2022-12-17 03:05:44 +0000 - dagster - DEBUG - counter_stat_job - 9d4fd384-2209-44a3-aefa-3f1152a40410 - 287 - df_to_pg - LOADED_INPUT - Loaded input "df" using input manager "io_manager", from output "result" of step "data_cleansing"
[2022-12-17T03:05:44.326+0000] {subprocess.py:93} INFO - 2022-12-17 03:05:44 +0000 - dagster - DEBUG - counter_stat_job - 9d4fd384-2209-44a3-aefa-3f1152a40410 - 287 - df_to_pg - STEP_INPUT - Got input "df" of type "DataFrame". (Type check passed).
[2022-12-17T03:05:44.446+0000] {subprocess.py:93} INFO - 2022-12-17 03:05:44 +0000 - dagster - ERROR - counter_stat_job - 9d4fd384-2209-44a3-aefa-3f1152a40410 - 287 - df_to_pg - STEP_FAILURE - Execution of step "df_to_pg" failed.
[2022-12-17T03:05:44.451+0000] {subprocess.py:93} INFO - 
[2022-12-17T03:05:44.452+0000] {subprocess.py:93} INFO - dagster._core.errors.DagsterExecutionStepExecutionError: Error occurred while executing op "df_to_pg"::
[2022-12-17T03:05:44.453+0000] {subprocess.py:93} INFO - 
[2022-12-17T03:05:44.456+0000] {subprocess.py:93} INFO - sqlalchemy.exc.OperationalError: (psycopg2.OperationalError) connection to server at "localhost" (127.0.0.1), port 5432 failed: Connection refused
[2022-12-17T03:05:44.458+0000] {subprocess.py:93} INFO - 	Is the server running on that host and accepting TCP/IP connections?
[2022-12-17T03:05:44.460+0000] {subprocess.py:93} INFO - connection to server at "localhost" (::1), port 5432 failed: Cannot assign requested address
[2022-12-17T03:05:44.461+0000] {subprocess.py:93} INFO - 	Is the server running on that host and accepting TCP/IP connections?
[2022-12-17T03:05:44.462+0000] {subprocess.py:93} INFO - 
[2022-12-17T03:05:44.463+0000] {subprocess.py:93} INFO - (Background on this error at: https://sqlalche.me/e/14/e3q8)
[2022-12-17T03:05:44.464+0000] {subprocess.py:93} INFO - 
[2022-12-17T03:05:44.465+0000] {subprocess.py:93} INFO - Stack Trace:
[2022-12-17T03:05:44.466+0000] {subprocess.py:93} INFO -   File "/home/***/.local/lib/python3.7/site-packages/dagster/_core/execution/plan/utils.py", line 47, in solid_execution_error_boundary
[2022-12-17T03:05:44.469+0000] {subprocess.py:93} INFO -     yield
[2022-12-17T03:05:44.470+0000] {subprocess.py:93} INFO -   File "/home/***/.local/lib/python3.7/site-packages/dagster/_utils/__init__.py", line 447, in iterate_with_context
[2022-12-17T03:05:44.471+0000] {subprocess.py:93} INFO -     next_output = next(iterator)
[2022-12-17T03:05:44.474+0000] {subprocess.py:93} INFO -   File "/home/***/.local/lib/python3.7/site-packages/dagster/_core/execution/plan/compute_generator.py", line 74, in _coerce_solid_compute_fn_to_iterator
[2022-12-17T03:05:44.475+0000] {subprocess.py:93} INFO -     result = fn(context, **kwargs) if context_arg_provided else fn(**kwargs)
[2022-12-17T03:05:44.477+0000] {subprocess.py:93} INFO -   File "/opt/***/tasks/data_cleansing_counter_stat.py", line 60, in df_to_pg
[2022-12-17T03:05:44.478+0000] {subprocess.py:93} INFO -     df.to_sql('lol_counter_stat',pg_engine,if_exists='append',index=False)
[2022-12-17T03:05:44.479+0000] {subprocess.py:93} INFO -   File "/home/***/.local/lib/python3.7/site-packages/pandas/core/generic.py", line 2882, in to_sql
[2022-12-17T03:05:44.481+0000] {subprocess.py:93} INFO -     method=method,
[2022-12-17T03:05:44.483+0000] {subprocess.py:93} INFO -   File "/home/***/.local/lib/python3.7/site-packages/pandas/io/sql.py", line 728, in to_sql
[2022-12-17T03:05:44.484+0000] {subprocess.py:93} INFO -     **engine_kwargs,
[2022-12-17T03:05:44.486+0000] {subprocess.py:93} INFO -   File "/home/***/.local/lib/python3.7/site-packages/pandas/io/sql.py", line 1758, in to_sql
[2022-12-17T03:05:44.488+0000] {subprocess.py:93} INFO -     dtype=dtype,
[2022-12-17T03:05:44.489+0000] {subprocess.py:93} INFO -   File "/home/***/.local/lib/python3.7/site-packages/pandas/io/sql.py", line 1650, in prep_table
[2022-12-17T03:05:44.491+0000] {subprocess.py:93} INFO -     table.create()
[2022-12-17T03:05:44.493+0000] {subprocess.py:93} INFO -   File "/home/***/.local/lib/python3.7/site-packages/pandas/io/sql.py", line 856, in create
[2022-12-17T03:05:44.500+0000] {subprocess.py:93} INFO -     if self.exists():
[2022-12-17T03:05:44.501+0000] {subprocess.py:93} INFO -   File "/home/***/.local/lib/python3.7/site-packages/pandas/io/sql.py", line 840, in exists
[2022-12-17T03:05:44.508+0000] {subprocess.py:93} INFO -     return self.pd_sql.has_table(self.name, self.schema)
[2022-12-17T03:05:44.512+0000] {subprocess.py:93} INFO -   File "/home/***/.local/lib/python3.7/site-packages/pandas/io/sql.py", line 1783, in has_table
[2022-12-17T03:05:44.519+0000] {subprocess.py:93} INFO -     insp = sa.inspect(self.connectable)
[2022-12-17T03:05:44.522+0000] {subprocess.py:93} INFO -   File "/home/***/.local/lib/python3.7/site-packages/sqlalchemy/inspection.py", line 64, in inspect
[2022-12-17T03:05:44.523+0000] {subprocess.py:93} INFO -     ret = reg(subject)
[2022-12-17T03:05:44.526+0000] {subprocess.py:93} INFO -   File "/home/***/.local/lib/python3.7/site-packages/sqlalchemy/engine/reflection.py", line 182, in _engine_insp
[2022-12-17T03:05:44.532+0000] {subprocess.py:93} INFO -     return Inspector._construct(Inspector._init_engine, bind)
[2022-12-17T03:05:44.534+0000] {subprocess.py:93} INFO -   File "/home/***/.local/lib/python3.7/site-packages/sqlalchemy/engine/reflection.py", line 117, in _construct
[2022-12-17T03:05:44.536+0000] {subprocess.py:93} INFO -     init(self, bind)
[2022-12-17T03:05:44.540+0000] {subprocess.py:93} INFO -   File "/home/***/.local/lib/python3.7/site-packages/sqlalchemy/engine/reflection.py", line 128, in _init_engine
[2022-12-17T03:05:44.542+0000] {subprocess.py:93} INFO -     engine.connect().close()
[2022-12-17T03:05:44.544+0000] {subprocess.py:93} INFO -   File "/home/***/.local/lib/python3.7/site-packages/sqlalchemy/engine/base.py", line 3197, in connect
[2022-12-17T03:05:44.549+0000] {subprocess.py:93} INFO -     return self._connection_cls(self, close_with_result=close_with_result)
[2022-12-17T03:05:44.553+0000] {subprocess.py:93} INFO -   File "/home/***/.local/lib/python3.7/site-packages/sqlalchemy/engine/base.py", line 96, in __init__
[2022-12-17T03:05:44.554+0000] {subprocess.py:93} INFO -     else engine.raw_connection()
[2022-12-17T03:05:44.555+0000] {subprocess.py:93} INFO -   File "/home/***/.local/lib/python3.7/site-packages/sqlalchemy/engine/base.py", line 3276, in raw_connection
[2022-12-17T03:05:44.556+0000] {subprocess.py:93} INFO -     return self._wrap_pool_connect(self.pool.connect, _connection)
[2022-12-17T03:05:44.557+0000] {subprocess.py:93} INFO -   File "/home/***/.local/lib/python3.7/site-packages/sqlalchemy/engine/base.py", line 3247, in _wrap_pool_connect
[2022-12-17T03:05:44.558+0000] {subprocess.py:93} INFO -     e, dialect, self
[2022-12-17T03:05:44.560+0000] {subprocess.py:93} INFO -   File "/home/***/.local/lib/python3.7/site-packages/sqlalchemy/engine/base.py", line 2101, in _handle_dbapi_exception_noconnection
[2022-12-17T03:05:44.565+0000] {subprocess.py:93} INFO -     sqlalchemy_exception, with_traceback=exc_info[2], from_=e
[2022-12-17T03:05:44.568+0000] {subprocess.py:93} INFO -   File "/home/***/.local/lib/python3.7/site-packages/sqlalchemy/util/compat.py", line 207, in raise_
[2022-12-17T03:05:44.570+0000] {subprocess.py:93} INFO -     raise exception
[2022-12-17T03:05:44.575+0000] {subprocess.py:93} INFO -   File "/home/***/.local/lib/python3.7/site-packages/sqlalchemy/engine/base.py", line 3243, in _wrap_pool_connect
[2022-12-17T03:05:44.576+0000] {subprocess.py:93} INFO -     return fn()
[2022-12-17T03:05:44.582+0000] {subprocess.py:93} INFO -   File "/home/***/.local/lib/python3.7/site-packages/sqlalchemy/pool/base.py", line 310, in connect
[2022-12-17T03:05:44.584+0000] {subprocess.py:93} INFO -     return _ConnectionFairy._checkout(self)
[2022-12-17T03:05:44.586+0000] {subprocess.py:93} INFO -   File "/home/***/.local/lib/python3.7/site-packages/sqlalchemy/pool/base.py", line 868, in _checkout
[2022-12-17T03:05:44.589+0000] {subprocess.py:93} INFO -     fairy = _ConnectionRecord.checkout(pool)
[2022-12-17T03:05:44.605+0000] {subprocess.py:93} INFO -   File "/home/***/.local/lib/python3.7/site-packages/sqlalchemy/pool/base.py", line 476, in checkout
[2022-12-17T03:05:44.608+0000] {subprocess.py:93} INFO -     rec = pool._do_get()
[2022-12-17T03:05:44.625+0000] {subprocess.py:93} INFO -   File "/home/***/.local/lib/python3.7/site-packages/sqlalchemy/pool/impl.py", line 146, in _do_get
[2022-12-17T03:05:44.626+0000] {subprocess.py:93} INFO -     self._dec_overflow()
[2022-12-17T03:05:44.629+0000] {subprocess.py:93} INFO -   File "/home/***/.local/lib/python3.7/site-packages/sqlalchemy/util/langhelpers.py", line 72, in __exit__
[2022-12-17T03:05:44.639+0000] {subprocess.py:93} INFO -     with_traceback=exc_tb,
[2022-12-17T03:05:44.666+0000] {subprocess.py:93} INFO -   File "/home/***/.local/lib/python3.7/site-packages/sqlalchemy/util/compat.py", line 207, in raise_
[2022-12-17T03:05:44.667+0000] {subprocess.py:93} INFO -     raise exception
[2022-12-17T03:05:44.668+0000] {subprocess.py:93} INFO -   File "/home/***/.local/lib/python3.7/site-packages/sqlalchemy/pool/impl.py", line 143, in _do_get
[2022-12-17T03:05:44.670+0000] {subprocess.py:93} INFO -     return self._create_connection()
[2022-12-17T03:05:44.672+0000] {subprocess.py:93} INFO -   File "/home/***/.local/lib/python3.7/site-packages/sqlalchemy/pool/base.py", line 256, in _create_connection
[2022-12-17T03:05:44.673+0000] {subprocess.py:93} INFO -     return _ConnectionRecord(self)
[2022-12-17T03:05:44.676+0000] {subprocess.py:93} INFO -   File "/home/***/.local/lib/python3.7/site-packages/sqlalchemy/pool/base.py", line 371, in __init__
[2022-12-17T03:05:44.683+0000] {subprocess.py:93} INFO -     self.__connect()
[2022-12-17T03:05:44.685+0000] {subprocess.py:93} INFO -   File "/home/***/.local/lib/python3.7/site-packages/sqlalchemy/pool/base.py", line 666, in __connect
[2022-12-17T03:05:44.687+0000] {subprocess.py:93} INFO -     pool.logger.debug("Error on connect(): %s", e)
[2022-12-17T03:05:44.689+0000] {subprocess.py:93} INFO -   File "/home/***/.local/lib/python3.7/site-packages/sqlalchemy/util/langhelpers.py", line 72, in __exit__
[2022-12-17T03:05:44.691+0000] {subprocess.py:93} INFO -     with_traceback=exc_tb,
[2022-12-17T03:05:44.694+0000] {subprocess.py:93} INFO -   File "/home/***/.local/lib/python3.7/site-packages/sqlalchemy/util/compat.py", line 207, in raise_
[2022-12-17T03:05:44.701+0000] {subprocess.py:93} INFO -     raise exception
[2022-12-17T03:05:44.703+0000] {subprocess.py:93} INFO -   File "/home/***/.local/lib/python3.7/site-packages/sqlalchemy/pool/base.py", line 661, in __connect
[2022-12-17T03:05:44.710+0000] {subprocess.py:93} INFO -     self.dbapi_connection = connection = pool._invoke_creator(self)
[2022-12-17T03:05:44.712+0000] {subprocess.py:93} INFO -   File "/home/***/.local/lib/python3.7/site-packages/sqlalchemy/engine/create.py", line 590, in connect
[2022-12-17T03:05:44.714+0000] {subprocess.py:93} INFO -     return dialect.connect(*cargs, **cparams)
[2022-12-17T03:05:44.717+0000] {subprocess.py:93} INFO -   File "/home/***/.local/lib/python3.7/site-packages/sqlalchemy/engine/default.py", line 584, in connect
[2022-12-17T03:05:44.719+0000] {subprocess.py:93} INFO -     return self.dbapi.connect(*cargs, **cparams)
[2022-12-17T03:05:44.720+0000] {subprocess.py:93} INFO -   File "/home/***/.local/lib/python3.7/site-packages/psycopg2/__init__.py", line 122, in connect
[2022-12-17T03:05:44.721+0000] {subprocess.py:93} INFO -     conn = _connect(dsn, connection_factory=connection_factory, **kwasync)
[2022-12-17T03:05:44.723+0000] {subprocess.py:93} INFO - 
[2022-12-17T03:05:44.725+0000] {subprocess.py:93} INFO - The above exception was caused by the following exception:
[2022-12-17T03:05:44.728+0000] {subprocess.py:93} INFO - psycopg2.OperationalError: connection to server at "localhost" (127.0.0.1), port 5432 failed: Connection refused
[2022-12-17T03:05:44.735+0000] {subprocess.py:93} INFO - 	Is the server running on that host and accepting TCP/IP connections?
[2022-12-17T03:05:44.737+0000] {subprocess.py:93} INFO - connection to server at "localhost" (::1), port 5432 failed: Cannot assign requested address
[2022-12-17T03:05:44.739+0000] {subprocess.py:93} INFO - 	Is the server running on that host and accepting TCP/IP connections?
[2022-12-17T03:05:44.740+0000] {subprocess.py:93} INFO - 
[2022-12-17T03:05:44.741+0000] {subprocess.py:93} INFO - 
[2022-12-17T03:05:44.742+0000] {subprocess.py:93} INFO - Stack Trace:
[2022-12-17T03:05:44.745+0000] {subprocess.py:93} INFO -   File "/home/***/.local/lib/python3.7/site-packages/sqlalchemy/engine/base.py", line 3243, in _wrap_pool_connect
[2022-12-17T03:05:44.754+0000] {subprocess.py:93} INFO -     return fn()
[2022-12-17T03:05:44.757+0000] {subprocess.py:93} INFO -   File "/home/***/.local/lib/python3.7/site-packages/sqlalchemy/pool/base.py", line 310, in connect
[2022-12-17T03:05:44.766+0000] {subprocess.py:93} INFO -     return _ConnectionFairy._checkout(self)
[2022-12-17T03:05:44.802+0000] {subprocess.py:93} INFO -   File "/home/***/.local/lib/python3.7/site-packages/sqlalchemy/pool/base.py", line 868, in _checkout
[2022-12-17T03:05:44.805+0000] {subprocess.py:93} INFO -     fairy = _ConnectionRecord.checkout(pool)
[2022-12-17T03:05:44.831+0000] {subprocess.py:93} INFO -   File "/home/***/.local/lib/python3.7/site-packages/sqlalchemy/pool/base.py", line 476, in checkout
[2022-12-17T03:05:44.839+0000] {subprocess.py:93} INFO -     rec = pool._do_get()
[2022-12-17T03:05:44.849+0000] {subprocess.py:93} INFO -   File "/home/***/.local/lib/python3.7/site-packages/sqlalchemy/pool/impl.py", line 146, in _do_get
[2022-12-17T03:05:44.876+0000] {subprocess.py:93} INFO -     self._dec_overflow()
[2022-12-17T03:05:44.891+0000] {subprocess.py:93} INFO -   File "/home/***/.local/lib/python3.7/site-packages/sqlalchemy/util/langhelpers.py", line 72, in __exit__
[2022-12-17T03:05:44.897+0000] {subprocess.py:93} INFO -     with_traceback=exc_tb,
[2022-12-17T03:05:44.928+0000] {subprocess.py:93} INFO -   File "/home/***/.local/lib/python3.7/site-packages/sqlalchemy/util/compat.py", line 207, in raise_
[2022-12-17T03:05:44.951+0000] {subprocess.py:93} INFO -     raise exception
[2022-12-17T03:05:44.962+0000] {subprocess.py:93} INFO -   File "/home/***/.local/lib/python3.7/site-packages/sqlalchemy/pool/impl.py", line 143, in _do_get
[2022-12-17T03:05:44.967+0000] {subprocess.py:93} INFO -     return self._create_connection()
[2022-12-17T03:05:44.969+0000] {subprocess.py:93} INFO -   File "/home/***/.local/lib/python3.7/site-packages/sqlalchemy/pool/base.py", line 256, in _create_connection
[2022-12-17T03:05:44.973+0000] {subprocess.py:93} INFO -     return _ConnectionRecord(self)
[2022-12-17T03:05:44.980+0000] {subprocess.py:93} INFO -   File "/home/***/.local/lib/python3.7/site-packages/sqlalchemy/pool/base.py", line 371, in __init__
[2022-12-17T03:05:44.986+0000] {subprocess.py:93} INFO -     self.__connect()
[2022-12-17T03:05:44.995+0000] {subprocess.py:93} INFO -   File "/home/***/.local/lib/python3.7/site-packages/sqlalchemy/pool/base.py", line 666, in __connect
[2022-12-17T03:05:45.001+0000] {subprocess.py:93} INFO -     pool.logger.debug("Error on connect(): %s", e)
[2022-12-17T03:05:45.004+0000] {subprocess.py:93} INFO -   File "/home/***/.local/lib/python3.7/site-packages/sqlalchemy/util/langhelpers.py", line 72, in __exit__
[2022-12-17T03:05:45.008+0000] {subprocess.py:93} INFO -     with_traceback=exc_tb,
[2022-12-17T03:05:45.016+0000] {subprocess.py:93} INFO -   File "/home/***/.local/lib/python3.7/site-packages/sqlalchemy/util/compat.py", line 207, in raise_
[2022-12-17T03:05:45.101+0000] {subprocess.py:93} INFO -     raise exception
[2022-12-17T03:05:45.104+0000] {subprocess.py:93} INFO -   File "/home/***/.local/lib/python3.7/site-packages/sqlalchemy/pool/base.py", line 661, in __connect
[2022-12-17T03:05:45.106+0000] {subprocess.py:93} INFO -     self.dbapi_connection = connection = pool._invoke_creator(self)
[2022-12-17T03:05:45.114+0000] {subprocess.py:93} INFO -   File "/home/***/.local/lib/python3.7/site-packages/sqlalchemy/engine/create.py", line 590, in connect
[2022-12-17T03:05:45.143+0000] {subprocess.py:93} INFO -     return dialect.connect(*cargs, **cparams)
[2022-12-17T03:05:45.163+0000] {subprocess.py:93} INFO -   File "/home/***/.local/lib/python3.7/site-packages/sqlalchemy/engine/default.py", line 584, in connect
[2022-12-17T03:05:45.172+0000] {subprocess.py:93} INFO -     return self.dbapi.connect(*cargs, **cparams)
[2022-12-17T03:05:45.182+0000] {subprocess.py:93} INFO -   File "/home/***/.local/lib/python3.7/site-packages/psycopg2/__init__.py", line 122, in connect
[2022-12-17T03:05:45.189+0000] {subprocess.py:93} INFO -     conn = _connect(dsn, connection_factory=connection_factory, **kwasync)
[2022-12-17T03:05:45.192+0000] {subprocess.py:93} INFO - 
[2022-12-17T03:05:45.195+0000] {subprocess.py:93} INFO - 2022-12-17 03:05:44 +0000 - dagster - ERROR - counter_stat_job - 9d4fd384-2209-44a3-aefa-3f1152a40410 - 287 - RUN_FAILURE - Execution of run for "counter_stat_job" failed. An exception was thrown during execution.
[2022-12-17T03:05:45.200+0000] {subprocess.py:93} INFO - 
[2022-12-17T03:05:45.209+0000] {subprocess.py:93} INFO - sqlalchemy.exc.OperationalError: (psycopg2.OperationalError) connection to server at "localhost" (127.0.0.1), port 5432 failed: Connection refused
[2022-12-17T03:05:45.215+0000] {subprocess.py:93} INFO - 	Is the server running on that host and accepting TCP/IP connections?
[2022-12-17T03:05:45.223+0000] {subprocess.py:93} INFO - connection to server at "localhost" (::1), port 5432 failed: Cannot assign requested address
[2022-12-17T03:05:45.228+0000] {subprocess.py:93} INFO - 	Is the server running on that host and accepting TCP/IP connections?
[2022-12-17T03:05:45.230+0000] {subprocess.py:93} INFO - 
[2022-12-17T03:05:45.233+0000] {subprocess.py:93} INFO - (Background on this error at: https://sqlalche.me/e/14/e3q8)
[2022-12-17T03:05:45.235+0000] {subprocess.py:93} INFO - 
[2022-12-17T03:05:45.238+0000] {subprocess.py:93} INFO - Stack Trace:
[2022-12-17T03:05:45.250+0000] {subprocess.py:93} INFO -   File "/home/***/.local/lib/python3.7/site-packages/dagster/_core/execution/api.py", line 1091, in pipeline_execution_iterator
[2022-12-17T03:05:45.251+0000] {subprocess.py:93} INFO -     for event in pipeline_context.executor.execute(pipeline_context, execution_plan):
[2022-12-17T03:05:45.259+0000] {subprocess.py:93} INFO -   File "/home/***/.local/lib/python3.7/site-packages/dagster/_core/executor/in_process.py", line 50, in execute
[2022-12-17T03:05:45.260+0000] {subprocess.py:93} INFO -     output_capture=plan_context.output_capture,
[2022-12-17T03:05:45.265+0000] {subprocess.py:93} INFO -   File "/home/***/.local/lib/python3.7/site-packages/dagster/_core/execution/api.py", line 1189, in __iter__
[2022-12-17T03:05:45.267+0000] {subprocess.py:93} INFO -     pipeline_context=self.pipeline_context,
[2022-12-17T03:05:45.271+0000] {subprocess.py:93} INFO -   File "/home/***/.local/lib/python3.7/site-packages/dagster/_core/execution/plan/execute_plan.py", line 121, in inner_plan_execution_iterator
[2022-12-17T03:05:45.276+0000] {subprocess.py:93} INFO -     dagster_event_sequence_for_step(step_context)
[2022-12-17T03:05:45.287+0000] {subprocess.py:93} INFO -   File "/home/***/.local/lib/python3.7/site-packages/dagster/_core/execution/plan/execute_plan.py", line 325, in dagster_event_sequence_for_step
[2022-12-17T03:05:45.292+0000] {subprocess.py:93} INFO -     raise dagster_user_error.user_exception
[2022-12-17T03:05:45.295+0000] {subprocess.py:93} INFO -   File "/home/***/.local/lib/python3.7/site-packages/dagster/_core/execution/plan/utils.py", line 47, in solid_execution_error_boundary
[2022-12-17T03:05:45.298+0000] {subprocess.py:93} INFO -     yield
[2022-12-17T03:05:45.305+0000] {subprocess.py:93} INFO -   File "/home/***/.local/lib/python3.7/site-packages/dagster/_utils/__init__.py", line 447, in iterate_with_context
[2022-12-17T03:05:45.307+0000] {subprocess.py:93} INFO -     next_output = next(iterator)
[2022-12-17T03:05:45.308+0000] {subprocess.py:93} INFO -   File "/home/***/.local/lib/python3.7/site-packages/dagster/_core/execution/plan/compute_generator.py", line 74, in _coerce_solid_compute_fn_to_iterator
[2022-12-17T03:05:45.310+0000] {subprocess.py:93} INFO -     result = fn(context, **kwargs) if context_arg_provided else fn(**kwargs)
[2022-12-17T03:05:45.313+0000] {subprocess.py:93} INFO -   File "/opt/***/tasks/data_cleansing_counter_stat.py", line 60, in df_to_pg
[2022-12-17T03:05:45.315+0000] {subprocess.py:93} INFO -     df.to_sql('lol_counter_stat',pg_engine,if_exists='append',index=False)
[2022-12-17T03:05:45.316+0000] {subprocess.py:93} INFO -   File "/home/***/.local/lib/python3.7/site-packages/pandas/core/generic.py", line 2882, in to_sql
[2022-12-17T03:05:45.323+0000] {subprocess.py:93} INFO -     method=method,
[2022-12-17T03:05:45.325+0000] {subprocess.py:93} INFO -   File "/home/***/.local/lib/python3.7/site-packages/pandas/io/sql.py", line 728, in to_sql
[2022-12-17T03:05:45.328+0000] {subprocess.py:93} INFO -     **engine_kwargs,
[2022-12-17T03:05:45.331+0000] {subprocess.py:93} INFO -   File "/home/***/.local/lib/python3.7/site-packages/pandas/io/sql.py", line 1758, in to_sql
[2022-12-17T03:05:45.332+0000] {subprocess.py:93} INFO -     dtype=dtype,
[2022-12-17T03:05:45.334+0000] {subprocess.py:93} INFO -   File "/home/***/.local/lib/python3.7/site-packages/pandas/io/sql.py", line 1650, in prep_table
[2022-12-17T03:05:45.336+0000] {subprocess.py:93} INFO -     table.create()
[2022-12-17T03:05:45.340+0000] {subprocess.py:93} INFO -   File "/home/***/.local/lib/python3.7/site-packages/pandas/io/sql.py", line 856, in create
[2022-12-17T03:05:45.342+0000] {subprocess.py:93} INFO -     if self.exists():
[2022-12-17T03:05:45.345+0000] {subprocess.py:93} INFO -   File "/home/***/.local/lib/python3.7/site-packages/pandas/io/sql.py", line 840, in exists
[2022-12-17T03:05:45.350+0000] {subprocess.py:93} INFO -     return self.pd_sql.has_table(self.name, self.schema)
[2022-12-17T03:05:45.354+0000] {subprocess.py:93} INFO -   File "/home/***/.local/lib/python3.7/site-packages/pandas/io/sql.py", line 1783, in has_table
[2022-12-17T03:05:45.357+0000] {subprocess.py:93} INFO -     insp = sa.inspect(self.connectable)
[2022-12-17T03:05:45.362+0000] {subprocess.py:93} INFO -   File "/home/***/.local/lib/python3.7/site-packages/sqlalchemy/inspection.py", line 64, in inspect
[2022-12-17T03:05:45.365+0000] {subprocess.py:93} INFO -     ret = reg(subject)
[2022-12-17T03:05:45.368+0000] {subprocess.py:93} INFO -   File "/home/***/.local/lib/python3.7/site-packages/sqlalchemy/engine/reflection.py", line 182, in _engine_insp
[2022-12-17T03:05:45.375+0000] {subprocess.py:93} INFO -     return Inspector._construct(Inspector._init_engine, bind)
[2022-12-17T03:05:45.378+0000] {subprocess.py:93} INFO -   File "/home/***/.local/lib/python3.7/site-packages/sqlalchemy/engine/reflection.py", line 117, in _construct
[2022-12-17T03:05:45.380+0000] {subprocess.py:93} INFO -     init(self, bind)
[2022-12-17T03:05:45.385+0000] {subprocess.py:93} INFO -   File "/home/***/.local/lib/python3.7/site-packages/sqlalchemy/engine/reflection.py", line 128, in _init_engine
[2022-12-17T03:05:45.386+0000] {subprocess.py:93} INFO -     engine.connect().close()
[2022-12-17T03:05:45.387+0000] {subprocess.py:93} INFO -   File "/home/***/.local/lib/python3.7/site-packages/sqlalchemy/engine/base.py", line 3197, in connect
[2022-12-17T03:05:45.391+0000] {subprocess.py:93} INFO -     return self._connection_cls(self, close_with_result=close_with_result)
[2022-12-17T03:05:45.392+0000] {subprocess.py:93} INFO -   File "/home/***/.local/lib/python3.7/site-packages/sqlalchemy/engine/base.py", line 96, in __init__
[2022-12-17T03:05:45.393+0000] {subprocess.py:93} INFO -     else engine.raw_connection()
[2022-12-17T03:05:45.395+0000] {subprocess.py:93} INFO -   File "/home/***/.local/lib/python3.7/site-packages/sqlalchemy/engine/base.py", line 3276, in raw_connection
[2022-12-17T03:05:45.397+0000] {subprocess.py:93} INFO -     return self._wrap_pool_connect(self.pool.connect, _connection)
[2022-12-17T03:05:45.400+0000] {subprocess.py:93} INFO -   File "/home/***/.local/lib/python3.7/site-packages/sqlalchemy/engine/base.py", line 3247, in _wrap_pool_connect
[2022-12-17T03:05:45.402+0000] {subprocess.py:93} INFO -     e, dialect, self
[2022-12-17T03:05:45.404+0000] {subprocess.py:93} INFO -   File "/home/***/.local/lib/python3.7/site-packages/sqlalchemy/engine/base.py", line 2101, in _handle_dbapi_exception_noconnection
[2022-12-17T03:05:45.407+0000] {subprocess.py:93} INFO -     sqlalchemy_exception, with_traceback=exc_info[2], from_=e
[2022-12-17T03:05:45.422+0000] {subprocess.py:93} INFO -   File "/home/***/.local/lib/python3.7/site-packages/sqlalchemy/util/compat.py", line 207, in raise_
[2022-12-17T03:05:45.426+0000] {subprocess.py:93} INFO -     raise exception
[2022-12-17T03:05:45.462+0000] {subprocess.py:93} INFO -   File "/home/***/.local/lib/python3.7/site-packages/sqlalchemy/engine/base.py", line 3243, in _wrap_pool_connect
[2022-12-17T03:05:45.469+0000] {subprocess.py:93} INFO -     return fn()
[2022-12-17T03:05:45.479+0000] {subprocess.py:93} INFO -   File "/home/***/.local/lib/python3.7/site-packages/sqlalchemy/pool/base.py", line 310, in connect
[2022-12-17T03:05:45.485+0000] {subprocess.py:93} INFO -     return _ConnectionFairy._checkout(self)
[2022-12-17T03:05:45.489+0000] {subprocess.py:93} INFO -   File "/home/***/.local/lib/python3.7/site-packages/sqlalchemy/pool/base.py", line 868, in _checkout
[2022-12-17T03:05:45.490+0000] {subprocess.py:93} INFO -     fairy = _ConnectionRecord.checkout(pool)
[2022-12-17T03:05:45.491+0000] {subprocess.py:93} INFO -   File "/home/***/.local/lib/python3.7/site-packages/sqlalchemy/pool/base.py", line 476, in checkout
[2022-12-17T03:05:45.494+0000] {subprocess.py:93} INFO -     rec = pool._do_get()
[2022-12-17T03:05:45.505+0000] {subprocess.py:93} INFO -   File "/home/***/.local/lib/python3.7/site-packages/sqlalchemy/pool/impl.py", line 146, in _do_get
[2022-12-17T03:05:45.510+0000] {subprocess.py:93} INFO -     self._dec_overflow()
[2022-12-17T03:05:45.516+0000] {subprocess.py:93} INFO -   File "/home/***/.local/lib/python3.7/site-packages/sqlalchemy/util/langhelpers.py", line 72, in __exit__
[2022-12-17T03:05:45.524+0000] {subprocess.py:93} INFO -     with_traceback=exc_tb,
[2022-12-17T03:05:45.527+0000] {subprocess.py:93} INFO -   File "/home/***/.local/lib/python3.7/site-packages/sqlalchemy/util/compat.py", line 207, in raise_
[2022-12-17T03:05:45.529+0000] {subprocess.py:93} INFO -     raise exception
[2022-12-17T03:05:45.538+0000] {subprocess.py:93} INFO -   File "/home/***/.local/lib/python3.7/site-packages/sqlalchemy/pool/impl.py", line 143, in _do_get
[2022-12-17T03:05:45.549+0000] {subprocess.py:93} INFO -     return self._create_connection()
[2022-12-17T03:05:45.552+0000] {subprocess.py:93} INFO -   File "/home/***/.local/lib/python3.7/site-packages/sqlalchemy/pool/base.py", line 256, in _create_connection
[2022-12-17T03:05:45.554+0000] {subprocess.py:93} INFO -     return _ConnectionRecord(self)
[2022-12-17T03:05:45.554+0000] {subprocess.py:93} INFO -   File "/home/***/.local/lib/python3.7/site-packages/sqlalchemy/pool/base.py", line 371, in __init__
[2022-12-17T03:05:45.556+0000] {subprocess.py:93} INFO -     self.__connect()
[2022-12-17T03:05:45.558+0000] {subprocess.py:93} INFO -   File "/home/***/.local/lib/python3.7/site-packages/sqlalchemy/pool/base.py", line 666, in __connect
[2022-12-17T03:05:45.569+0000] {subprocess.py:93} INFO -     pool.logger.debug("Error on connect(): %s", e)
[2022-12-17T03:05:45.570+0000] {subprocess.py:93} INFO -   File "/home/***/.local/lib/python3.7/site-packages/sqlalchemy/util/langhelpers.py", line 72, in __exit__
[2022-12-17T03:05:45.572+0000] {subprocess.py:93} INFO -     with_traceback=exc_tb,
[2022-12-17T03:05:45.575+0000] {subprocess.py:93} INFO -   File "/home/***/.local/lib/python3.7/site-packages/sqlalchemy/util/compat.py", line 207, in raise_
[2022-12-17T03:05:45.578+0000] {subprocess.py:93} INFO -     raise exception
[2022-12-17T03:05:45.579+0000] {subprocess.py:93} INFO -   File "/home/***/.local/lib/python3.7/site-packages/sqlalchemy/pool/base.py", line 661, in __connect
[2022-12-17T03:05:45.580+0000] {subprocess.py:93} INFO -     self.dbapi_connection = connection = pool._invoke_creator(self)
[2022-12-17T03:05:45.583+0000] {subprocess.py:93} INFO -   File "/home/***/.local/lib/python3.7/site-packages/sqlalchemy/engine/create.py", line 590, in connect
[2022-12-17T03:05:45.584+0000] {subprocess.py:93} INFO -     return dialect.connect(*cargs, **cparams)
[2022-12-17T03:05:45.586+0000] {subprocess.py:93} INFO -   File "/home/***/.local/lib/python3.7/site-packages/sqlalchemy/engine/default.py", line 584, in connect
[2022-12-17T03:05:45.587+0000] {subprocess.py:93} INFO -     return self.dbapi.connect(*cargs, **cparams)
[2022-12-17T03:05:45.592+0000] {subprocess.py:93} INFO -   File "/home/***/.local/lib/python3.7/site-packages/psycopg2/__init__.py", line 122, in connect
[2022-12-17T03:05:45.593+0000] {subprocess.py:93} INFO -     conn = _connect(dsn, connection_factory=connection_factory, **kwasync)
[2022-12-17T03:05:45.594+0000] {subprocess.py:93} INFO - 
[2022-12-17T03:05:45.595+0000] {subprocess.py:93} INFO - The above exception was caused by the following exception:
[2022-12-17T03:05:45.597+0000] {subprocess.py:93} INFO - psycopg2.OperationalError: connection to server at "localhost" (127.0.0.1), port 5432 failed: Connection refused
[2022-12-17T03:05:45.602+0000] {subprocess.py:93} INFO - 	Is the server running on that host and accepting TCP/IP connections?
[2022-12-17T03:05:45.603+0000] {subprocess.py:93} INFO - connection to server at "localhost" (::1), port 5432 failed: Cannot assign requested address
[2022-12-17T03:05:45.605+0000] {subprocess.py:93} INFO - 	Is the server running on that host and accepting TCP/IP connections?
[2022-12-17T03:05:45.608+0000] {subprocess.py:93} INFO - 
[2022-12-17T03:05:45.614+0000] {subprocess.py:93} INFO - 
[2022-12-17T03:05:45.616+0000] {subprocess.py:93} INFO - Stack Trace:
[2022-12-17T03:05:45.626+0000] {subprocess.py:93} INFO -   File "/home/***/.local/lib/python3.7/site-packages/sqlalchemy/engine/base.py", line 3243, in _wrap_pool_connect
[2022-12-17T03:05:45.628+0000] {subprocess.py:93} INFO -     return fn()
[2022-12-17T03:05:45.632+0000] {subprocess.py:93} INFO -   File "/home/***/.local/lib/python3.7/site-packages/sqlalchemy/pool/base.py", line 310, in connect
[2022-12-17T03:05:45.633+0000] {subprocess.py:93} INFO -     return _ConnectionFairy._checkout(self)
[2022-12-17T03:05:45.634+0000] {subprocess.py:93} INFO -   File "/home/***/.local/lib/python3.7/site-packages/sqlalchemy/pool/base.py", line 868, in _checkout
[2022-12-17T03:05:45.644+0000] {subprocess.py:93} INFO -     fairy = _ConnectionRecord.checkout(pool)
[2022-12-17T03:05:45.645+0000] {subprocess.py:93} INFO -   File "/home/***/.local/lib/python3.7/site-packages/sqlalchemy/pool/base.py", line 476, in checkout
[2022-12-17T03:05:45.647+0000] {subprocess.py:93} INFO -     rec = pool._do_get()
[2022-12-17T03:05:45.650+0000] {subprocess.py:93} INFO -   File "/home/***/.local/lib/python3.7/site-packages/sqlalchemy/pool/impl.py", line 146, in _do_get
[2022-12-17T03:05:45.653+0000] {subprocess.py:93} INFO -     self._dec_overflow()
[2022-12-17T03:05:45.662+0000] {subprocess.py:93} INFO -   File "/home/***/.local/lib/python3.7/site-packages/sqlalchemy/util/langhelpers.py", line 72, in __exit__
[2022-12-17T03:05:45.669+0000] {subprocess.py:93} INFO -     with_traceback=exc_tb,
[2022-12-17T03:05:45.674+0000] {subprocess.py:93} INFO -   File "/home/***/.local/lib/python3.7/site-packages/sqlalchemy/util/compat.py", line 207, in raise_
[2022-12-17T03:05:45.694+0000] {subprocess.py:93} INFO -     raise exception
[2022-12-17T03:05:45.711+0000] {subprocess.py:93} INFO -   File "/home/***/.local/lib/python3.7/site-packages/sqlalchemy/pool/impl.py", line 143, in _do_get
[2022-12-17T03:05:45.713+0000] {subprocess.py:93} INFO -     return self._create_connection()
[2022-12-17T03:05:45.719+0000] {subprocess.py:93} INFO -   File "/home/***/.local/lib/python3.7/site-packages/sqlalchemy/pool/base.py", line 256, in _create_connection
[2022-12-17T03:05:45.721+0000] {subprocess.py:93} INFO -     return _ConnectionRecord(self)
[2022-12-17T03:05:45.725+0000] {subprocess.py:93} INFO -   File "/home/***/.local/lib/python3.7/site-packages/sqlalchemy/pool/base.py", line 371, in __init__
[2022-12-17T03:05:45.727+0000] {subprocess.py:93} INFO -     self.__connect()
[2022-12-17T03:05:45.740+0000] {subprocess.py:93} INFO -   File "/home/***/.local/lib/python3.7/site-packages/sqlalchemy/pool/base.py", line 666, in __connect
[2022-12-17T03:05:45.750+0000] {subprocess.py:93} INFO -     pool.logger.debug("Error on connect(): %s", e)
[2022-12-17T03:05:45.753+0000] {subprocess.py:93} INFO -   File "/home/***/.local/lib/python3.7/site-packages/sqlalchemy/util/langhelpers.py", line 72, in __exit__
[2022-12-17T03:05:45.835+0000] {subprocess.py:93} INFO -     with_traceback=exc_tb,
[2022-12-17T03:05:45.841+0000] {subprocess.py:93} INFO -   File "/home/***/.local/lib/python3.7/site-packages/sqlalchemy/util/compat.py", line 207, in raise_
[2022-12-17T03:05:45.842+0000] {subprocess.py:93} INFO -     raise exception
[2022-12-17T03:05:45.843+0000] {subprocess.py:93} INFO -   File "/home/***/.local/lib/python3.7/site-packages/sqlalchemy/pool/base.py", line 661, in __connect
[2022-12-17T03:05:45.844+0000] {subprocess.py:93} INFO -     self.dbapi_connection = connection = pool._invoke_creator(self)
[2022-12-17T03:05:45.844+0000] {subprocess.py:93} INFO -   File "/home/***/.local/lib/python3.7/site-packages/sqlalchemy/engine/create.py", line 590, in connect
[2022-12-17T03:05:45.848+0000] {subprocess.py:93} INFO -     return dialect.connect(*cargs, **cparams)
[2022-12-17T03:05:45.849+0000] {subprocess.py:93} INFO -   File "/home/***/.local/lib/python3.7/site-packages/sqlalchemy/engine/default.py", line 584, in connect
[2022-12-17T03:05:45.850+0000] {subprocess.py:93} INFO -     return self.dbapi.connect(*cargs, **cparams)
[2022-12-17T03:05:45.851+0000] {subprocess.py:93} INFO -   File "/home/***/.local/lib/python3.7/site-packages/psycopg2/__init__.py", line 122, in connect
[2022-12-17T03:05:45.853+0000] {subprocess.py:93} INFO -     conn = _connect(dsn, connection_factory=connection_factory, **kwasync)
[2022-12-17T03:05:45.854+0000] {subprocess.py:93} INFO - 
[2022-12-17T03:05:45.856+0000] {subprocess.py:93} INFO - Traceback (most recent call last):
[2022-12-17T03:05:45.858+0000] {subprocess.py:93} INFO -   File "/home/***/.local/lib/python3.7/site-packages/sqlalchemy/engine/base.py", line 3243, in _wrap_pool_connect
[2022-12-17T03:05:45.859+0000] {subprocess.py:93} INFO -     return fn()
[2022-12-17T03:05:45.860+0000] {subprocess.py:93} INFO -   File "/home/***/.local/lib/python3.7/site-packages/sqlalchemy/pool/base.py", line 310, in connect
[2022-12-17T03:05:45.860+0000] {subprocess.py:93} INFO -     return _ConnectionFairy._checkout(self)
[2022-12-17T03:05:45.861+0000] {subprocess.py:93} INFO -   File "/home/***/.local/lib/python3.7/site-packages/sqlalchemy/pool/base.py", line 868, in _checkout
[2022-12-17T03:05:45.864+0000] {subprocess.py:93} INFO -     fairy = _ConnectionRecord.checkout(pool)
[2022-12-17T03:05:45.865+0000] {subprocess.py:93} INFO -   File "/home/***/.local/lib/python3.7/site-packages/sqlalchemy/pool/base.py", line 476, in checkout
[2022-12-17T03:05:45.866+0000] {subprocess.py:93} INFO -     rec = pool._do_get()
[2022-12-17T03:05:45.871+0000] {subprocess.py:93} INFO -   File "/home/***/.local/lib/python3.7/site-packages/sqlalchemy/pool/impl.py", line 146, in _do_get
[2022-12-17T03:05:45.873+0000] {subprocess.py:93} INFO -     self._dec_overflow()
[2022-12-17T03:05:45.874+0000] {subprocess.py:93} INFO -   File "/home/***/.local/lib/python3.7/site-packages/sqlalchemy/util/langhelpers.py", line 72, in __exit__
[2022-12-17T03:05:45.875+0000] {subprocess.py:93} INFO -     with_traceback=exc_tb,
[2022-12-17T03:05:45.876+0000] {subprocess.py:93} INFO -   File "/home/***/.local/lib/python3.7/site-packages/sqlalchemy/util/compat.py", line 207, in raise_
[2022-12-17T03:05:45.877+0000] {subprocess.py:93} INFO -     raise exception
[2022-12-17T03:05:45.879+0000] {subprocess.py:93} INFO -   File "/home/***/.local/lib/python3.7/site-packages/sqlalchemy/pool/impl.py", line 143, in _do_get
[2022-12-17T03:05:45.880+0000] {subprocess.py:93} INFO -     return self._create_connection()
[2022-12-17T03:05:45.881+0000] {subprocess.py:93} INFO -   File "/home/***/.local/lib/python3.7/site-packages/sqlalchemy/pool/base.py", line 256, in _create_connection
[2022-12-17T03:05:45.882+0000] {subprocess.py:93} INFO -     return _ConnectionRecord(self)
[2022-12-17T03:05:45.883+0000] {subprocess.py:93} INFO -   File "/home/***/.local/lib/python3.7/site-packages/sqlalchemy/pool/base.py", line 371, in __init__
[2022-12-17T03:05:45.884+0000] {subprocess.py:93} INFO -     self.__connect()
[2022-12-17T03:05:45.885+0000] {subprocess.py:93} INFO -   File "/home/***/.local/lib/python3.7/site-packages/sqlalchemy/pool/base.py", line 666, in __connect
[2022-12-17T03:05:45.886+0000] {subprocess.py:93} INFO -     pool.logger.debug("Error on connect(): %s", e)
[2022-12-17T03:05:45.888+0000] {subprocess.py:93} INFO -   File "/home/***/.local/lib/python3.7/site-packages/sqlalchemy/util/langhelpers.py", line 72, in __exit__
[2022-12-17T03:05:45.889+0000] {subprocess.py:93} INFO -     with_traceback=exc_tb,
[2022-12-17T03:05:45.890+0000] {subprocess.py:93} INFO -   File "/home/***/.local/lib/python3.7/site-packages/sqlalchemy/util/compat.py", line 207, in raise_
[2022-12-17T03:05:45.891+0000] {subprocess.py:93} INFO -     raise exception
[2022-12-17T03:05:45.892+0000] {subprocess.py:93} INFO -   File "/home/***/.local/lib/python3.7/site-packages/sqlalchemy/pool/base.py", line 661, in __connect
[2022-12-17T03:05:45.893+0000] {subprocess.py:93} INFO -     self.dbapi_connection = connection = pool._invoke_creator(self)
[2022-12-17T03:05:45.894+0000] {subprocess.py:93} INFO -   File "/home/***/.local/lib/python3.7/site-packages/sqlalchemy/engine/create.py", line 590, in connect
[2022-12-17T03:05:45.895+0000] {subprocess.py:93} INFO -     return dialect.connect(*cargs, **cparams)
[2022-12-17T03:05:45.897+0000] {subprocess.py:93} INFO -   File "/home/***/.local/lib/python3.7/site-packages/sqlalchemy/engine/default.py", line 584, in connect
[2022-12-17T03:05:45.899+0000] {subprocess.py:93} INFO -     return self.dbapi.connect(*cargs, **cparams)
[2022-12-17T03:05:45.900+0000] {subprocess.py:93} INFO -   File "/home/***/.local/lib/python3.7/site-packages/psycopg2/__init__.py", line 122, in connect
[2022-12-17T03:05:45.901+0000] {subprocess.py:93} INFO -     conn = _connect(dsn, connection_factory=connection_factory, **kwasync)
[2022-12-17T03:05:45.903+0000] {subprocess.py:93} INFO - psycopg2.OperationalError: connection to server at "localhost" (127.0.0.1), port 5432 failed: Connection refused
[2022-12-17T03:05:45.904+0000] {subprocess.py:93} INFO - 	Is the server running on that host and accepting TCP/IP connections?
[2022-12-17T03:05:45.905+0000] {subprocess.py:93} INFO - connection to server at "localhost" (::1), port 5432 failed: Cannot assign requested address
[2022-12-17T03:05:45.906+0000] {subprocess.py:93} INFO - 	Is the server running on that host and accepting TCP/IP connections?
[2022-12-17T03:05:45.907+0000] {subprocess.py:93} INFO - 
[2022-12-17T03:05:45.908+0000] {subprocess.py:93} INFO - 
[2022-12-17T03:05:45.913+0000] {subprocess.py:93} INFO - The above exception was the direct cause of the following exception:
[2022-12-17T03:05:45.915+0000] {subprocess.py:93} INFO - 
[2022-12-17T03:05:45.916+0000] {subprocess.py:93} INFO - Traceback (most recent call last):
[2022-12-17T03:05:45.920+0000] {subprocess.py:93} INFO -   File "/opt/***/tasks/data_cleansing_counter_stat.py", line 75, in <module>
[2022-12-17T03:05:45.924+0000] {subprocess.py:93} INFO -     result = counter_stat_job.execute_in_process()
[2022-12-17T03:05:45.925+0000] {subprocess.py:93} INFO -   File "/home/***/.local/lib/python3.7/site-packages/dagster/_core/definitions/job_definition.py", line 395, in execute_in_process
[2022-12-17T03:05:45.928+0000] {subprocess.py:93} INFO -     asset_selection=frozenset(asset_selection),
[2022-12-17T03:05:45.930+0000] {subprocess.py:93} INFO -   File "/home/***/.local/lib/python3.7/site-packages/dagster/_core/execution/execute_in_process.py", line 77, in core_execute_in_process
[2022-12-17T03:05:45.932+0000] {subprocess.py:93} INFO -     event_list = list(execute_run_iterable)
[2022-12-17T03:05:45.933+0000] {subprocess.py:93} INFO -   File "/home/***/.local/lib/python3.7/site-packages/dagster/_core/execution/api.py", line 1189, in __iter__
[2022-12-17T03:05:45.936+0000] {subprocess.py:93} INFO -     pipeline_context=self.pipeline_context,
[2022-12-17T03:05:45.937+0000] {subprocess.py:93} INFO -   File "/home/***/.local/lib/python3.7/site-packages/dagster/_core/execution/api.py", line 1091, in pipeline_execution_iterator
[2022-12-17T03:05:45.937+0000] {subprocess.py:93} INFO -     for event in pipeline_context.executor.execute(pipeline_context, execution_plan):
[2022-12-17T03:05:45.938+0000] {subprocess.py:93} INFO -   File "/home/***/.local/lib/python3.7/site-packages/dagster/_core/executor/in_process.py", line 50, in execute
[2022-12-17T03:05:45.939+0000] {subprocess.py:93} INFO -     output_capture=plan_context.output_capture,
[2022-12-17T03:05:45.940+0000] {subprocess.py:93} INFO -   File "/home/***/.local/lib/python3.7/site-packages/dagster/_core/execution/api.py", line 1189, in __iter__
[2022-12-17T03:05:45.941+0000] {subprocess.py:93} INFO -     pipeline_context=self.pipeline_context,
[2022-12-17T03:05:45.941+0000] {subprocess.py:93} INFO -   File "/home/***/.local/lib/python3.7/site-packages/dagster/_core/execution/plan/execute_plan.py", line 121, in inner_plan_execution_iterator
[2022-12-17T03:05:45.943+0000] {subprocess.py:93} INFO -     dagster_event_sequence_for_step(step_context)
[2022-12-17T03:05:45.945+0000] {subprocess.py:93} INFO -   File "/home/***/.local/lib/python3.7/site-packages/dagster/_core/execution/plan/execute_plan.py", line 325, in dagster_event_sequence_for_step
[2022-12-17T03:05:45.949+0000] {subprocess.py:93} INFO -     raise dagster_user_error.user_exception
[2022-12-17T03:05:45.951+0000] {subprocess.py:93} INFO -   File "/home/***/.local/lib/python3.7/site-packages/dagster/_core/execution/plan/utils.py", line 47, in solid_execution_error_boundary
[2022-12-17T03:05:45.952+0000] {subprocess.py:93} INFO -     yield
[2022-12-17T03:05:45.953+0000] {subprocess.py:93} INFO -   File "/home/***/.local/lib/python3.7/site-packages/dagster/_utils/__init__.py", line 447, in iterate_with_context
[2022-12-17T03:05:45.954+0000] {subprocess.py:93} INFO -     next_output = next(iterator)
[2022-12-17T03:05:45.955+0000] {subprocess.py:93} INFO -   File "/home/***/.local/lib/python3.7/site-packages/dagster/_core/execution/plan/compute_generator.py", line 74, in _coerce_solid_compute_fn_to_iterator
[2022-12-17T03:05:45.956+0000] {subprocess.py:93} INFO -     result = fn(context, **kwargs) if context_arg_provided else fn(**kwargs)
[2022-12-17T03:05:45.957+0000] {subprocess.py:93} INFO -   File "/opt/***/tasks/data_cleansing_counter_stat.py", line 60, in df_to_pg
[2022-12-17T03:05:45.958+0000] {subprocess.py:93} INFO -     df.to_sql('lol_counter_stat',pg_engine,if_exists='append',index=False)
[2022-12-17T03:05:45.959+0000] {subprocess.py:93} INFO -   File "/home/***/.local/lib/python3.7/site-packages/pandas/core/generic.py", line 2882, in to_sql
[2022-12-17T03:05:45.960+0000] {subprocess.py:93} INFO -     method=method,
[2022-12-17T03:05:45.960+0000] {subprocess.py:93} INFO -   File "/home/***/.local/lib/python3.7/site-packages/pandas/io/sql.py", line 728, in to_sql
[2022-12-17T03:05:45.961+0000] {subprocess.py:93} INFO -     **engine_kwargs,
[2022-12-17T03:05:45.961+0000] {subprocess.py:93} INFO -   File "/home/***/.local/lib/python3.7/site-packages/pandas/io/sql.py", line 1758, in to_sql
[2022-12-17T03:05:45.962+0000] {subprocess.py:93} INFO -     dtype=dtype,
[2022-12-17T03:05:45.963+0000] {subprocess.py:93} INFO -   File "/home/***/.local/lib/python3.7/site-packages/pandas/io/sql.py", line 1650, in prep_table
[2022-12-17T03:05:45.963+0000] {subprocess.py:93} INFO -     table.create()
[2022-12-17T03:05:45.964+0000] {subprocess.py:93} INFO -   File "/home/***/.local/lib/python3.7/site-packages/pandas/io/sql.py", line 856, in create
[2022-12-17T03:05:45.964+0000] {subprocess.py:93} INFO -     if self.exists():
[2022-12-17T03:05:45.965+0000] {subprocess.py:93} INFO -   File "/home/***/.local/lib/python3.7/site-packages/pandas/io/sql.py", line 840, in exists
[2022-12-17T03:05:45.965+0000] {subprocess.py:93} INFO -     return self.pd_sql.has_table(self.name, self.schema)
[2022-12-17T03:05:45.966+0000] {subprocess.py:93} INFO -   File "/home/***/.local/lib/python3.7/site-packages/pandas/io/sql.py", line 1783, in has_table
[2022-12-17T03:05:45.967+0000] {subprocess.py:93} INFO -     insp = sa.inspect(self.connectable)
[2022-12-17T03:05:45.967+0000] {subprocess.py:93} INFO -   File "/home/***/.local/lib/python3.7/site-packages/sqlalchemy/inspection.py", line 64, in inspect
[2022-12-17T03:05:45.968+0000] {subprocess.py:93} INFO -     ret = reg(subject)
[2022-12-17T03:05:45.969+0000] {subprocess.py:93} INFO -   File "/home/***/.local/lib/python3.7/site-packages/sqlalchemy/engine/reflection.py", line 182, in _engine_insp
[2022-12-17T03:05:45.970+0000] {subprocess.py:93} INFO -     return Inspector._construct(Inspector._init_engine, bind)
[2022-12-17T03:05:45.970+0000] {subprocess.py:93} INFO -   File "/home/***/.local/lib/python3.7/site-packages/sqlalchemy/engine/reflection.py", line 117, in _construct
[2022-12-17T03:05:45.971+0000] {subprocess.py:93} INFO -     init(self, bind)
[2022-12-17T03:05:45.971+0000] {subprocess.py:93} INFO -   File "/home/***/.local/lib/python3.7/site-packages/sqlalchemy/engine/reflection.py", line 128, in _init_engine
[2022-12-17T03:05:45.974+0000] {subprocess.py:93} INFO -     engine.connect().close()
[2022-12-17T03:05:45.980+0000] {subprocess.py:93} INFO -   File "/home/***/.local/lib/python3.7/site-packages/sqlalchemy/engine/base.py", line 3197, in connect
[2022-12-17T03:05:45.981+0000] {subprocess.py:93} INFO -     return self._connection_cls(self, close_with_result=close_with_result)
[2022-12-17T03:05:45.982+0000] {subprocess.py:93} INFO -   File "/home/***/.local/lib/python3.7/site-packages/sqlalchemy/engine/base.py", line 96, in __init__
[2022-12-17T03:05:45.983+0000] {subprocess.py:93} INFO -     else engine.raw_connection()
[2022-12-17T03:05:45.984+0000] {subprocess.py:93} INFO -   File "/home/***/.local/lib/python3.7/site-packages/sqlalchemy/engine/base.py", line 3276, in raw_connection
[2022-12-17T03:05:45.985+0000] {subprocess.py:93} INFO -     return self._wrap_pool_connect(self.pool.connect, _connection)
[2022-12-17T03:05:45.985+0000] {subprocess.py:93} INFO -   File "/home/***/.local/lib/python3.7/site-packages/sqlalchemy/engine/base.py", line 3247, in _wrap_pool_connect
[2022-12-17T03:05:45.986+0000] {subprocess.py:93} INFO -     e, dialect, self
[2022-12-17T03:05:45.987+0000] {subprocess.py:93} INFO -   File "/home/***/.local/lib/python3.7/site-packages/sqlalchemy/engine/base.py", line 2101, in _handle_dbapi_exception_noconnection
[2022-12-17T03:05:45.987+0000] {subprocess.py:93} INFO -     sqlalchemy_exception, with_traceback=exc_info[2], from_=e
[2022-12-17T03:05:45.988+0000] {subprocess.py:93} INFO -   File "/home/***/.local/lib/python3.7/site-packages/sqlalchemy/util/compat.py", line 207, in raise_
[2022-12-17T03:05:45.989+0000] {subprocess.py:93} INFO -     raise exception
[2022-12-17T03:05:45.989+0000] {subprocess.py:93} INFO -   File "/home/***/.local/lib/python3.7/site-packages/sqlalchemy/engine/base.py", line 3243, in _wrap_pool_connect
[2022-12-17T03:05:45.991+0000] {subprocess.py:93} INFO -     return fn()
[2022-12-17T03:05:45.999+0000] {subprocess.py:93} INFO -   File "/home/***/.local/lib/python3.7/site-packages/sqlalchemy/pool/base.py", line 310, in connect
[2022-12-17T03:05:46.001+0000] {subprocess.py:93} INFO -     return _ConnectionFairy._checkout(self)
[2022-12-17T03:05:46.002+0000] {subprocess.py:93} INFO -   File "/home/***/.local/lib/python3.7/site-packages/sqlalchemy/pool/base.py", line 868, in _checkout
[2022-12-17T03:05:46.002+0000] {subprocess.py:93} INFO -     fairy = _ConnectionRecord.checkout(pool)
[2022-12-17T03:05:46.003+0000] {subprocess.py:93} INFO -   File "/home/***/.local/lib/python3.7/site-packages/sqlalchemy/pool/base.py", line 476, in checkout
[2022-12-17T03:05:46.004+0000] {subprocess.py:93} INFO -     rec = pool._do_get()
[2022-12-17T03:05:46.004+0000] {subprocess.py:93} INFO -   File "/home/***/.local/lib/python3.7/site-packages/sqlalchemy/pool/impl.py", line 146, in _do_get
[2022-12-17T03:05:46.005+0000] {subprocess.py:93} INFO -     self._dec_overflow()
[2022-12-17T03:05:46.008+0000] {subprocess.py:93} INFO -   File "/home/***/.local/lib/python3.7/site-packages/sqlalchemy/util/langhelpers.py", line 72, in __exit__
[2022-12-17T03:05:46.008+0000] {subprocess.py:93} INFO -     with_traceback=exc_tb,
[2022-12-17T03:05:46.010+0000] {subprocess.py:93} INFO -   File "/home/***/.local/lib/python3.7/site-packages/sqlalchemy/util/compat.py", line 207, in raise_
[2022-12-17T03:05:46.011+0000] {subprocess.py:93} INFO -     raise exception
[2022-12-17T03:05:46.012+0000] {subprocess.py:93} INFO -   File "/home/***/.local/lib/python3.7/site-packages/sqlalchemy/pool/impl.py", line 143, in _do_get
[2022-12-17T03:05:46.013+0000] {subprocess.py:93} INFO -     return self._create_connection()
[2022-12-17T03:05:46.015+0000] {subprocess.py:93} INFO -   File "/home/***/.local/lib/python3.7/site-packages/sqlalchemy/pool/base.py", line 256, in _create_connection
[2022-12-17T03:05:46.016+0000] {subprocess.py:93} INFO -     return _ConnectionRecord(self)
[2022-12-17T03:05:46.017+0000] {subprocess.py:93} INFO -   File "/home/***/.local/lib/python3.7/site-packages/sqlalchemy/pool/base.py", line 371, in __init__
[2022-12-17T03:05:46.018+0000] {subprocess.py:93} INFO -     self.__connect()
[2022-12-17T03:05:46.020+0000] {subprocess.py:93} INFO -   File "/home/***/.local/lib/python3.7/site-packages/sqlalchemy/pool/base.py", line 666, in __connect
[2022-12-17T03:05:46.021+0000] {subprocess.py:93} INFO -     pool.logger.debug("Error on connect(): %s", e)
[2022-12-17T03:05:46.022+0000] {subprocess.py:93} INFO -   File "/home/***/.local/lib/python3.7/site-packages/sqlalchemy/util/langhelpers.py", line 72, in __exit__
[2022-12-17T03:05:46.024+0000] {subprocess.py:93} INFO -     with_traceback=exc_tb,
[2022-12-17T03:05:46.024+0000] {subprocess.py:93} INFO -   File "/home/***/.local/lib/python3.7/site-packages/sqlalchemy/util/compat.py", line 207, in raise_
[2022-12-17T03:05:46.025+0000] {subprocess.py:93} INFO -     raise exception
[2022-12-17T03:05:46.026+0000] {subprocess.py:93} INFO -   File "/home/***/.local/lib/python3.7/site-packages/sqlalchemy/pool/base.py", line 661, in __connect
[2022-12-17T03:05:46.027+0000] {subprocess.py:93} INFO -     self.dbapi_connection = connection = pool._invoke_creator(self)
[2022-12-17T03:05:46.028+0000] {subprocess.py:93} INFO -   File "/home/***/.local/lib/python3.7/site-packages/sqlalchemy/engine/create.py", line 590, in connect
[2022-12-17T03:05:46.029+0000] {subprocess.py:93} INFO -     return dialect.connect(*cargs, **cparams)
[2022-12-17T03:05:46.030+0000] {subprocess.py:93} INFO -   File "/home/***/.local/lib/python3.7/site-packages/sqlalchemy/engine/default.py", line 584, in connect
[2022-12-17T03:05:46.031+0000] {subprocess.py:93} INFO -     return self.dbapi.connect(*cargs, **cparams)
[2022-12-17T03:05:46.035+0000] {subprocess.py:93} INFO -   File "/home/***/.local/lib/python3.7/site-packages/psycopg2/__init__.py", line 122, in connect
[2022-12-17T03:05:46.037+0000] {subprocess.py:93} INFO -     conn = _connect(dsn, connection_factory=connection_factory, **kwasync)
[2022-12-17T03:05:46.040+0000] {subprocess.py:93} INFO - sqlalchemy.exc.OperationalError: (psycopg2.OperationalError) connection to server at "localhost" (127.0.0.1), port 5432 failed: Connection refused
[2022-12-17T03:05:46.041+0000] {subprocess.py:93} INFO - 	Is the server running on that host and accepting TCP/IP connections?
[2022-12-17T03:05:46.042+0000] {subprocess.py:93} INFO - connection to server at "localhost" (::1), port 5432 failed: Cannot assign requested address
[2022-12-17T03:05:46.043+0000] {subprocess.py:93} INFO - 	Is the server running on that host and accepting TCP/IP connections?
[2022-12-17T03:05:46.044+0000] {subprocess.py:93} INFO - 
[2022-12-17T03:05:46.046+0000] {subprocess.py:93} INFO - (Background on this error at: https://sqlalche.me/e/14/e3q8)
[2022-12-17T03:05:47.382+0000] {subprocess.py:97} INFO - Command exited with return code 1
[2022-12-17T03:05:47.608+0000] {taskinstance.py:1851} ERROR - Task failed with exception
Traceback (most recent call last):
  File "/home/airflow/.local/lib/python3.7/site-packages/airflow/operators/bash.py", line 197, in execute
    f'Bash command failed. The command returned a non-zero exit code {result.exit_code}.'
airflow.exceptions.AirflowException: Bash command failed. The command returned a non-zero exit code 1.
[2022-12-17T03:05:47.670+0000] {taskinstance.py:1406} INFO - Marking task as FAILED. dag_id=Can_I_change_name_to_this, task_id=task_7, execution_date=20221217T030445, start_date=20221217T030534, end_date=20221217T030547
[2022-12-17T03:05:47.809+0000] {standard_task_runner.py:105} ERROR - Failed to execute job 84 for task task_7 (Bash command failed. The command returned a non-zero exit code 1.; 285)
[2022-12-17T03:05:47.914+0000] {local_task_job.py:159} INFO - Task exited with return code 1
[2022-12-17T03:05:48.079+0000] {taskinstance.py:2623} INFO - 0 downstream tasks scheduled from follow-on schedule check
